Workbook

Sheet Summary
A1: Optimization | B1: Vanilla
A2: Ram | B2: Total-Time | C2: Total-Fake-Dirty-Pages | D2: Total-Transferred-Page-Count | E2: FD Percentage | G2: FD Percentage : The Percentage of Fake Dirty Pages from The Total # of Pages Marked for Transfer | P2: SS
A3: 1024 | B3: =Vanilla!E6 -> 10552.333 | C3: =Vanilla!Q6 -> 21901.667 | D3: =Vanilla!R6 -> 304901.33 | E3: =C3/D3 -> 0.071831981
A4: 2048 | B4: =Vanilla!E13 -> 22718 | C4: =Vanilla!Q13 -> 56554.667 | D4: =Vanilla!R13 -> 645633 | E4: =C4/D4 -> 0.087595688
A5: 4096 | B5: =Vanilla!E20 -> 40078 | C5: =Vanilla!Q20 -> 189537.33 | D5: =Vanilla!R20 -> 1344508 | E5: =C5/D5 -> 0.14097152
A6: 8192 | B6: =Vanilla!E27 -> 56432 | C6: =Vanilla!Q27 -> 187223.67 | D6: =Vanilla!R27 -> 2417097.3 | E6: =C6/D6 -> 0.077458059
A7: 12288 | B7: =Vanilla!E34 -> 75654 | C7: =Vanilla!Q34 -> 299065.33 | D7: =Vanilla!R34 -> 3595613.7 | E7: =C7/D7 -> 0.083175046
A8: 16384 | B8: =Vanilla!E41 -> 88905 | C8: =Vanilla!Q41 -> 369528.67 | D8: =Vanilla!R41 -> 4734474.3 | E8: =C8/D8 -> 0.078050622
G9: TMT Improvement
A10: Optimization | B10: XBZRLE | G10: Vanilla vs | H10: X | I10: C | J10: HS1 | K10: HM5 | L10: HM3 | M10: XHS1 | N10: XHM5 | O10: XHM3 | P10: CHS1 | Q10: CHM5 | R10: CHM3
A11: Ram | B11: Total-Time | C11: Total-Fake-Dirty-Pages | D11: Total-Transferred-Page-Count | E11: FD Percentage | G11: Ram | U11: X | W11: XBZRLE
A12: 1024 | B12: =XBZRLE!E6 -> 10232.667 | C12: =XBZRLE!Q6 -> 21649.667 | D12: =XBZRLE!R6 -> 300142.33 | E12: =C12/D12 -> 0.072131333 | G12: 1024 | H12: =(B3-B12)/B3 -> 0.030293458 | I12: =($B$3-$B21)/$B$3 -> 0.32267745 | J12: =($B$3-$B30)/$B$3 -> 0.059891967 | K12: =($B$3-$B39)/$B$3 -> 0.075591496 | L12: =($B$3-$B48)/$B$3 -> 0.056733108 | M12: =($B$3-$B57)/$B$3 -> 0.025649935 | N12: =($B$3-$B66)/$B$3 -> 0.018321382 | O12: =($B$3-$B75)/$B$3 -> 0.017342136 | P12: =($B$3-$B84)/$B$3 -> 0.36715418 | Q12: =($B$3-$B93)/$B$3 -> 0.3972897 | R12: =($B$3-$B102)/$B$3 -> 0.38544398 | U12: C | W12: Compress
A13: 2048 | B13: =XBZRLE!E13 -> 21128.333 | C13: =XBZRLE!Q13 -> 37841.667 | D13: =XBZRLE!R13 -> 595248 | E13: =C13/D13 -> 0.063572942 | G13: 2048 | H13: =(B4-B13)/B4 -> 0.069973883 | I13: =($B$4-$B22)/$B$4 -> 0.33095636 | J13: =($B$4-$B31)/$B$4 -> 0.092349679 | K13: =($B$4-$B40)/$B$4 -> 0.10520292 | L13: =($B$4-$B49)/$B$4 -> 0.086876779 | M13: =($B$4-$B58)/$B$4 -> 0.11206972 | N13: =($B$4-$B67)/$B$4 -> 0.11174693 | O13: =($B$4-$B76)/$B$4 -> 0.11557649 | P13: =($B$4-$B85)/$B$4 -> 0.37013235 | Q13: =($B$4-$B94)/$B$4 -> 0.3960736 | R13: =($B$4-$B103)/$B$4 -> 0.37849576 | U13: HS1 | W13: HBFDP_SHA1
A14: 4096 | B14: =XBZRLE!E20 -> 38105 | C14: =XBZRLE!Q20 -> 171713 | D14: =XBZRLE!R20 -> 1310042.3 | E14: =C14/D14 -> 0.13107439 | G14: 4096 | H14: =(B5-B14)/B5 -> 0.049229003 | I14: =($B$5-$B23)/$B$5 -> 0.3512484 | J14: =($B$5-$B32)/$B$5 -> 0.12040687 | K14: =($B$5-$B41)/$B$5 -> 0.13983565 | L14: =($B$5-$B50)/$B$5 -> 0.13394714 | M14: =($B$5-$B59)/$B$5 -> 0.10085334 | N14: =($B$5-$B68)/$B$5 -> 0.1429213 | O14: =($B$5-$B77)/$B$5 -> 0.1001547 | P14: =($B$5-$B86)/$B$5 -> 0.35702048 | Q14: =($B$5-$B95)/$B$5 -> 0.39443918 | R14: =($B$5-$B104)/$B$5 -> 0.37826239 | U14: HM5 | W14: HBFDP_MD5
A15: 8192 | B15: =XBZRLE!E27 -> 55719.667 | C15: =XBZRLE!Q27 -> 189679.67 | D15: =XBZRLE!R27 -> 2446905.7 | E15: =C15/D15 -> 0.077518177 | G15: 8192 | H15: =(B6-B15)/B6 -> 0.012622862 | I15: =($B$6-$B24)/$B$6 -> 0.1953856 | J15: =($B$6-$B33)/$B$6 -> 0.074721198 | K15: =($B$6-$B42)/$B$6 -> 0.10856724 | L15: =($B$6-$B51)/$B$6 -> 0.093558029 | M15: =($B$6-$B60)/$B$6 -> 0.066215386 | N15: =($B$6-$B69)/$B$6 -> 0.11005576 | O15: =($B$6-$B78)/$B$6 -> 0.07518193 | P15: =($B$6-$B87)/$B$6 -> 0.23071425 | Q15: =($B$6-$B96)/$B$6 -> 0.2618727 | R15: =($B$6-$B105)/$B$6 -> 0.21656743 | U15: HM3 | W15: HBFDP_Murmur3
A16: 12288 | B16: =XBZRLE!E34 -> 73263.333 | C16: =XBZRLE!Q34 -> 269453.67 | D16: =XBZRLE!R34 -> 3525425 | E16: =C16/D16 -> 0.076431541 | G16: 12288 | H16: =(B7-B16)/B7 -> 0.031600004 | I16: =($B$7-$B25)/$B$7 -> 0.17617046 | J16: =($B$7-$B34)/$B$7 -> 0.10212723 | K16: =($B$7-$B43)/$B$7 -> 0.1432883 | L16: =($B$7-$B52)/$B$7 -> 0.10712366 | M16: =($B$7-$B61)/$B$7 -> 0.082665821 | N16: =($B$7-$B70)/$B$7 -> 0.13428239 | O16: =($B$7-$B79)/$B$7 -> 0.10626889 | P16: =($B$7-$B88)/$B$7 -> 0.18037821 | Q16: =($B$7-$B97)/$B$6 -> 0.31571331 | R16: =($B$7-$B106)/$B$7 -> 0.19545122 | U16: XHS1 | W16: XBZRLE_HBFDP_SHA1
A17: 16384 | B17: =XBZRLE!E41 -> 88181.667 | C17: =XBZRLE!Q41 -> 298566 | D17: =XBZRLE!R41 -> 4628958 | E17: =C17/D17 -> 0.064499613 | G17: 16384 | H17: =(B8-B17)/B8 -> 0.0081360253 | I17: =($B$8-$B26)/$B$8 -> 0.097253623 | J17: =($B$8-$B35)/$B$8 -> 0.021322385 | K17: =($B$8-$B44)/$B$8 -> 0.12845547 | L17: =($B$8-$B53)/$B$8 -> 0.043094689 | M17: =($B$8-$B62)/$B$8 -> 0.022544664 | N17: =($B$8-$B71)/$B$8 -> 0.063532235 | O17: =($B$8-$B80)/$B$8 -> 0.028142399 | P17: =($B$8-$B89)/$B$8 -> 0.098505896 | Q17: =($B$8-$B98)/$B$8 -> 0.1412669 | R17: =($B$8-$B107)/$B$8 -> 0.097684795 | U17: XHM5 | W17: XBZRLE_HBFDP_MD5
U18: XHM3 | W18: XBZRLE_HBFDP_Murmur3
A19: Optimization | B19: Compress | U19: CHS1 | W19: Compress_HBFDP_SHA1
A20: Ram | B20: Total-Time | C20: Total-Fake-Dirty-Pages | D20: Total-Transferred-Page-Count | E20: FD Percentage | U20: CHM5 | W20: Compress_HBFDP_MD5
A21: 1024 | B21: =Compress!E6 -> 7147.3333 | C21: =Compress!Q6 -> 22758.333 | D21: =Compress!R6 -> 286471 | E21: =C21/D21 -> 0.07944376 | U21: CHM3 | W21: Compress_HBFDP_Murmur3
A22: 2048 | B22: =Compress!E13 -> 15199.333 | C22: =Compress!Q13 -> 49604.333 | D22: =Compress!R13 -> 560801.67 | E22: =C22/D22 -> 0.088452543
A23: 4096 | B23: =Compress!E20 -> 26000.667 | C23: =Compress!Q20 -> 98742 | D23: =Compress!R20 -> 1119809 | E23: =C23/D23 -> 0.088177537
A24: 8192 | B24: =Compress!E27 -> 45406 | C24: =Compress!Q27 -> 131451 | D24: =Compress!R27 -> 2177441 | E24: =C24/D24 -> 0.060369489
A25: 12288 | B25: =Compress!E34 -> 62326 | C25: =Compress!Q34 -> 164240 | D25: =Compress!R34 -> 3227472.3 | E25: =C25/D25 -> 0.05088812
A26: 16384 | B26: =Compress!E41 -> 80258.667 | C26: =Compress!Q41 -> 185558.67 | D26: =Compress!R41 -> 4285914.7 | E26: =C26/D26 -> 0.043294998
A28: Optimization | B28: HBFDP_SHA1
A29: Ram | B29: Total-Time | C29: Total-Fake-Dirty-Pages | D29: Total-Transferred-Page-Count | E29: FD Percentage
A30: 1024 | B30: =HBFDP_SHA1!E6 -> 9920.3333 | C30: =HBFDP_SHA1!Q6 -> 22806.333 | D30: =HBFDP_SHA1!R6 -> 280989.33 | E30: =C30/(C30+D30) -> 0.075071292
A31: 2048 | B31: =HBFDP_SHA1!E13 -> 20620 | C31: =HBFDP_SHA1!Q13 -> 55412 | D31: =HBFDP_SHA1!R13 -> 572684.67 | E31: =C31/(C31+D31) -> 0.088222089
A32: 4096 | B32: =HBFDP_SHA1!E20 -> 35252.333 | C32: =HBFDP_SHA1!Q20 -> 65187 | D32: =HBFDP_SHA1!R20 -> 1146898 | E32: =C32/(C32+D32) -> 0.053780882
A33: 8192 | B33: =HBFDP_SHA1!E27 -> 52215.333 | C33: =HBFDP_SHA1!Q27 -> 139477.33 | D33: =HBFDP_SHA1!R27 -> 2206718 | E33: =C33/(C33+D33) -> 0.059448304
A34: 12288 | B34: =HBFDP_SHA1!E34 -> 67927.667 | C34: =HBFDP_SHA1!Q34 -> 181700.33 | D34: =HBFDP_SHA1!R34 -> 3270437.3 | E34: =C34/(C34+D34) -> 0.05263415
A35: 16384 | B35: =HBFDP_SHA1!E41 -> 87009.333 | C35: =HBFDP_SHA1!Q41 -> 273227.67 | D35: =HBFDP_SHA1!R41 -> 4347026.7 | E35: =C35/(C35+D35) -> 0.059136932
A37: Optimization | B37: HBFDP_MD5
A38: Ram | B38: Total-Time | C38: Total-Fake-Dirty-Pages | D38: Total-Transferred-Page-Count | E38: FD Percentage
A39: 1024 | B39: =HBFDP_MD5!E6 -> 9754.6667 | C39: =HBFDP_MD5!Q6 -> 20370.667 | D39: =HBFDP_MD5!R6 -> 280295 | E39: =C39/(C39+D39) -> 0.067751888
A40: 2048 | B40: =HBFDP_MD5!E13 -> 20328 | C40: =HBFDP_MD5!Q13 -> 50730 | D40: =HBFDP_MD5!R13 -> 569226.67 | E40: =C40/(C40+D40) -> 0.0818283
A41: 4096 | B41: =HBFDP_MD5!E20 -> 34473.667 | C41: =HBFDP_MD5!Q20 -> 84192.667 | D41: =HBFDP_MD5!R20 -> 1140615.7 | E41: =C41/(C41+D41) -> 0.068739463
A42: 8192 | B42: =HBFDP_MD5!E27 -> 50305.333 | C42: =HBFDP_MD5!Q27 -> 155633.33 | D42: =HBFDP_MD5!R27 -> 2204676 | E42: =C42/(C42+D42) -> 0.065937685
...

Sheet Vanilla
A1: RAM | B1: 1024
A2: Experiment | B2: Iterations | C2: Setup-Time | D2: Downtime | E2: Total-Time | F2: Ram-Total | G2: Ram-Postcopy-Requests | H2: Ram-Dirty-Sync-Count | I2: Ram-Remaining | J2: Ram-Mbps | K2: Ram-Transferred | L2: Ram-Duplicate | M2: Ram-Dirty-Pages-Rate | N2: Ram-Skipped | O2: Ram-Normal-Bytes | P2: Ram-Normal | Q2: Total-Fake-Dirty-Pages | R2: Total-Transferred-Page-Count
A3: 1 | B3: 3 | C3: 2 | D3: 387 | E3: 10551 | F3: 1091379200 | G3: 0 | H3: 5 | I3: 0 | J3: 909.42471 | K3: 1198977769 | L3: 11643 | M3: 0 | N3: 0 | O3: 1196535808 | P3: 292123 | Q3: 21747 | R3: 303766
A4: 2 | B4: 3 | C4: 2 | D4: 78 | E4: 10553 | F4: 1091379200 | G4: 0 | H4: 5 | I4: 0 | J4: 922.92041 | K4: 1217004274 | L4: 9100 | M4: 0 | N4: 0 | O4: 1214550016 | P4: 296521 | Q4: 22461 | R4: 305621
A5: 3 | B5: 3 | C5: 2 | D5: 95 | E5: 10553 | F5: 1091379200 | G5: 0 | H5: 5 | I5: 0 | J5: 913.92339 | K5: 1205138323 | L5: 11693 | M5: 0 | N5: 0 | O5: 1202683904 | P5: 293624 | Q5: 21497 | R5: 305317
A6: Average | B6: =AVERAGE(B3:B5) -> 3 | C6: =AVERAGE(C3:C5) -> 2 | D6: =AVERAGE(D3:D5) -> 186.66667 | E6: =AVERAGE(E3:E5) -> 10552.333 | F6: =AVERAGE(F3:F5) -> 1091379200 | G6: =AVERAGE(G3:G5) -> 0 | H6: =AVERAGE(H3:H5) -> 5 | I6: =AVERAGE(I3:I5) -> 0 | ... R6: =AVERAGE(R3:R5) -> 304901.33
A8: RAM | B8: 2048
A9: Experiment | B9: Iterations | C9: Setup-Time | D9: Downtime | E9: Total-Time | F9: Ram-Total | G9: Ram-Postcopy-Requests | H9: Ram-Dirty-Sync-Count | I9: Ram-Remaining | J9: Ram-Mbps | K9: Ram-Transferred | L9: Ram-Duplicate | M9: Ram-Dirty-Pages-Rate | N9: Ram-Skipped | O9: Ram-Normal-Bytes | P9: Ram-Normal | Q9: Total-Fake-Dirty-Pages | R9: Total-Transferred-Page-Count
A10: 1 | B10: 4 | C10: 2 | D10: 105 | E10: 22722 | F10: 2165121024 | G10: 0 | H10: 6 | I10: 0 | J10: 920.61309 | K10: 2614328777 | L10: 12142 | M10: 0 | N10: 0 | O10: 2609123328 | P10: 636993 | Q10: 59393 | R10: 649135
A11: 2 | B11: 3 | C11: 2 | D11: 224 | E11: 22545 | F11: 2165121024 | G11: 0 | H11: 5 | I11: 0 | J11: 912.78119 | K11: 2571890907 | L11: 12320 | M11: 0 | N11: 0 | O11: 2566766592 | P11: 626652 | Q11: 52337 | R11: 638972
A12: 3 | B12: 3 | C12: 2 | D12: 181 | E12: 22887 | F12: 2165121024 | G12: 0 | H12: 5 | I12: 0 | J12: 913.30447 | K12: 2612409222 | L12: 12267 | M12: 0 | N12: 0 | O12: 2607206400 | P12: 636525 | Q12: 57934 | R12: 648792
A13: Average | B13: =AVERAGE(B10:B12) -> 3.3333333 | C13: =AVERAGE(C10:C12) -> 2 | D13: =AVERAGE(D10:D12) -> 170 | E13: =AVERAGE(E10:E12) -> 22718 | F13: =AVERAGE(F10:F12) -> 2165121024 | G13: =AVERAGE(G10:G12) -> 0 | H13: =AVERAGE(H10:H12) -> 5.3333333 | I13: =AVERAGE(I10:I12) -> 0 | ... R13: =AVERAGE(R10:R12) -> 645633
A15: RAM | B15: 4096
A16: Experiment | B16: Iterations | C16: Setup-Time | D16: Downtime | E16: Total-Time | F16: Ram-Total | G16: Ram-Postcopy-Requests | H16: Ram-Dirty-Sync-Count | I16: Ram-Remaining | J16: Ram-Mbps | K16: Ram-Transferred | L16: Ram-Duplicate | M16: Ram-Dirty-Pages-Rate | N16: Ram-Skipped | O16: Ram-Normal-Bytes | P16: Ram-Normal | Q16: Total-Fake-Dirty-Pages | R16: Total-Transferred-Page-Count
A17: 1 | B17: 5 | C17: 3 | D17: 151 | E17: 40286 | F17: 4312604672 | G17: 0 | H17: 7 | I17: 0 | J17: 833.07345 | K17: 4194624788 | L17: 321030 | M17: 0 | N17: 0 | O17: 4183564288 | P17: 1021378 | Q17: 187643 | R17: 1342408
A18: 2 | B18: 6 | C18: 3 | D18: 134 | E18: 39424 | F18: 4312604672 | G18: 0 | H18: 8 | I18: 0 | J18: 824.21224 | K18: 4061196394 | L18: 352132 | M18: 0 | N18: 0 | O18: 4050116608 | P18: 988798 | Q18: 188061 | R18: 1340930
A19: 3 | B19: 6 | C19: 3 | D19: 152 | E19: 40524 | F19: 4312604672 | G19: 0 | H19: 8 | I19: 0 | J19: 829.13043 | K19: 4199436808 | L19: 327650 | M19: 0 | N19: 0 | O19: 4188307456 | P19: 1022536 | Q19: 192908 | R19: 1350186
A20: Average | B20: =AVERAGE(B17:B19) -> 5.6666667 | C20: =AVERAGE(C17:C19) -> 3 | D20: =AVERAGE(D17:D19) -> 145.66667 | E20: =AVERAGE(E17:E19) -> 40078 | F20: =AVERAGE(F17:F19) -> 4312604672 | G20: =AVERAGE(G17:G19) -> 0 | H20: =AVERAGE(H17:H19) -> 7.6666667 | I20: =AVERAGE(I17:I19) -> 0 | ... R20: =AVERAGE(R17:R19) -> 1344508
A22: RAM | B22: 8192
A23: Experiment | B23: Iterations | C23: Setup-Time | D23: Downtime | E23: Total-Time | F23: Ram-Total | G23: Ram-Postcopy-Requests | H23: Ram-Dirty-Sync-Count | I23: Ram-Remaining | J23: Ram-Mbps | K23: Ram-Transferred | L23: Ram-Duplicate | M23: Ram-Dirty-Pages-Rate | N23: Ram-Skipped | O23: Ram-Normal-Bytes | P23: Ram-Normal | Q23: Total-Fake-Dirty-Pages | R23: Total-Transferred-Page-Count
A24: 1 | B24: 6 | C24: 5 | D24: 142 | E24: 56752 | F24: 8607571968 | G24: 0 | H24: 8 | I24: 0 | J24: 663.19564 | K24: 4704082911 | L24: 1340172 | M24: 0 | N24: 0 | O24: 4682874880 | P24: 1143280 | Q24: 260673 | R24: 2483452
A25: 2 | B25: 5 | C25: 4 | D25: 158 | E25: 56022 | F25: 8607571968 | G25: 0 | H25: 7 | I25: 0 | J25: 632.85634 | K25: 4431205871 | L25: 1348609 | M25: 0 | N25: 0 | O25: 4410454016 | P25: 1076771 | Q25: 192787 | R25: 2425380
A26: 3 | B26: 5 | C26: 4 | D26: 176 | E26: 56522 | F26: 8607571968 | G26: 0 | H26: 7 | I26: 0 | J26: 655.97161 | K26: 4634062991 | L26: 1215969 | M26: 0 | N26: 0 | O26: 4614107136 | P26: 1126491 | Q26: 108211 | R26: 2342460
A27: Average | B27: =AVERAGE(B24:B26) -> 5.3333333 | C27: =AVERAGE(C24:C26) -> 4.3333333 | D27: =AVERAGE(D24:D26) -> 158.66667 | E27: =AVERAGE(E24:E26) -> 56432 | F27: =AVERAGE(F24:F26) -> 8607571968 | G27: =AVERAGE(G24:G26) -> 0 | H27: =AVERAGE(H24:H26) -> 7.3333333 | I27: =AVERAGE(I24:I26) -> 0 | ... R27: =AVERAGE(R24:R26) -> 2417097.3
A29: RAM | B29: 12288
A30: Experiment | B30: Iterations | C30: Setup-Time | D30: Downtime | E30: Total-Time | F30: Ram-Total | G30: Ram-Postcopy-Requests | H30: Ram-Dirty-Sync-Count | I30: Ram-Remaining | J30: Ram-Mbps | K30: Ram-Transferred | L30: Ram-Duplicate | M30: Ram-Dirty-Pages-Rate | N30: Ram-Skipped | O30: Ram-Normal-Bytes | P30: Ram-Normal | Q30: Total-Fake-Dirty-Pages | R30: Total-Transferred-Page-Count
A31: 1 | B31: 8 | C31: 6 | D31: 176 | E31: 75352 | F31: 12902539264 | G31: 0 | H31: 10 | I31: 0 | J31: 609.73575 | K31: 5742431188 | L31: 2258937 | M31: 0 | N31: 0 | O31: 5710946304 | P31: 1394274 | Q31: 349565 | R31: 3653211
A32: 2 | B32: 7 | C32: 7 | D32: 166 | E32: 75646 | F32: 12902539264 | G32: 0 | H32: 9 | I32: 0 | J32: 539.72665 | K32: 5102835567 | L32: 2331497 | M32: 0 | N32: 0 | O32: 5071945728 | P32: 1238268 | Q32: 272586 | R32: 3569765
A33: 3 | B33: 6 | C33: 6 | D33: 190 | E33: 75964 | F33: 12902539264 | G33: 0 | H33: 8 | I33: 0 | J33: 556.40401 | K33: 5282704474 | L33: 2281660 | M33: 0 | N33: 0 | O33: 5251911680 | P33: 1282205 | Q33: 275045 | R33: 3563865
A34: Average | B34: =AVERAGE(B31:B33) -> 7 | C34: =AVERAGE(C31:C33) -> 6.3333333 | D34: =AVERAGE(D31:D33) -> 177.33333 | E34: =AVERAGE(E31:E33) -> 75654 | F34: =AVERAGE(F31:F33) -> 12902539264 | G34: =AVERAGE(G31:G33) -> 0 | H34: =AVERAGE(H31:H33) -> 9 | I34: =AVERAGE(I31:I33) -> 0 | ... R34: =AVERAGE(R31:R33) -> 3595613.7
A36: RAM | B36: 16384
A37: Experiment | B37: Iterations | C37: Setup-Time | D37: Downtime | E37: Total-Time | F37: Ram-Total | G37: Ram-Postcopy-Requests | H37: Ram-Dirty-Sync-Count | I37: Ram-Remaining | J37: Ram-Mbps | K37: Ram-Transferred | L37: Ram-Duplicate | M37: Ram-Dirty-Pages-Rate | N37: Ram-Skipped | O37: Ram-Normal-Bytes | P37: Ram-Normal | Q37: Total-Fake-Dirty-Pages | R37: Total-Transferred-Page-Count
A38: 1 | B38: 8 | C38: 8 | D38: 172 | E38: 89990 | F38: 17197506560 | G38: 0 | H38: 10 | I38: 0 | J38: 522.6196 | K38: 5878082039 | L38: 3302873 | M38: 0 | N38: 0 | O38: 5836955648 | P38: 1425038 | Q38: 364805 | R38: 4727911
A39: 2 | B39: 8 | C39: 8 | D39: 136 | E39: 88197 | F39: 17197506560 | G39: 0 | H39: 10 | I39: 0 | J39: 527.13877 | K39: 5810767558 | L39: 3309635 | M39: 0 | N39: 0 | O39: 5769711616 | P39: 1408621 | Q39: 358054 | R39: 4718256
A40: 3 | B40: 9 | C40: 8 | D40: 144 | E40: 88528 | F40: 17197506560 | G40: 0 | H40: 11 | I40: 0 | J40: 543.27992 | K40: 6011179762 | L40: 3299780 | M40: 0 | N40: 0 | O40: 5969821696 | P40: 1457476 | Q40: 385727 | R40: 4757256
A41: Average | B41: =AVERAGE(B38:B40) -> 8.3333333 | C41: =AVERAGE(C38:C40) -> 8 | D41: =AVERAGE(D38:D40) -> 150.66667 | E41: =AVERAGE(E38:E40) -> 88905 | F41: =AVERAGE(F38:F40) -> 17197506560 | G41: =AVERAGE(G38:G40) -> 0 | H41: =AVERAGE(H38:H40) -> 10.333333 | I41: =AVERAGE(I38:I40) -> 0 | ... R41: =AVERAGE(R38:R40) -> 4734474.3

Sheet XBZRLE
A1: RAM | B1: 1024
A2: Experiment | B2: Iterations | C2: Setup-Time | D2: Downtime | E2: Total-Time | F2: Ram-Total | G2: Ram-Postcopy-Requests | H2: Ram-Dirty-Sync-Count | I2: Ram-Remaining | J2: Ram-Mbps | K2: Ram-Transferred | L2: Ram-Duplicate | M2: Ram-Dirty-Pages-Rate | N2: Ram-Skipped | O2: Ram-Normal-Bytes | P2: Ram-Normal | Q2: Total-Fake-Dirty-Pages | R2: Total-Transferred-Page-Count
A3: 1 | B3: 3 | C3: 15 | D3: 63 | E3: 10204 | F3: 1091379200 | G3: 0 | H3: 5 | I3: 0 | J3: 933.34028 | K3: 1188513127 | L3: 9632 | M3: 0 | N3: 0 | O3: 1185513472 | P3: 289432 | Q3: 21215 | R3: 301418
A4: 2 | B4: 2 | C4: 15 | D4: 98 | E4: 10246 | F4: 1091379200 | G4: 0 | H4: 4 | I4: 0 | J4: 914.25041 | K4: 1168999640 | L4: 11986 | M4: 0 | N4: 0 | O4: 1166209024 | P4: 284719 | Q4: 21655 | R4: 298090
A5: 3 | B5: 3 | C5: 15 | D5: 19 | E5: 10248 | F5: 1091379200 | G5: 0 | H5: 5 | I5: 0 | J5: 921.74882 | K5: 1178819572 | L5: 11724 | M5: 0 | N5: 0 | O5: 1175801856 | P5: 287061 | Q5: 22079 | R5: 300919
A6: Average | B6: =AVERAGE(B3:B5) -> 2.6666667 | C6: =AVERAGE(C3:C5) -> 15 | D6: =AVERAGE(D3:D5) -> 60 | E6: =AVERAGE(E3:E5) -> 10232.667 | F6: =AVERAGE(F3:F5) -> 1091379200 | G6: =AVERAGE(G3:G5) -> 0 | H6: =AVERAGE(H3:H5) -> 4.6666667 | I6: =AVERAGE(I3:I5) -> 0 | ... R6: =AVERAGE(R3:R5) -> 300142.33
A8: RAM | B8: 2048
A9: Experiment | B9: Iterations | C9: Setup-Time | D9: Downtime | E9: Total-Time | F9: Ram-Total | G9: Ram-Postcopy-Requests | H9: Ram-Dirty-Sync-Count | I9: Ram-Remaining | J9: Ram-Mbps | K9: Ram-Transferred | L9: Ram-Duplicate | M9: Ram-Dirty-Pages-Rate | N9: Ram-Skipped | O9: Ram-Normal-Bytes | P9: Ram-Normal | Q9: Total-Fake-Dirty-Pages | R9: Total-Transferred-Page-Count
A10: 1 | B10: 3 | C10: 18 | D10: 43 | E10: 21069 | F10: 2165121024 | G10: 0 | H10: 5 | I10: 0 | J10: 906.24983 | K10: 2384470754 | L10: 12582 | M10: 0 | N10: 0 | O10: 2379038720 | P10: 580820 | Q10: 36359 | R10: 596603
A11: 2 | B11: 3 | C11: 19 | D11: 61 | E11: 21234 | F11: 2165121024 | G11: 0 | H11: 5 | I11: 0 | J11: 888.47452 | K11: 2355910977 | L11: 11818 | M11: 0 | N11: 0 | O11: 2349993984 | P11: 573729 | Q11: 33368 | R11: 588618
A12: 3 | B12: 3 | C12: 19 | D12: 42 | E12: 21082 | F12: 2165121024 | G12: 0 | H12: 5 | I12: 0 | J12: 912.28049 | K12: 2401708121 | L12: 12345 | M12: 0 | N12: 0 | O12: 2396110848 | P12: 584988 | Q12: 43798 | R12: 600523
A13: Average | B13: =AVERAGE(B10:B12) -> 3 | C13: =AVERAGE(C10:C12) -> 18.666667 | D13: =AVERAGE(D10:D12) -> 48.666667 | E13: =AVERAGE(E10:E12) -> 21128.333 | F13: =AVERAGE(F10:F12) -> 2165121024 | G13: =AVERAGE(G10:G12) -> 0 | H13: =AVERAGE(H10:H12) -> 5 | I13: =AVERAGE(I10:I12) -> 0 | ... R13: =AVERAGE(R10:R12) -> 595248
A15: RAM | B15: 4096
A16: Experiment | B16: Iterations | C16: Setup-Time | D16: Downtime | E16: Total-Time | F16: Ram-Total | G16: Ram-Postcopy-Requests | H16: Ram-Dirty-Sync-Count | I16: Ram-Remaining | J16: Ram-Mbps | K16: Ram-Transferred | L16: Ram-Duplicate | M16: Ram-Dirty-Pages-Rate | N16: Ram-Skipped | O16: Ram-Normal-Bytes | P16: Ram-Normal | Q16: Total-Fake-Dirty-Pages | R16: Total-Transferred-Page-Count
A17: 1 | B17: 5 | C17: 20 | D17: 78 | E17: 37903 | F17: 4312604672 | G17: 0 | H17: 7 | I17: 0 | J17: 815.5504 | K17: 3861724521 | L17: 359208 | M17: 0 | N17: 0 | O17: 3847860224 | P17: 939419 | Q17: 173341 | R17: 1311172
A18: 2 | B18: 5 | C18: 19 | D18: 71 | E18: 38211 | F18: 4312604672 | G18: 0 | H18: 7 | I18: 0 | J18: 819.78294 | K18: 3913431333 | L18: 345530 | M18: 0 | N18: 0 | O18: 3899621376 | P18: 952056 | Q18: 176491 | R18: 1310144
A19: 3 | B19: 5 | C19: 22 | D19: 98 | E19: 38201 | F19: 4312604672 | G19: 0 | H19: 7 | I19: 0 | J19: 822.22095 | K19: 3923734289 | L19: 341687 | M19: 0 | N19: 0 | O19: 3908337664 | P19: 954184 | Q19: 165307 | R19: 1308811
A20: Average | B20: =AVERAGE(B17:B19) -> 5 | C20: =AVERAGE(C17:C19) -> 20.333333 | D20: =AVERAGE(D17:D19) -> 82.333333 | E20: =AVERAGE(E17:E19) -> 38105 | F20: =AVERAGE(F17:F19) -> 4312604672 | G20: =AVERAGE(G17:G19) -> 0 | H20: =AVERAGE(H17:H19) -> 7 | I20: =AVERAGE(I17:I19) -> 0 | ... R20: =AVERAGE(R17:R19) -> 1310042.3
A22: RAM | B22: 8192
A23: Experiment | B23: Iterations | C23: Setup-Time | D23: Downtime | E23: Total-Time | F23: Ram-Total | G23: Ram-Postcopy-Requests | H23: Ram-Dirty-Sync-Count | I23: Ram-Remaining | J23: Ram-Mbps | K23: Ram-Transferred | L23: Ram-Duplicate | M23: Ram-Dirty-Pages-Rate | N23: Ram-Skipped | O23: Ram-Normal-Bytes | P23: Ram-Normal | Q23: Total-Fake-Dirty-Pages | R23: Total-Transferred-Page-Count
A24: 1 | B24: 5 | C24: 22 | D24: 79 | E24: 55404 | F24: 8607571968 | G24: 0 | H24: 7 | I24: 0 | J24: 632.16529 | K24: 4376109854 | L24: 1420646 | M24: 0 | N24: 0 | O24: 4351877120 | P24: 1062470 | Q24: 120525 | R24: 2492424
A25: 2 | B25: 5 | C25: 20 | D25: 66 | E25: 55891 | F25: 8607571968 | G25: 0 | H25: 7 | I25: 0 | J25: 628.67049 | K25: 4390343680 | L25: 1331691 | M25: 0 | N25: 0 | O25: 4365639680 | P25: 1065830 | Q25: 212981 | R25: 2408168
A26: 3 | B26: 5 | C26: 21 | D26: 95 | E26: 55864 | F26: 8607571968 | G26: 0 | H26: 7 | I26: 0 | J26: 644.46113 | K26: 4498367920 | L26: 1336563 | M26: 0 | N26: 0 | O26: 4473425920 | P26: 1092145 | Q26: 235533 | R26: 2440125
A27: Average | B27: =AVERAGE(B24:B26) -> 5 | C27: =AVERAGE(C24:C26) -> 21 | D27: =AVERAGE(D24:D26) -> 80 | E27: =AVERAGE(E24:E26) -> 55719.667 | F27: =AVERAGE(F24:F26) -> 8607571968 | G27: =AVERAGE(G24:G26) -> 0 | H27: =AVERAGE(H24:H26) -> 7 | I27: =AVERAGE(I24:I26) -> 0 | ... R27: =AVERAGE(R24:R26) -> 2446905.7
A29: RAM | B29: 12288
A30: Experiment | B30: Iterations | C30: Setup-Time | D30: Downtime | E30: Total-Time | F30: Ram-Total | G30: Ram-Postcopy-Requests | H30: Ram-Dirty-Sync-Count | I30: Ram-Remaining | J30: Ram-Mbps | K30: Ram-Transferred | L30: Ram-Duplicate | M30: Ram-Dirty-Pages-Rate | N30: Ram-Skipped | O30: Ram-Normal-Bytes | P30: Ram-Normal | Q30: Total-Fake-Dirty-Pages | R30: Total-Transferred-Page-Count
A31: 1 | B31: 5 | C31: 23 | D31: 82 | E31: 72226 | F31: 12902539264 | G31: 0 | H31: 7 | I31: 0 | J31: 520.10142 | K31: 4693897882 | L31: 2330574 | M31: 0 | N31: 0 | O31: 4659732480 | P31: 1137630 | Q31: 227418 | R31: 3481648
A32: 2 | B32: 6 | C32: 22 | D32: 84 | E32: 73579 | F32: 12902539264 | G32: 0 | H32: 8 | I32: 0 | J32: 550.71874 | K32: 5063439792 | L32: 2292422 | M32: 0 | N32: 0 | O32: 5028507648 | P32: 1227663 | Q32: 273919 | R32: 3535354
A33: 3 | B33: 6 | C33: 24 | D33: 84 | E33: 73985 | F33: 12902539264 | G33: 0 | H33: 8 | I33: 0 | J33: 556.1825 | K33: 5141764251 | L33: 2295798 | M33: 0 | N33: 0 | O33: 5106253824 | P33: 1246644 | Q33: 307024 | R33: 3559273
A34: Average | B34: =AVERAGE(B31:B33) -> 5.6666667 | C34: =AVERAGE(C31:C33) -> 23 | D34: =AVERAGE(D31:D33) -> 83.333333 | E34: =AVERAGE(E31:E33) -> 73263.333 | F34: =AVERAGE(F31:F33) -> 12902539264 | G34: =AVERAGE(G31:G33) -> 0 | H34: =AVERAGE(H31:H33) -> 7.6666667 | I34: =AVERAGE(I31:I33) -> 0 | ... R34: =AVERAGE(R31:R33) -> 3525425
A36: RAM | B36: 16384
A37: Experiment | B37: Iterations | C37: Setup-Time | D37: Downtime | E37: Total-Time | F37: Ram-Total | G37: Ram-Postcopy-Requests | H37: Ram-Dirty-Sync-Count | I37: Ram-Remaining | J37: Ram-Mbps | K37: Ram-Transferred | L37: Ram-Duplicate | M37: Ram-Dirty-Pages-Rate | N37: Ram-Skipped | O37: Ram-Normal-Bytes | P37: Ram-Normal | Q37: Total-Fake-Dirty-Pages | R37: Total-Transferred-Page-Count
A38: 1 | B38: 25 | C38: 24 | D38: 82 | E38: 88545 | F38: 17197506560 | G38: 0 | H38: 27 | I38: 0 | J38: 502.72829 | K38: 5562538157 | L38: 3318150 | M38: 0 | N38: 0 | O38: 5479464960 | P38: 1337760 | Q38: 354969 | R38: 4704550
A39: 2 | B39: 6 | C39: 26 | D39: 89 | E39: 88419 | F39: 17197506560 | G39: 0 | H39: 8 | I39: 0 | J39: 452.16592 | K39: 4995825033 | L39: 3331712 | M39: 0 | N39: 0 | O39: 4950327296 | P39: 1208576 | Q39: 237175 | R39: 4555487
A40: 3 | B40: 8 | C40: 23 | D40: 79 | E40: 87581 | F40: 17197506560 | G40: 0 | H40: 10 | I40: 0 | J40: 509.69125 | K40: 5578230838 | L40: 3258109 | M40: 0 | N40: 0 | O40: 5530202112 | P40: 1350147 | Q40: 303554 | R40: 4626837
A41: Average | B41: =AVERAGE(B38:B40) -> 13 | C41: =AVERAGE(C38:C40) -> 24.333333 | D41: =AVERAGE(D38:D40) -> 83.333333 | E41: =AVERAGE(E38:E40) -> 88181.667 | F41: =AVERAGE(F38:F40) -> 17197506560 | G41: =AVERAGE(G38:G40) -> 0 | H41: =AVERAGE(H38:H40) -> 15 | I41: =AVERAGE(I38:I40) -> 0 | ... R41: =AVERAGE(R38:R40) -> 4628958

Sheet Compress
A1: RAM | B1: 1024
A2: Experiment | B2: Iterations | C2: Setup-Time | D2: Downtime | E2: Total-Time | F2: Ram-Total | G2: Ram-Postcopy-Requests | H2: Ram-Dirty-Sync-Count | I2: Ram-Remaining | J2: Ram-Mbps | K2: Ram-Transferred | L2: Ram-Duplicate | M2: Ram-Dirty-Pages-Rate | N2: Ram-Skipped | O2: Ram-Normal-Bytes | P2: Ram-Normal | Q2: Total-Fake-Dirty-Pages | R2: Total-Transferred-Page-Count
A3: 1 | B3: 3 | C3: 2 | D3: 557 | E3: 7131 | F3: 1091379200 | G3: 0 | H3: 5 | I3: 0 | J3: 805.89981 | K3: 717945240 | L3: 11321 | M3: 0 | N3: 0 | O3: 32768 | P3: 8 | Q3: 17145 | R3: 276081
A4: 2 | B4: 2 | C4: 2 | D4: 528 | E4: 7174 | F4: 1091379200 | G4: 0 | H4: 4 | I4: 0 | J4: 823.05919 | K4: 737660204 | L4: 11436 | M4: 0 | N4: 0 | O4: 32768 | P4: 8 | Q4: 24403 | R4: 290846
A5: 3 | B5: 2 | C5: 3 | D5: 116 | E5: 7137 | F5: 1091379200 | G5: 0 | H5: 4 | I5: 0 | J5: 807.98691 | K5: 720309968 | L5: 11566 | M5: 0 | N5: 0 | O5: 32768 | P5: 8 | Q5: 26727 | R5: 292486
A6: Average | B6: =AVERAGE(B3:B5) -> 2.3333333 | C6: =AVERAGE(C3:C5) -> 2.3333333 | D6: =AVERAGE(D3:D5) -> 400.33333 | E6: =AVERAGE(E3:E5) -> 7147.3333 | F6: =AVERAGE(F3:F5) -> 1091379200 | G6: =AVERAGE(G3:G5) -> 0 | H6: =AVERAGE(H3:H5) -> 4.3333333 | I6: =AVERAGE(I3:I5) -> 0 | ... R6: =AVERAGE(R3:R5) -> 286471
A8: RAM | B8: 2048
A9: Experiment | B9: Iterations | C9: Setup-Time | D9: Downtime | E9: Total-Time | F9: Ram-Total | G9: Ram-Postcopy-Requests | H9: Ram-Dirty-Sync-Count | I9: Ram-Remaining | J9: Ram-Mbps | K9: Ram-Transferred | L9: Ram-Duplicate | M9: Ram-Dirty-Pages-Rate | N9: Ram-Skipped | O9: Ram-Normal-Bytes | P9: Ram-Normal | Q9: Total-Fake-Dirty-Pages | R9: Total-Transferred-Page-Count
A10: 1 | B10: 3 | C10: 3 | D10: 53 | E10: 15187 | F10: 2165121024 | G10: 0 | H10: 5 | I10: 0 | J10: 852.30914 | K10: 1617470369 | L10: 12242 | M10: 0 | N10: 0 | O10: 28672 | P10: 7 | Q10: 55605 | R10: 561669
A11: 2 | B11: 3 | C11: 3 | D11: 1001 | E11: 15270 | F11: 2165121024 | G11: 0 | H11: 5 | I11: 0 | J11: 843.7759 | K11: 1610028451 | L11: 11430 | M11: 0 | N11: 0 | O11: 32768 | P11: 8 | Q11: 46238 | R11: 559489
A12: 3 | B12: 3 | C12: 3 | D12: 1068 | E12: 15141 | F12: 2165121024 | G12: 0 | H12: 5 | I12: 0 | J12: 837.69587 | K12: 1584917618 | L12: 12409 | M12: 0 | N12: 0 | O12: 32768 | P12: 8 | Q12: 46970 | R12: 561247
A13: Average | B13: =AVERAGE(B10:B12) -> 3 | C13: =AVERAGE(C10:C12) -> 3 | D13: =AVERAGE(D10:D12) -> 707.33333 | E13: =AVERAGE(E10:E12) -> 15199.333 | F13: =AVERAGE(F10:F12) -> 2165121024 | G13: =AVERAGE(G10:G12) -> 0 | H13: =AVERAGE(H10:H12) -> 5 | I13: =AVERAGE(I10:I12) -> 0 | ... R13: =AVERAGE(R10:R12) -> 560801.67
A15: RAM | B15: 4096
A16: Experiment | B16: Iterations | C16: Setup-Time | D16: Downtime | E16: Total-Time | F16: Ram-Total | G16: Ram-Postcopy-Requests | H16: Ram-Dirty-Sync-Count | I16: Ram-Remaining | J16: Ram-Mbps | K16: Ram-Transferred | L16: Ram-Duplicate | M16: Ram-Dirty-Pages-Rate | N16: Ram-Skipped | O16: Ram-Normal-Bytes | P16: Ram-Normal | Q16: Total-Fake-Dirty-Pages | R16: Total-Transferred-Page-Count
A17: 1 | B17: 4 | C17: 3 | D17: 95 | E17: 26009 | F17: 4312604672 | G17: 0 | H17: 6 | I17: 0 | J17: 681.92323 | K17: 2216549531 | L17: 330852 | M17: 0 | N17: 0 | O17: 28672 | P17: 7 | Q17: 104629 | R17: 1116455
A18: 2 | B18: 4 | C18: 4 | D18: 126 | E18: 26270 | F18: 4312604672 | G18: 0 | H18: 6 | I18: 0 | J18: 733.05828 | K18: 2406601193 | L18: 254366 | M18: 0 | N18: 0 | O18: 28672 | P18: 7 | Q18: 101470 | R18: 1110823
A19: 3 | B19: 4 | C19: 3 | D19: 90 | E19: 25723 | F19: 4312604672 | G19: 0 | H19: 6 | I19: 0 | J19: 679.60456 | K19: 2184716252 | L19: 324323 | M19: 0 | N19: 0 | O19: 28672 | P19: 7 | Q19: 90127 | R19: 1132149
A20: Average | B20: =AVERAGE(B17:B19) -> 4 | C20: =AVERAGE(C17:C19) -> 3.3333333 | D20: =AVERAGE(D17:D19) -> 103.66667 | E20: =AVERAGE(E17:E19) -> 26000.667 | F20: =AVERAGE(F17:F19) -> 4312604672 | G20: =AVERAGE(G17:G19) -> 0 | H20: =AVERAGE(H17:H19) -> 6 | I20: =AVERAGE(I17:I19) -> 0 | ... R20: =AVERAGE(R17:R19) -> 1119809
A22: RAM | B22: 8192
A23: Experiment | B23: Iterations | C23: Setup-Time | D23: Downtime | E23: Total-Time | F23: Ram-Total | G23: Ram-Postcopy-Requests | H23: Ram-Dirty-Sync-Count | I23: Ram-Remaining | J23: Ram-Mbps | K23: Ram-Transferred | L23: Ram-Duplicate | M23: Ram-Dirty-Pages-Rate | N23: Ram-Skipped | O23: Ram-Normal-Bytes | P23: Ram-Normal | Q23: Total-Fake-Dirty-Pages | R23: Total-Transferred-Page-Count
A24: 1 | B24: 5 | C24: 4 | D24: 80 | E24: 45437 | F24: 8607571968 | G24: 0 | H24: 7 | I24: 0 | J24: 467.97913 | K24: 2657499564 | L24: 1255198 | M24: 0 | N24: 0 | O24: 32768 | P24: 8 | Q24: 122315 | R24: 2174744
A25: 2 | B25: 4 | C25: 5 | D25: 100 | E25: 45179 | F25: 8607571968 | G25: 0 | H25: 6 | I25: 0 | J25: 463.08061 | K25: 2614687999 | L25: 1299789 | M25: 0 | N25: 0 | O25: 28672 | P25: 7 | Q25: 157804 | R25: 2178371
A26: 3 | B26: 4 | C26: 5 | D26: 100 | E26: 45602 | F26: 8607571968 | G26: 0 | H26: 6 | I26: 0 | J26: 449.53743 | K26: 2561982362 | L26: 1271886 | M26: 0 | N26: 0 | O26: 28672 | P26: 7 | Q26: 114234 | R26: 2179208
A27: Average | B27: =AVERAGE(B24:B26) -> 4.3333333 | C27: =AVERAGE(C24:C26) -> 4.6666667 | D27: =AVERAGE(D24:D26) -> 93.333333 | E27: =AVERAGE(E24:E26) -> 45406 | F27: =AVERAGE(F24:F26) -> 8607571968 | G27: =AVERAGE(G24:G26) -> 0 | H27: =AVERAGE(H24:H26) -> 6.3333333 | I27: =AVERAGE(I24:I26) -> 0 | ... R27: =AVERAGE(R24:R26) -> 2177441
A29: RAM | B29: 12288
A30: Experiment | B30: Iterations | C30: Setup-Time | D30: Downtime | E30: Total-Time | F30: Ram-Total | G30: Ram-Postcopy-Requests | H30: Ram-Dirty-Sync-Count | I30: Ram-Remaining | J30: Ram-Mbps | K30: Ram-Transferred | L30: Ram-Duplicate | M30: Ram-Dirty-Pages-Rate | N30: Ram-Skipped | O30: Ram-Normal-Bytes | P30: Ram-Normal | Q30: Total-Fake-Dirty-Pages | R30: Total-Transferred-Page-Count
A31: 1 | B31: 5 | C31: 7 | D31: 82 | E31: 62299 | F31: 12902539264 | G31: 0 | H31: 7 | I31: 0 | J31: 373.87106 | K31: 2910934596 | L31: 2229434 | M31: 0 | N31: 0 | O31: 28672 | P31: 7 | Q31: 135869 | R31: 3250435
A32: 2 | B32: 5 | C32: 6 | D32: 83 | E32: 62353 | F32: 12902539264 | G32: 0 | H32: 7 | I32: 0 | J32: 357.31464 | K32: 2784474538 | L32: 2318514 | M32: 0 | N32: 0 | O32: 28672 | P32: 7 | Q32: 183402 | R32: 3204363
A33: 3 | B33: 5 | C33: 7 | D33: 53 | E33: 62326 | F33: 12902539264 | G33: 0 | H33: 7 | I33: 0 | J33: 354.91215 | K33: 2764508836 | L33: 2294953 | M33: 0 | N33: 0 | O33: 28672 | P33: 7 | Q33: 173449 | R33: 3227619
A34: Average | B34: =AVERAGE(B31:B33) -> 5 | C34: =AVERAGE(C31:C33) -> 6.6666667 | D34: =AVERAGE(D31:D33) -> 72.666667 | E34: =AVERAGE(E31:E33) -> 62326 | F34: =AVERAGE(F31:F33) -> 12902539264 | G34: =AVERAGE(G31:G33) -> 0 | H34: =AVERAGE(H31:H33) -> 7 | I34: =AVERAGE(I31:I33) -> 0 | ... R34: =AVERAGE(R31:R33) -> 3227472.3
A36: RAM | B36: 16384
A37: Experiment | B37: Iterations | C37: Setup-Time | D37: Downtime | E37: Total-Time | F37: Ram-Total | G37: Ram-Postcopy-Requests | H37: Ram-Dirty-Sync-Count | I37: Ram-Remaining | J37: Ram-Mbps | K37: Ram-Transferred | L37: Ram-Duplicate | M37: Ram-Dirty-Pages-Rate | N37: Ram-Skipped | O37: Ram-Normal-Bytes | P37: Ram-Normal | Q37: Total-Fake-Dirty-Pages | R37: Total-Transferred-Page-Count
A38: 1 | B38: 4 | C38: 8 | D38: 83 | E38: 80370 | F38: 17197506560 | G38: 0 | H38: 6 | I38: 0 | J38: 298.1326 | K38: 2994604139 | L38: 3278109 | M38: 0 | N38: 0 | O38: 28672 | P38: 7 | Q38: 171710 | R38: 4256488
A39: 2 | B39: 5 | C39: 9 | D39: 88 | E39: 80440 | F39: 17197506560 | G39: 0 | H39: 7 | I39: 0 | J39: 307.67555 | K39: 3093119055 | L39: 3273894 | M39: 0 | N39: 0 | O39: 28672 | P39: 7 | Q39: 208802 | R39: 4296522
A40: 3 | B40: 4 | C40: 9 | D40: 197 | E40: 79966 | F40: 17197506560 | G40: 0 | H40: 6 | I40: 0 | J40: 276.6406 | K40: 2764706663 | L40: 3338508 | M40: 0 | N40: 0 | O40: 28672 | P40: 7 | Q40: 176164 | R40: 4304734
A41: Average | B41: =AVERAGE(B38:B40) -> 4.3333333 | C41: =AVERAGE(C38:C40) -> 8.6666667 | D41: =AVERAGE(D38:D40) -> 122.66667 | E41: =AVERAGE(E38:E40) -> 80258.667 | F41: =AVERAGE(F38:F40) -> 17197506560 | G41: =AVERAGE(G38:G40) -> 0 | H41: =AVERAGE(H38:H40) -> 6.3333333 | I41: =AVERAGE(I38:I40) -> 0 | ... R41: =AVERAGE(R38:R40) -> 4285914.7

Sheet HBFDP_SHA1
A1: RAM | B1: 1024
A2: Experiment | B2: Iterations | C2: Setup-Time | D2: Downtime | E2: Total-Time | F2: Ram-Total | G2: Ram-Postcopy-Requests | H2: Ram-Dirty-Sync-Count | I2: Ram-Remaining | J2: Ram-Mbps | K2: Ram-Transferred | L2: Ram-Duplicate | M2: Ram-Dirty-Pages-Rate | N2: Ram-Skipped | O2: Ram-Normal-Bytes | P2: Ram-Normal | Q2: Total-Fake-Dirty-Pages | R2: Total-Transferred-Page-Count
A3: 1 | B3: 2 | C3: 2 | D3: 400 | E3: 10032 | F3: 1091379200 | G3: 0 | H3: 4 | I3: 0 | J3: 886.98837 | K3: 1111849310 | L3: 10216 | M3: 0 | N3: 0 | O3: 1109590016 | P3: 270896 | Q3: 22967 | R3: 281112
A4: 2 | B4: 2 | C4: 1 | D4: 382 | E4: 9970 | F4: 1091379200 | G4: 0 | H4: 4 | I4: 0 | J4: 884.70103 | K4: 1102235708 | L4: 10446 | M4: 0 | N4: 0 | O4: 1099993088 | P4: 268553 | Q4: 21375 | R4: 278999
A5: 3 | B5: 2 | C5: 2 | D5: 87 | E5: 9759 | F5: 1091379200 | G5: 0 | H5: 4 | I5: 0 | J5: 917.71167 | K5: 1119051740 | L5: 10206 | M5: 0 | N5: 0 | O5: 1116778496 | P5: 272651 | Q5: 24077 | R5: 282857
A6: Average | B6: =AVERAGE(B3:B5) -> 2 | C6: =AVERAGE(C3:C5) -> 1.6666667 | D6: =AVERAGE(D3:D5) -> 289.66667 | E6: =AVERAGE(E3:E5) -> 9920.3333 | F6: =AVERAGE(F3:F5) -> 1091379200 | G6: =AVERAGE(G3:G5) -> 0 | H6: =AVERAGE(H3:H5) -> 4 | I6: =AVERAGE(I3:I5) -> 0 | ... R6: =AVERAGE(R3:R5) -> 280989.33
A8: RAM | B8: 2048
A9: Experiment | B9: Iterations | C9: Setup-Time | D9: Downtime | E9: Total-Time | F9: Ram-Total | G9: Ram-Postcopy-Requests | H9: Ram-Dirty-Sync-Count | I9: Ram-Remaining | J9: Ram-Mbps | K9: Ram-Transferred | L9: Ram-Duplicate | M9: Ram-Dirty-Pages-Rate | N9: Ram-Skipped | O9: Ram-Normal-Bytes | P9: Ram-Normal | Q9: Total-Fake-Dirty-Pages | R9: Total-Transferred-Page-Count
A10: 1 | B10: 3 | C10: 2 | D10: 41 | E10: 20616 | F10: 2165121024 | G10: 0 | H10: 5 | I10: 0 | J10: 890.70256 | K10: 2294905429 | L10: 11599 | M10: 0 | N10: 0 | O10: 2290327552 | P10: 559162 | Q10: 59023 | R10: 570761
A11: 2 | B11: 3 | C11: 1 | D11: 41 | E11: 20689 | F11: 2165121024 | G11: 0 | H11: 5 | I11: 0 | J11: 889.58478 | K11: 2300253850 | L11: 12156 | M11: 0 | N11: 0 | O11: 2295660544 | P11: 560464 | Q11: 53302 | R11: 572620
A12: 3 | B12: 3 | C12: 2 | D12: 46 | E12: 20555 | F12: 2165121024 | G12: 0 | H12: 5 | I12: 0 | J12: 897.6666 | K12: 2306005327 | L12: 12809 | M12: 0 | N12: 0 | O12: 2301394944 | P12: 561864 | Q12: 53911 | R12: 574673
A13: Average | B13: =AVERAGE(B10:B12) -> 3 | C13: =AVERAGE(C10:C12) -> 1.6666667 | D13: =AVERAGE(D10:D12) -> 42.666667 | E13: =AVERAGE(E10:E12) -> 20620 | F13: =AVERAGE(F10:F12) -> 2165121024 | G13: =AVERAGE(G10:G12) -> 0 | H13: =AVERAGE(H10:H12) -> 5 | I13: =AVERAGE(I10:I12) -> 0 | ... R13: =AVERAGE(R10:R12) -> 572684.67
A15: RAM | B15: 4096
A16: Experiment | B16: Iterations | C16: Setup-Time | D16: Downtime | E16: Total-Time | F16: Ram-Total | G16: Ram-Postcopy-Requests | H16: Ram-Dirty-Sync-Count | I16: Ram-Remaining | J16: Ram-Mbps | K16: Ram-Transferred | L16: Ram-Duplicate | M16: Ram-Dirty-Pages-Rate | N16: Ram-Skipped | O16: Ram-Normal-Bytes | P16: Ram-Normal | Q16: Total-Fake-Dirty-Pages | R16: Total-Transferred-Page-Count
A17: 1 | B17: 3 | C17: 3 | D17: 124 | E17: 35296 | F17: 4312604672 | G17: 0 | H17: 5 | I17: 0 | J17: 835.79024 | K17: 3686980717 | L17: 248551 | M17: 0 | N17: 0 | O17: 3677560832 | P17: 897842 | Q17: 35785 | R17: 1146393
A18: 2 | B18: 4 | C18: 3 | D18: 72 | E18: 35215 | F18: 4312604672 | G18: 0 | H18: 6 | I18: 0 | J18: 805.56942 | K18: 3545501391 | L18: 285705 | M18: 0 | N18: 0 | O18: 3536023552 | P18: 863287 | Q18: 88455 | R18: 1148992
A19: 3 | B19: 4 | C19: 3 | D19: 73 | E19: 35246 | F19: 4312604672 | G19: 0 | H19: 6 | I19: 0 | J19: 810.08666 | K19: 3568523094 | L19: 276392 | M19: 0 | N19: 0 | O19: 3559084032 | P19: 868917 | Q19: 71321 | R19: 1145309
A20: Average | B20: =AVERAGE(B17:B19) -> 3.6666667 | C20: =AVERAGE(C17:C19) -> 3 | D20: =AVERAGE(D17:D19) -> 89.666667 | E20: =AVERAGE(E17:E19) -> 35252.333 | F20: =AVERAGE(F17:F19) -> 4312604672 | G20: =AVERAGE(G17:G19) -> 0 | H20: =AVERAGE(H17:H19) -> 5.6666667 | I20: =AVERAGE(I17:I19) -> 0 | ... R20: =AVERAGE(R17:R19) -> 1146898
A22: RAM | B22: 8192
A23: Experiment | B23: Iterations | C23: Setup-Time | D23: Downtime | E23: Total-Time | F23: Ram-Total | G23: Ram-Postcopy-Requests | H23: Ram-Dirty-Sync-Count | I23: Ram-Remaining | J23: Ram-Mbps | K23: Ram-Transferred | L23: Ram-Duplicate | M23: Ram-Dirty-Pages-Rate | N23: Ram-Skipped | O23: Ram-Normal-Bytes | P23: Ram-Normal | Q23: Total-Fake-Dirty-Pages | R23: Total-Transferred-Page-Count
A24: 1 | B24: 4 | C24: 5 | D24: 53 | E24: 52017 | F24: 8607571968 | G24: 0 | H24: 6 | I24: 0 | J24: 595.4959 | K24: 3871404173 | L24: 1260178 | M24: 0 | N24: 0 | O24: 3852537856 | P24: 940561 | Q24: 107464 | R24: 2200739
A25: 2 | B25: 4 | C25: 5 | D25: 64 | E25: 52079 | F25: 8607571968 | G25: 0 | H25: 6 | I25: 0 | J25: 587.6714 | K25: 3825087651 | L25: 1280381 | M25: 0 | N25: 0 | O25: 3806130176 | P25: 929231 | Q25: 131874 | R25: 2209612
A26: 3 | B26: 4 | C26: 4 | D26: 72 | E26: 52550 | F26: 8607571968 | G26: 0 | H26: 6 | I26: 0 | J26: 597.76472 | K26: 3926055690 | L26: 1255916 | M26: 0 | N26: 0 | O26: 3907121152 | P26: 953887 | Q26: 179094 | R26: 2209803
A27: Average | B27: =AVERAGE(B24:B26) -> 4 | C27: =AVERAGE(C24:C26) -> 4.6666667 | D27: =AVERAGE(D24:D26) -> 63 | E27: =AVERAGE(E24:E26) -> 52215.333 | F27: =AVERAGE(F24:F26) -> 8607571968 | G27: =AVERAGE(G24:G26) -> 0 | H27: =AVERAGE(H24:H26) -> 6 | I27: =AVERAGE(I24:I26) -> 0 | ... R27: =AVERAGE(R24:R26) -> 2206718
A29: RAM | B29: 12288
A30: Experiment | B30: Iterations | C30: Setup-Time | D30: Downtime | E30: Total-Time | F30: Ram-Total | G30: Ram-Postcopy-Requests | H30: Ram-Dirty-Sync-Count | I30: Ram-Remaining | J30: Ram-Mbps | K30: Ram-Transferred | L30: Ram-Duplicate | M30: Ram-Dirty-Pages-Rate | N30: Ram-Skipped | O30: Ram-Normal-Bytes | P30: Ram-Normal | Q30: Total-Fake-Dirty-Pages | R30: Total-Transferred-Page-Count
A31: 1 | B31: 4 | C31: 6 | D31: 62 | E31: 67833 | F31: 12902539264 | G31: 0 | H31: 6 | I31: 0 | J31: 476.12183 | K31: 4036527009 | L31: 2301507 | M31: 0 | N31: 0 | O31: 4007985152 | P31: 978512 | Q31: 174956 | R31: 3280019
A32: 2 | B32: 4 | C32: 6 | D32: 128 | E32: 67982 | F32: 12902539264 | G32: 0 | H32: 6 | I32: 0 | J32: 471.81576 | K32: 4008806091 | L32: 2289829 | M32: 0 | N32: 0 | O32: 3980423168 | P32: 971783 | Q32: 192561 | R32: 3261612
A33: 3 | B33: 4 | C33: 6 | D33: 66 | E33: 67968 | F33: 12902539264 | G33: 0 | H33: 6 | I33: 0 | J33: 476.18317 | K33: 4045082636 | L33: 2289057 | M33: 0 | N33: 0 | O33: 4016635904 | P33: 980624 | Q33: 177584 | R33: 3269681
A34: Average | B34: =AVERAGE(B31:B33) -> 4 | C34: =AVERAGE(C31:C33) -> 6 | D34: =AVERAGE(D31:D33) -> 85.333333 | E34: =AVERAGE(E31:E33) -> 67927.667 | F34: =AVERAGE(F31:F33) -> 12902539264 | G34: =AVERAGE(G31:G33) -> 0 | H34: =AVERAGE(H31:H33) -> 6 | I34: =AVERAGE(I31:I33) -> 0 | ... R34: =AVERAGE(R31:R33) -> 3270437.3
A36: RAM | B36: 16384
A37: Experiment | B37: Iterations | C37: Setup-Time | D37: Downtime | E37: Total-Time | F37: Ram-Total | G37: Ram-Postcopy-Requests | H37: Ram-Dirty-Sync-Count | I37: Ram-Remaining | J37: Ram-Mbps | K37: Ram-Transferred | L37: Ram-Duplicate | M37: Ram-Dirty-Pages-Rate | N37: Ram-Skipped | O37: Ram-Normal-Bytes | P37: Ram-Normal | Q37: Total-Fake-Dirty-Pages | R37: Total-Transferred-Page-Count
A38: 1 | B38: 5 | C38: 7 | D38: 87 | E38: 86160 | F38: 17197506560 | G38: 0 | H38: 7 | I38: 0 | J38: 420.37984 | K38: 4526910394 | L38: 3243192 | M38: 0 | N38: 0 | O38: 4488953856 | P38: 1095936 | Q38: 233567 | R38: 4339128
A39: 2 | B39: 6 | C39: 7 | D39: 111 | E39: 86994 | F39: 17197506560 | G39: 0 | H39: 8 | I39: 0 | J39: 422.23111 | K39: 4590864753 | L39: 3234719 | M39: 0 | N39: 0 | O39: 4552859648 | P39: 1111538 | Q39: 288288 | R39: 4346257
A40: 3 | B40: 5 | C40: 8 | D40: 102 | E40: 87874 | F40: 17197506560 | G40: 0 | H40: 7 | I40: 0 | J40: 412.53228 | K40: 4530732712 | L40: 3258862 | M40: 0 | N40: 0 | O40: 4492627968 | P40: 1096833 | Q40: 297828 | R40: 4355695
A41: Average | B41: =AVERAGE(B38:B40) -> 5.3333333 | C41: =AVERAGE(C38:C40) -> 7.3333333 | D41: =AVERAGE(D38:D40) -> 100 | E41: =AVERAGE(E38:E40) -> 87009.333 | F41: =AVERAGE(F38:F40) -> 17197506560 | G41: =AVERAGE(G38:G40) -> 0 | H41: =AVERAGE(H38:H40) -> 7.3333333 | I41: =AVERAGE(I38:I40) -> 0 | ... R41: =AVERAGE(R38:R40) -> 4347026.7

Sheet HBFDP_MD5
A1: RAM | B1: 1024
A2: Experiment | B2: Iterations | C2: Setup-Time | D2: Downtime | E2: Total-Time | F2: Ram-Total | G2: Ram-Postcopy-Requests | H2: Ram-Dirty-Sync-Count | I2: Ram-Remaining | J2: Ram-Mbps | K2: Ram-Transferred | L2: Ram-Duplicate | M2: Ram-Dirty-Pages-Rate | N2: Ram-Skipped | O2: Ram-Normal-Bytes | P2: Ram-Normal | Q2: Total-Fake-Dirty-Pages | R2: Total-Transferred-Page-Count
A3: 1 | B3: 2 | C3: 1 | D3: 52 | E3: 9701 | F3: 1091379200 | G3: 0 | H3: 4 | I3: 0 | J3: 907.19885 | K3: 1099766252 | L3: 11942 | M3: 0 | N3: 0 | O3: 1097515008 | P3: 267948 | Q3: 19759 | R3: 279890
A4: 2 | B4: 2 | C4: 1 | D4: 58 | E4: 9772 | F4: 1091379200 | G4: 0 | H4: 4 | I4: 0 | J4: 902.42393 | K4: 1101985670 | L4: 11392 | M4: 0 | N4: 0 | O4: 1099735040 | P4: 268490 | Q4: 19932 | R4: 279882
A5: 3 | B5: 2 | C5: 2 | D5: 70 | E5: 9791 | F5: 1091379200 | G5: 0 | H5: 4 | I5: 0 | J5: 905.86046 | K5: 1108221149 | L5: 11103 | M5: 0 | N5: 0 | O5: 1105960960 | P5: 270010 | Q5: 21421 | R5: 281113
A6: Average | B6: =AVERAGE(B3:B5) -> 2 | C6: =AVERAGE(C3:C5) -> 1.3333333 | D6: =AVERAGE(D3:D5) -> 60 | E6: =AVERAGE(E3:E5) -> 9754.6667 | F6: =AVERAGE(F3:F5) -> 1091379200 | G6: =AVERAGE(G3:G5) -> 0 | H6: =AVERAGE(H3:H5) -> 4 | I6: =AVERAGE(I3:I5) -> 0 | ... R6: =AVERAGE(R3:R5) -> 280295
A8: RAM | B8: 2048
A9: Experiment | B9: Iterations | C9: Setup-Time | D9: Downtime | E9: Total-Time | F9: Ram-Total | G9: Ram-Postcopy-Requests | H9: Ram-Dirty-Sync-Count | I9: Ram-Remaining | J9: Ram-Mbps | K9: Ram-Transferred | L9: Ram-Duplicate | M9: Ram-Dirty-Pages-Rate | N9: Ram-Skipped | O9: Ram-Normal-Bytes | P9: Ram-Normal | Q9: Total-Fake-Dirty-Pages | R9: Total-Transferred-Page-Count
A10: 1 | B10: 3 | C10: 1 | D10: 34 | E10: 20293 | F10: 2165121024 | G10: 0 | H10: 5 | I10: 0 | J10: 901.09177 | K10: 2285406901 | L10: 12759 | M10: 0 | N10: 0 | O10: 2280837120 | P10: 556845 | Q10: 55813 | R10: 569604
A11: 2 | B11: 3 | C11: 2 | D11: 46 | E11: 20358 | F11: 2165121024 | G11: 0 | H11: 5 | I11: 0 | J11: 898.93883 | K11: 2287137475 | L11: 11245 | M11: 0 | N11: 0 | O11: 2282577920 | P11: 557270 | Q11: 49101 | R11: 568515
A12: 3 | B12: 3 | C12: 2 | D12: 295 | E12: 20333 | F12: 2165121024 | G12: 0 | H12: 5 | I12: 0 | J12: 899.56129 | K12: 2285910199 | L12: 12593 | M12: 0 | N12: 0 | O12: 2281340928 | P12: 556968 | Q12: 47276 | R12: 569561
A13: Average | B13: =AVERAGE(B10:B12) -> 3 | C13: =AVERAGE(C10:C12) -> 1.6666667 | D13: =AVERAGE(D10:D12) -> 125 | E13: =AVERAGE(E10:E12) -> 20328 | F13: =AVERAGE(F10:F12) -> 2165121024 | G13: =AVERAGE(G10:G12) -> 0 | H13: =AVERAGE(H10:H12) -> 5 | I13: =AVERAGE(I10:I12) -> 0 | ... R13: =AVERAGE(R10:R12) -> 569226.67
A15: RAM | B15: 4096
A16: Experiment | B16: Iterations | C16: Setup-Time | D16: Downtime | E16: Total-Time | F16: Ram-Total | G16: Ram-Postcopy-Requests | H16: Ram-Dirty-Sync-Count | I16: Ram-Remaining | J16: Ram-Mbps | K16: Ram-Transferred | L16: Ram-Duplicate | M16: Ram-Dirty-Pages-Rate | N16: Ram-Skipped | O16: Ram-Normal-Bytes | P16: Ram-Normal | Q16: Total-Fake-Dirty-Pages | R16: Total-Transferred-Page-Count
A17: 1 | B17: 3 | C17: 3 | D17: 105 | E17: 34093 | F17: 4312604672 | G17: 0 | H17: 5 | I17: 0 | J17: 835.2468 | K17: 3558983041 | L17: 270659 | M17: 0 | N17: 0 | O17: 3549614080 | P17: 866605 | Q17: 33678 | R17: 1137264
A18: 2 | B18: 4 | C18: 3 | D18: 84 | E18: 35202 | F18: 4312604672 | G18: 0 | H18: 6 | I18: 0 | J18: 767.63022 | K18: 3377264616 | L18: 324298 | M18: 0 | N18: 0 | O18: 3367768064 | P18: 822209 | Q18: 181754 | R18: 1146507
A19: 3 | B19: 3 | C19: 2 | D19: 108 | E19: 34126 | F19: 4312604672 | G19: 0 | H19: 5 | I19: 0 | J19: 827.5089 | K19: 3529526824 | L19: 278666 | M19: 0 | N19: 0 | O19: 3520143360 | P19: 859410 | Q19: 37146 | R19: 1138076
A20: Average | B20: =AVERAGE(B17:B19) -> 3.3333333 | C20: =AVERAGE(C17:C19) -> 2.6666667 | D20: =AVERAGE(D17:D19) -> 99 | E20: =AVERAGE(E17:E19) -> 34473.667 | F20: =AVERAGE(F17:F19) -> 4312604672 | G20: =AVERAGE(G17:G19) -> 0 | H20: =AVERAGE(H17:H19) -> 5.3333333 | I20: =AVERAGE(I17:I19) -> 0 | ... R20: =AVERAGE(R17:R19) -> 1140615.7
A22: RAM | B22: 8192
A23: Experiment | B23: Iterations | C23: Setup-Time | D23: Downtime | E23: Total-Time | F23: Ram-Total | G23: Ram-Postcopy-Requests | H23: Ram-Dirty-Sync-Count | I23: Ram-Remaining | J23: Ram-Mbps | K23: Ram-Transferred | L23: Ram-Duplicate | M23: Ram-Dirty-Pages-Rate | N23: Ram-Skipped | O23: Ram-Normal-Bytes | P23: Ram-Normal | Q23: Total-Fake-Dirty-Pages | R23: Total-Transferred-Page-Count
A24: 1 | B24: 4 | C24: 5 | D24: 70 | E24: 50416 | F24: 8607571968 | G24: 0 | H24: 6 | I24: 0 | J24: 567.88417 | K24: 3578238693 | L24: 1335383 | M24: 0 | N24: 0 | O24: 3559268352 | P24: 868962 | Q24: 187241 | R24: 2204345
A25: 2 | B25: 4 | C25: 4 | D25: 36 | E25: 50043 | F25: 8607571968 | G25: 0 | H25: 6 | I25: 0 | J25: 608.18867 | K25: 3803931693 | L25: 1274927 | M25: 0 | N25: 0 | O25: 3785064448 | P25: 924088 | Q25: 122535 | R25: 2199015
A26: 3 | B26: 4 | C26: 5 | D26: 75 | E26: 50457 | F26: 8607571968 | G26: 0 | H26: 6 | I26: 0 | J26: 594.14319 | K26: 3746751615 | L26: 1300569 | M26: 0 | N26: 0 | O26: 3727765504 | P26: 910099 | Q26: 157124 | R26: 2210668
A27: Average | B27: =AVERAGE(B24:B26) -> 4 | C27: =AVERAGE(C24:C26) -> 4.6666667 | D27: =AVERAGE(D24:D26) -> 60.333333 | E27: =AVERAGE(E24:E26) -> 50305.333 | F27: =AVERAGE(F24:F26) -> 8607571968 | G27: =AVERAGE(G24:G26) -> 0 | H27: =AVERAGE(H24:H26) -> 6 | I27: =AVERAGE(I24:I26) -> 0 | ... R27: =AVERAGE(R24:R26) -> 2204676
A29: RAM | B29: 12288
A30: Experiment | B30: Iterations | C30: Setup-Time | D30: Downtime | E30: Total-Time | F30: Ram-Total | G30: Ram-Postcopy-Requests | H30: Ram-Dirty-Sync-Count | I30: Ram-Remaining | J30: Ram-Mbps | K30: Ram-Transferred | L30: Ram-Duplicate | M30: Ram-Dirty-Pages-Rate | N30: Ram-Skipped | O30: Ram-Normal-Bytes | P30: Ram-Normal | Q30: Total-Fake-Dirty-Pages | R30: Total-Transferred-Page-Count
A31: 1 | B31: 3 | C31: 6 | D31: 38 | E31: 64167 | F31: 12902539264 | G31: 0 | H31: 5 | I31: 0 | J31: 528.03255 | K31: 4234674682 | L31: 2175468 | M31: 0 | N31: 0 | O31: 4206878720 | P31: 1027070 | Q31: 64359 | R31: 3202538
A32: 2 | B32: 4 | C32: 5 | D32: 55 | E32: 65429 | F32: 12902539264 | G32: 0 | H32: 6 | I32: 0 | J32: 492.17705 | K32: 4024811484 | L32: 2287070 | M32: 0 | N32: 0 | O32: 3996422144 | P32: 975689 | Q32: 184415 | R32: 3262759
A33: 3 | B33: 4 | C33: 6 | D33: 94 | E33: 64845 | F33: 12902539264 | G33: 0 | H33: 6 | I33: 0 | J33: 472.34385 | K33: 3828075435 | L33: 2339221 | M33: 0 | N33: 0 | O33: 3799601152 | P33: 927637 | Q33: 198144 | R33: 3266858
A34: Average | B34: =AVERAGE(B31:B33) -> 3.6666667 | C34: =AVERAGE(C31:C33) -> 5.6666667 | D34: =AVERAGE(D31:D33) -> 62.333333 | E34: =AVERAGE(E31:E33) -> 64813.667 | F34: =AVERAGE(F31:F33) -> 12902539264 | G34: =AVERAGE(G31:G33) -> 0 | H34: =AVERAGE(H31:H33) -> 5.6666667 | I34: =AVERAGE(I31:I33) -> 0 | ... R34: =AVERAGE(R31:R33) -> 3244051.7
A36: RAM | B36: 16384
A37: Experiment | B37: Iterations | C37: Setup-Time | D37: Downtime | E37: Total-Time | F37: Ram-Total | G37: Ram-Postcopy-Requests | H37: Ram-Dirty-Sync-Count | I37: Ram-Remaining | J37: Ram-Mbps | K37: Ram-Transferred | L37: Ram-Duplicate | M37: Ram-Dirty-Pages-Rate | N37: Ram-Skipped | O37: Ram-Normal-Bytes | P37: Ram-Normal | Q37: Total-Fake-Dirty-Pages | R37: Total-Transferred-Page-Count
A38: 1 | B38: 4 | C38: 8 | D38: 59 | E38: 77870 | F38: 17197506560 | G38: 0 | H38: 6 | I38: 0 | J38: 406.91156 | K38: 3960156069 | L38: 3357647 | M38: 0 | N38: 0 | O38: 3922276352 | P38: 957587 | Q38: 145771 | R38: 4315234
A39: 2 | B39: 4 | C39: 7 | D39: 65 | E39: 77431 | F39: 17197506560 | G39: 0 | H39: 6 | I39: 0 | J39: 426.62211 | K39: 4128636411 | L39: 3393997 | M39: 0 | N39: 0 | O39: 4090101760 | P39: 998560 | Q39: 42366 | R39: 4392557
A40: 3 | B40: 3 | C40: 8 | D40: 60 | E40: 77153 | F40: 17197506560 | G40: 0 | H40: 5 | I40: 0 | J40: 416.64941 | K40: 4017589957 | L40: 3284511 | M40: 0 | N40: 0 | O40: 3980255232 | P40: 971742 | Q40: 94798 | R40: 4256253
A41: Average | B41: =AVERAGE(B38:B40) -> 3.6666667 | C41: =AVERAGE(C38:C40) -> 7.6666667 | D41: =AVERAGE(D38:D40) -> 61.333333 | E41: =AVERAGE(E38:E40) -> 77484.667 | F41: =AVERAGE(F38:F40) -> 17197506560 | G41: =AVERAGE(G38:G40) -> 0 | H41: =AVERAGE(H38:H40) -> 5.6666667 | I41: =AVERAGE(I38:I40) -> 0 | ... R41: =AVERAGE(R38:R40) -> 4321348

Sheet HBFDP_Murmur3
A1: RAM | B1: 1024
A2: Experiment | B2: Iterations | C2: Setup-Time | D2: Downtime | E2: Total-Time | F2: Ram-Total | G2: Ram-Postcopy-Requests | H2: Ram-Dirty-Sync-Count | I2: Ram-Remaining | J2: Ram-Mbps | K2: Ram-Transferred | L2: Ram-Duplicate | M2: Ram-Dirty-Pages-Rate | N2: Ram-Skipped | O2: Ram-Normal-Bytes | P2: Ram-Normal | Q2: Total-Fake-Dirty-Pages | R2: Total-Transferred-Page-Count
A3: 1 | B3: 3 | C3: 2 | D3: 534 | E3: 10096 | F3: 1091379200 | G3: 0 | H3: 5 | I3: 0 | J3: 886.88565 | K3: 1118815579 | L3: 11781 | M3: 0 | N3: 0 | O3: 1116528640 | P3: 272590 | Q3: 19938 | R3: 284371
A4: 2 | B4: 2 | C4: 2 | D4: 367 | E4: 9875 | F4: 1091379200 | G4: 0 | H4: 4 | I4: 0 | J4: 894.80085 | K4: 1104083741 | L4: 11495 | M4: 0 | N4: 0 | O4: 1101828096 | P4: 269001 | Q4: 24208 | R4: 280496
A5: 3 | B5: 2 | C5: 2 | D5: 373 | E5: 9890 | F5: 1091379200 | G5: 0 | H5: 4 | I5: 0 | J5: 894.34356 | K5: 1105196276 | L5: 11534 | M5: 0 | N5: 0 | O5: 1102938112 | P5: 269272 | Q5: 24155 | R5: 280806
A6: Average | B6: =AVERAGE(B3:B5) -> 2.3333333 | C6: =AVERAGE(C3:C5) -> 2 | D6: =AVERAGE(D3:D5) -> 424.66667 | E6: =AVERAGE(E3:E5) -> 9953.6667 | F6: =AVERAGE(F3:F5) -> 1091379200 | G6: =AVERAGE(G3:G5) -> 0 | H6: =AVERAGE(H3:H5) -> 4.3333333 | I6: =AVERAGE(I3:I5) -> 0 | ... R6: =AVERAGE(R3:R5) -> 281891
A8: RAM | B8: 2048
A9: Experiment | B9: Iterations | C9: Setup-Time | D9: Downtime | E9: Total-Time | F9: Ram-Total | G9: Ram-Postcopy-Requests | H9: Ram-Dirty-Sync-Count | I9: Ram-Remaining | J9: Ram-Mbps | K9: Ram-Transferred | L9: Ram-Duplicate | M9: Ram-Dirty-Pages-Rate | N9: Ram-Skipped | O9: Ram-Normal-Bytes | P9: Ram-Normal | Q9: Total-Fake-Dirty-Pages | R9: Total-Transferred-Page-Count
A10: 1 | B10: 3 | C10: 2 | D10: 53 | E10: 20711 | F10: 2165121024 | G10: 0 | H10: 5 | I10: 0 | J10: 887.52224 | K10: 2297249866 | L10: 12172 | M10: 0 | N10: 0 | O10: 2292662272 | P10: 559732 | Q10: 55227 | R10: 571904
A11: 2 | B11: 3 | C11: 2 | D11: 66 | E11: 20766 | F11: 2165121024 | G11: 0 | H11: 5 | I11: 0 | J11: 895.35953 | K11: 2323693279 | L11: 11409 | M11: 0 | N11: 0 | O11: 2319060992 | P11: 566177 | Q11: 54363 | R11: 577586
A12: 3 | B12: 3 | C12: 1 | D12: 499 | E12: 20756 | F12: 2165121024 | G12: 0 | H12: 5 | I12: 0 | J12: 881.57516 | K12: 2286924184 | L12: 12626 | M12: 0 | N12: 0 | O12: 2282352640 | P12: 557215 | Q12: 44940 | R12: 569841
A13: Average | B13: =AVERAGE(B10:B12) -> 3 | C13: =AVERAGE(C10:C12) -> 1.6666667 | D13: =AVERAGE(D10:D12) -> 206 | E13: =AVERAGE(E10:E12) -> 20744.333 | F13: =AVERAGE(F10:F12) -> 2165121024 | G13: =AVERAGE(G10:G12) -> 0 | H13: =AVERAGE(H10:H12) -> 5 | I13: =AVERAGE(I10:I12) -> 0 | ... R13: =AVERAGE(R10:R12) -> 573110.33
A15: RAM | B15: 4096
A16: Experiment | B16: Iterations | C16: Setup-Time | D16: Downtime | E16: Total-Time | F16: Ram-Total | G16: Ram-Postcopy-Requests | H16: Ram-Dirty-Sync-Count | I16: Ram-Remaining | J16: Ram-Mbps | K16: Ram-Transferred | L16: Ram-Duplicate | M16: Ram-Dirty-Pages-Rate | N16: Ram-Skipped | O16: Ram-Normal-Bytes | P16: Ram-Normal | Q16: Total-Fake-Dirty-Pages | R16: Total-Transferred-Page-Count
A17: 1 | B17: 5 | C17: 3 | D17: 36 | E17: 34614 | F17: 4312604672 | G17: 0 | H17: 6 | I17: 0 | J17: 829.18429 | K17: 3587149764 | L17: 266206 | M17: 0 | N17: 0 | O17: 3577765888 | P17: 873478 | Q17: 41251 | R17: 1139684
A18: 2 | B18: 4 | C18: 3 | D18: 99 | E18: 34821 | F18: 4312604672 | G18: 0 | H18: 6 | I18: 0 | J18: 812.21353 | K18: 3534743943 | L18: 286065 | M18: 0 | N18: 0 | O18: 3525283840 | P18: 860665 | Q18: 72203 | R18: 1146730
A19: 3 | B19: 4 | C19: 3 | D19: 66 | E19: 34694 | F19: 4312604672 | G19: 0 | H19: 6 | I19: 0 | J19: 826.69727 | K19: 3584656955 | L19: 277416 | M19: 0 | N19: 0 | O19: 3575177216 | P19: 872846 | Q19: 45999 | R19: 1150262
A20: Average | B20: =AVERAGE(B17:B19) -> 4.3333333 | C20: =AVERAGE(C17:C19) -> 3 | D20: =AVERAGE(D17:D19) -> 67 | E20: =AVERAGE(E17:E19) -> 34709.667 | F20: =AVERAGE(F17:F19) -> 4312604672 | G20: =AVERAGE(G17:G19) -> 0 | H20: =AVERAGE(H17:H19) -> 6 | I20: =AVERAGE(I17:I19) -> 0 | ... R20: =AVERAGE(R17:R19) -> 1145558.7
A22: RAM | B22: 8192
A23: Experiment | B23: Iterations | C23: Setup-Time | D23: Downtime | E23: Total-Time | F23: Ram-Total | G23: Ram-Postcopy-Requests | H23: Ram-Dirty-Sync-Count | I23: Ram-Remaining | J23: Ram-Mbps | K23: Ram-Transferred | L23: Ram-Duplicate | M23: Ram-Dirty-Pages-Rate | N23: Ram-Skipped | O23: Ram-Normal-Bytes | P23: Ram-Normal | Q23: Total-Fake-Dirty-Pages | R23: Total-Transferred-Page-Count
A24: 1 | B24: 4 | C24: 5 | D24: 171 | E24: 51128 | F24: 8607571968 | G24: 0 | H24: 6 | I24: 0 | J24: 570.89104 | K24: 3647995416 | L24: 1319994 | M24: 0 | N24: 0 | O24: 3629027328 | P24: 885993 | Q24: 177818 | R24: 2205987
A25: 2 | B25: 4 | C25: 5 | D25: 91 | E25: 50719 | F25: 8607571968 | G25: 0 | H25: 6 | I25: 0 | J25: 572.52657 | K25: 3629176659 | L25: 1322973 | M25: 0 | N25: 0 | O25: 3610218496 | P25: 881401 | Q25: 153708 | R25: 2204374
A26: 3 | B26: 4 | C26: 4 | D26: 50 | E26: 51610 | F26: 8607571968 | G26: 0 | H26: 6 | I26: 0 | J26: 570.9521 | K26: 3682856880 | L26: 1308826 | M26: 0 | N26: 0 | O26: 3663921152 | P26: 894512 | Q26: 181991 | R26: 2203338
A27: Average | B27: =AVERAGE(B24:B26) -> 4 | C27: =AVERAGE(C24:C26) -> 4.6666667 | D27: =AVERAGE(D24:D26) -> 104 | E27: =AVERAGE(E24:E26) -> 51152.333 | F27: =AVERAGE(F24:F26) -> 8607571968 | G27: =AVERAGE(G24:G26) -> 0 | H27: =AVERAGE(H24:H26) -> 6 | I27: =AVERAGE(I24:I26) -> 0 | ... R27: =AVERAGE(R24:R26) -> 2204566.3
A29: RAM | B29: 12288
A30: Experiment | B30: Iterations | C30: Setup-Time | D30: Downtime | E30: Total-Time | F30: Ram-Total | G30: Ram-Postcopy-Requests | H30: Ram-Dirty-Sync-Count | I30: Ram-Remaining | J30: Ram-Mbps | K30: Ram-Transferred | L30: Ram-Duplicate | M30: Ram-Dirty-Pages-Rate | N30: Ram-Skipped | O30: Ram-Normal-Bytes | P30: Ram-Normal | Q30: Total-Fake-Dirty-Pages | R30: Total-Transferred-Page-Count
A31: 1 | B31: 4 | C31: 6 | D31: 31 | E31: 67276 | F31: 12902539264 | G31: 0 | H31: 6 | I31: 0 | J31: 494.82023 | K31: 4160607183 | L31: 2255433 | M31: 0 | N31: 0 | O31: 4132237312 | P31: 1008847 | Q31: 103742 | R31: 3264280
A32: 2 | B32: 4 | C32: 6 | D32: 71 | E32: 67852 | F32: 12902539264 | G32: 0 | H32: 6 | I32: 0 | J32: 480.76133 | K32: 4077004275 | L32: 2291421 | M32: 0 | N32: 0 | O32: 4048474112 | P32: 988397 | Q32: 124144 | R32: 3279818
A33: 3 | B33: 4 | C33: 6 | D33: 53 | E33: 67521 | F33: 12902539264 | G33: 0 | H33: 6 | I33: 0 | J33: 462.83451 | K33: 3905821611 | L33: 2317789 | M33: 0 | N33: 0 | O33: 3877388288 | P33: 946628 | Q33: 161170 | R33: 3264417
A34: Average | B34: =AVERAGE(B31:B33) -> 4 | C34: =AVERAGE(C31:C33) -> 6 | D34: =AVERAGE(D31:D33) -> 51.666667 | E34: =AVERAGE(E31:E33) -> 67549.667 | F34: =AVERAGE(F31:F33) -> 12902539264 | G34: =AVERAGE(G31:G33) -> 0 | H34: =AVERAGE(H31:H33) -> 6 | I34: =AVERAGE(I31:I33) -> 0 | ... R34: =AVERAGE(R31:R33) -> 3269505
A36: RAM | B36: 16384
A37: Experiment | B37: Iterations | C37: Setup-Time | D37: Downtime | E37: Total-Time | F37: Ram-Total | G37: Ram-Postcopy-Requests | H37: Ram-Dirty-Sync-Count | I37: Ram-Remaining | J37: Ram-Mbps | K37: Ram-Transferred | L37: Ram-Duplicate | M37: Ram-Dirty-Pages-Rate | N37: Ram-Skipped | O37: Ram-Normal-Bytes | P37: Ram-Normal | Q37: Total-Fake-Dirty-Pages | R37: Total-Transferred-Page-Count
A38: 1 | B38: 4 | C38: 7 | D38: 81 | E38: 84780 | F38: 17197506560 | G38: 0 | H38: 6 | I38: 0 | J38: 400.50484 | K38: 4243787190 | L38: 3281448 | M38: 0 | N38: 0 | O38: 4206039040 | P38: 1026865 | Q38: 199087 | R38: 4308313
A39: 2 | B39: 4 | C39: 7 | D39: 86 | E39: 85041 | F39: 17197506560 | G39: 0 | H39: 6 | I39: 0 | J39: 391.80189 | K39: 4164347817 | L39: 3312651 | M39: 0 | N39: 0 | O39: 4126474240 | P39: 1007440 | Q39: 233230 | R39: 4320091
A40: 3 | B40: 4 | C40: 8 | D40: 97 | E40: 85400 | F40: 17197506560 | G40: 0 | H40: 6 | I40: 0 | J40: 413.85132 | K40: 4417236630 | L40: 3266176 | M40: 0 | N40: 0 | O40: 4379287552 | P40: 1069162 | Q40: 266496 | R40: 4335338
A41: Average | B41: =AVERAGE(B38:B40) -> 4 | C41: =AVERAGE(C38:C40) -> 7.3333333 | D41: =AVERAGE(D38:D40) -> 88 | E41: =AVERAGE(E38:E40) -> 85073.667 | F41: =AVERAGE(F38:F40) -> 17197506560 | G41: =AVERAGE(G38:G40) -> 0 | H41: =AVERAGE(H38:H40) -> 6 | I41: =AVERAGE(I38:I40) -> 0 | ... R41: =AVERAGE(R38:R40) -> 4321247.3

Sheet XBZRLE_HBFDP_SHA1
A1: RAM | B1: 1024
A2: Experiment | B2: Iterations | C2: Setup-Time | D2: Downtime | E2: Total-Time | F2: Ram-Total | G2: Ram-Postcopy-Requests | H2: Ram-Dirty-Sync-Count | I2: Ram-Remaining | J2: Ram-Mbps | K2: Ram-Transferred | L2: Ram-Duplicate | M2: Ram-Dirty-Pages-Rate | N2: Ram-Skipped | O2: Ram-Normal-Bytes | P2: Ram-Normal | Q2: Total-Fake-Dirty-Pages | R2: Total-Transferred-Page-Count
A3: 1 | B3: 2 | C3: 33 | D3: 297 | E3: 10358 | F3: 1091379200 | G3: 0 | H3: 4 | I3: 0 | J3: 873.55916 | K3: 1127224930 | L3: 10957 | M3: 0 | N3: 0 | O3: 1124749312 | P3: 274597 | Q3: 25673 | R3: 286375
A4: 2 | B4: 2 | C4: 33 | D4: 559 | E4: 10268 | F4: 1091379200 | G4: 0 | H4: 4 | I4: 0 | J4: 871.15454 | K4: 1114320983 | L4: 11730 | M4: 0 | N4: 0 | O4: 1111724032 | P4: 271417 | Q4: 28891 | R4: 284359
A5: 3 | B5: 2 | C5: 33 | D5: 261 | E5: 10219 | F5: 1091379200 | G5: 0 | H5: 4 | I5: 0 | J5: 866.94783 | K5: 1103628969 | L5: 10834 | M5: 0 | N5: 0 | O5: 1101127680 | P5: 268830 | Q5: 18587 | R5: 280581
A6: Average | B6: =AVERAGE(B3:B5) -> 2 | C6: =AVERAGE(C3:C5) -> 33 | D6: =AVERAGE(D3:D5) -> 372.33333 | E6: =AVERAGE(E3:E5) -> 10281.667 | F6: =AVERAGE(F3:F5) -> 1091379200 | G6: =AVERAGE(G3:G5) -> 0 | H6: =AVERAGE(H3:H5) -> 4 | I6: =AVERAGE(I3:I5) -> 0 | ... R6: =AVERAGE(R3:R5) -> 283771.67
A8: RAM | B8: 2048
A9: Experiment | B9: Iterations | C9: Setup-Time | D9: Downtime | E9: Total-Time | F9: Ram-Total | G9: Ram-Postcopy-Requests | H9: Ram-Dirty-Sync-Count | I9: Ram-Remaining | J9: Ram-Mbps | K9: Ram-Transferred | L9: Ram-Duplicate | M9: Ram-Dirty-Pages-Rate | N9: Ram-Skipped | O9: Ram-Normal-Bytes | P9: Ram-Normal | Q9: Total-Fake-Dirty-Pages | R9: Total-Transferred-Page-Count
A10: 1 | B10: 3 | C10: 35 | D10: 36 | E10: 20182 | F10: 2165121024 | G10: 0 | H10: 5 | I10: 0 | J10: 892.89372 | K10: 2248428848 | L10: 11694 | M10: 0 | N10: 0 | O10: 2243203072 | P10: 547657 | Q10: 49861 | R10: 562159
