Workbook

Sheet Summary
A1: Optimization | B1: Vanilla
A2: Ram | B2: Total-Time | C2: Total-Fake-Dirty-Pages | D2: Total-Transferred-Page-Count
A3: 1024 | B3: ='Vanilla'!E6 | C3: ='Vanilla'!Q6 | D3: ='Vanilla'!R6
A4: 2048 | B4: ='Vanilla'!E13 | C4: ='Vanilla'!Q13 | D4: ='Vanilla'!R13
A5: 4096 | B5: ='Vanilla'!E20 | C5: ='Vanilla'!Q20 | D5: ='Vanilla'!R20
A6: 8192 | B6: ='Vanilla'!E27 | C6: ='Vanilla'!Q27 | D6: ='Vanilla'!R27
A7: 12288 | B7: ='Vanilla'!E34 | C7: ='Vanilla'!Q34 | D7: ='Vanilla'!R34
A8: 16384 | B8: ='Vanilla'!E41 | C8: ='Vanilla'!Q41 | D8: ='Vanilla'!R41
A10: Optimization | B10: XBZRLE
A11: Ram | B11: Total-Time | C11: Total-Fake-Dirty-Pages | D11: Total-Transferred-Page-Count
A12: 1024 | B12: ='XBZRLE'!E6 | C12: ='XBZRLE'!Q6 | D12: ='XBZRLE'!R6
A13: 2048 | B13: ='XBZRLE'!E13 | C13: ='XBZRLE'!Q13 | D13: ='XBZRLE'!R13
A14: 4096 | B14: ='XBZRLE'!E20 | C14: ='XBZRLE'!Q20 | D14: ='XBZRLE'!R20
A15: 8192 | B15: ='XBZRLE'!E27 | C15: ='XBZRLE'!Q27 | D15: ='XBZRLE'!R27
A16: 12288 | B16: ='XBZRLE'!E34 | C16: ='XBZRLE'!Q34 | D16: ='XBZRLE'!R34
A17: 16384 | B17: ='XBZRLE'!E41 | C17: ='XBZRLE'!Q41 | D17: ='XBZRLE'!R41
A19: Optimization | B19: Compress
A20: Ram | B20: Total-Time | C20: Total-Fake-Dirty-Pages | D20: Total-Transferred-Page-Count
A21: 1024 | B21: ='Compress'!E6 | C21: ='Compress'!Q6 | D21: ='Compress'!R6
A22: 2048 | B22: ='Compress'!E13 | C22: ='Compress'!Q13 | D22: ='Compress'!R13
A23: 4096 | B23: ='Compress'!E20 | C23: ='Compress'!Q20 | D23: ='Compress'!R20
A24: 8192 | B24: ='Compress'!E27 | C24: ='Compress'!Q27 | D24: ='Compress'!R27
A25: 12288 | B25: ='Compress'!E34 | C25: ='Compress'!Q34 | D25: ='Compress'!R34
A26: 16384 | B26: ='Compress'!E41 | C26: ='Compress'!Q41 | D26: ='Compress'!R41
A28: Optimization | B28: HBFDP_SHA1
A29: Ram | B29: Total-Time | C29: Total-Fake-Dirty-Pages | D29: Total-Transferred-Page-Count
A30: 1024 | B30: ='HBFDP_SHA1'!E6 | C30: ='HBFDP_SHA1'!Q6 | D30: ='HBFDP_SHA1'!R6
A31: 2048 | B31: ='HBFDP_SHA1'!E13 | C31: ='HBFDP_SHA1'!Q13 | D31: ='HBFDP_SHA1'!R13
A32: 4096 | B32: ='HBFDP_SHA1'!E20 | C32: ='HBFDP_SHA1'!Q20 | D32: ='HBFDP_SHA1'!R20
A33: 8192 | B33: ='HBFDP_SHA1'!E27 | C33: ='HBFDP_SHA1'!Q27 | D33: ='HBFDP_SHA1'!R27
A34: 12288 | B34: ='HBFDP_SHA1'!E34 | C34: ='HBFDP_SHA1'!Q34 | D34: ='HBFDP_SHA1'!R34
A35: 16384 | B35: ='HBFDP_SHA1'!E41 | C35: ='HBFDP_SHA1'!Q41 | D35: ='HBFDP_SHA1'!R41
A37: Optimization | B37: HBFDP_MD5
A38: Ram | B38: Total-Time | C38: Total-Fake-Dirty-Pages | D38: Total-Transferred-Page-Count
A39: 1024 | B39: ='HBFDP_MD5'!E6 | C39: ='HBFDP_MD5'!Q6 | D39: ='HBFDP_MD5'!R6
A40: 2048 | B40: ='HBFDP_MD5'!E13 | C40: ='HBFDP_MD5'!Q13 | D40: ='HBFDP_MD5'!R13
A41: 4096 | B41: ='HBFDP_MD5'!E20 | C41: ='HBFDP_MD5'!Q20 | D41: ='HBFDP_MD5'!R20
A42: 8192 | B42: ='HBFDP_MD5'!E27 | C42: ='HBFDP_MD5'!Q27 | D42: ='HBFDP_MD5'!R27
A43: 12288 | B43: ='HBFDP_MD5'!E34 | C43: ='HBFDP_MD5'!Q34 | D43: ='HBFDP_MD5'!R34
A44: 16384 | B44: ='HBFDP_MD5'!E41 | C44: ='HBFDP_MD5'!Q41 | D44: ='HBFDP_MD5'!R41
...

Sheet Vanilla
A1: RAM | B1: 1024
A2: Experiment | B2: Iterations | C2: Setup-Time | D2: Downtime | E2: Total-Time | F2: Ram-Total | G2: Ram-Postcopy-Requests | H2: Ram-Dirty-Sync-Count | I2: Ram-Remaining | J2: Ram-Mbps | K2: Ram-Transferred | L2: Ram-Duplicate | M2: Ram-Dirty-Pages-Rate | N2: Ram-Skipped | O2: Ram-Normal-Bytes | P2: Ram-Normal | Q2: Total-Fake-Dirty-Pages | R2: Total-Transferred-Page-Count
A3: 1 | B3: 3 | C3: 2 | D3: 735 | E3: 10942 | F3: 1091379200 | G3: 0 | H3: 5 | I3: 0 | J3: 887.93362 | K3: 1214036848 | L3: 11354 | M3: 0 | N3: 0 | O3: 1211568128 | P3: 295793 | Q3: 0 | R3: 307147
A4: 2 | B4: 3 | C4: 2 | D4: 405 | E4: 10565 | F4: 1091379200 | G4: 0 | H4: 5 | I4: 0 | J4: 913.97945 | K4: 1206583228 | L4: 12182 | M4: 0 | N4: 0 | O4: 1204121600 | P4: 293975 | Q4: 0 | R4: 306157
A5: 3 | B5: 3 | C5: 1 | D5: 368 | E5: 10832 | F5: 1091379200 | G5: 0 | H5: 5 | I5: 0 | J5: 894.59742 | K5: 1210960702 | L5: 11104 | M5: 0 | N5: 0 | O5: 1208500224 | P5: 295044 | Q5: 0 | R5: 306148
A6: Average | B6: =AVERAGE(B3:B5) | C6: =AVERAGE(C3:C5) | D6: =AVERAGE(D3:D5) | E6: =AVERAGE(E3:E5) | F6: =AVERAGE(F3:F5) | G6: =AVERAGE(G3:G5) | H6: =AVERAGE(H3:H5) | I6: =AVERAGE(I3:I5) | ... R6: =AVERAGE(R3:R5)
A8: RAM | B8: 2048
A9: Experiment | B9: Iterations | C9: Setup-Time | D9: Downtime | E9: Total-Time | F9: Ram-Total | G9: Ram-Postcopy-Requests | H9: Ram-Dirty-Sync-Count | I9: Ram-Remaining | J9: Ram-Mbps | K9: Ram-Transferred | L9: Ram-Duplicate | M9: Ram-Dirty-Pages-Rate | N9: Ram-Skipped | O9: Ram-Normal-Bytes | P9: Ram-Normal | Q9: Total-Fake-Dirty-Pages | R9: Total-Transferred-Page-Count
A10: 1 | B10: 4 | C10: 2 | D10: 110 | E10: 21963 | F10: 2165121024 | G10: 0 | H10: 6 | I10: 0 | J10: 938.86386 | K10: 2577086248 | L10: 12736 | M10: 0 | N10: 0 | O10: 2571948032 | P10: 627917 | Q10: 0 | R10: 640653
A11: 2 | B11: 4 | C11: 2 | D11: 174 | E11: 21871 | F11: 2165121024 | G11: 0 | H11: 6 | I11: 0 | J11: 937.80392 | K11: 2563391826 | L11: 11900 | M11: 0 | N11: 0 | O11: 2558287872 | P11: 624582 | Q11: 0 | R11: 636482
A12: 3 | B12: 4 | C12: 3 | D12: 155 | E12: 21497 | F12: 2165121024 | G12: 0 | H12: 6 | I12: 0 | J12: 936.73476 | K12: 2516559714 | L12: 11748 | M12: 0 | N12: 0 | O12: 2511548416 | P12: 613171 | Q12: 0 | R12: 624919
A13: Average | B13: =AVERAGE(B10:B12) | C13: =AVERAGE(C10:C12) | D13: =AVERAGE(D10:D12) | E13: =AVERAGE(E10:E12) | F13: =AVERAGE(F10:F12) | G13: =AVERAGE(G10:G12) | H13: =AVERAGE(H10:H12) | I13: =AVERAGE(I10:I12) | ... R13: =AVERAGE(R10:R12)
A15: RAM | B15: 4096
A16: Experiment | B16: Iterations | C16: Setup-Time | D16: Downtime | E16: Total-Time | F16: Ram-Total | G16: Ram-Postcopy-Requests | H16: Ram-Dirty-Sync-Count | I16: Ram-Remaining | J16: Ram-Mbps | K16: Ram-Transferred | L16: Ram-Duplicate | M16: Ram-Dirty-Pages-Rate | N16: Ram-Skipped | O16: Ram-Normal-Bytes | P16: Ram-Normal | Q16: Total-Fake-Dirty-Pages | R16: Total-Transferred-Page-Count
A17: 1 | B17: 2 | C17: 3 | D17: 158 | E17: 31756 | F17: 4312604672 | G17: 0 | H17: 4 | I17: 0 | J17: 938.74644 | K17: 3725789609 | L17: 188979 | M17: 0 | N17: 0 | O17: 3716829184 | P17: 907429 | Q17: 0 | R17: 1096408
A18: 2 | B18: 6 | C18: 4 | D18: 171 | E18: 32151 | F18: 4312604672 | G18: 0 | H18: 8 | I18: 0 | J18: 932.31734 | K18: 3746188249 | L18: 304995 | M18: 0 | N18: 0 | O18: 3736145920 | P18: 912145 | Q18: 0 | R18: 1217140
A19: 3 | B19: 5 | C19: 3 | D19: 158 | E19: 32177 | F19: 4312604672 | G19: 0 | H19: 7 | I19: 0 | J19: 930.93842 | K19: 3743789147 | L19: 309293 | M19: 0 | N19: 0 | O19: 3733712896 | P19: 911551 | Q19: 0 | R19: 1220844
A20: Average | B20: =AVERAGE(B17:B19) | C20: =AVERAGE(C17:C19) | D20: =AVERAGE(D17:D19) | E20: =AVERAGE(E17:E19) | F20: =AVERAGE(F17:F19) | G20: =AVERAGE(G17:G19) | H20: =AVERAGE(H17:H19) | I20: =AVERAGE(I17:I19) | ... R20: =AVERAGE(R17:R19)
A22: RAM | B22: 8192
A23: Experiment | B23: Iterations | C23: Setup-Time | D23: Downtime | E23: Total-Time | F23: Ram-Total | G23: Ram-Postcopy-Requests | H23: Ram-Dirty-Sync-Count | I23: Ram-Remaining | J23: Ram-Mbps | K23: Ram-Transferred | L23: Ram-Duplicate | M23: Ram-Dirty-Pages-Rate | N23: Ram-Skipped | O23: Ram-Normal-Bytes | P23: Ram-Normal | Q23: Total-Fake-Dirty-Pages | R23: Total-Transferred-Page-Count
A24: 1 | B24: 5 | C24: 6 | D24: 147 | E24: 33179 | F24: 8607571968 | G24: 0 | H24: 7 | I24: 0 | J24: 922.16246 | K24: 3823649459 | L24: 1357701 | M24: 0 | N24: 0 | O24: 3804000256 | P24: 928711 | Q24: 0 | R24: 2286412
A25: 2 | B25: 6 | C25: 5 | D25: 135 | E25: 33427 | F25: 8607571968 | G25: 0 | H25: 8 | I25: 0 | J25: 922.81393 | K25: 3855073435 | L25: 1345349 | M25: 0 | N25: 0 | O25: 3835473920 | P25: 936395 | Q25: 0 | R25: 2281744
A26: 3 | B26: 6 | C26: 5 | D26: 133 | E26: 33924 | F26: 8607571968 | G26: 0 | H26: 8 | I26: 0 | J26: 923.25367 | K26: 3914267706 | L26: 1349703 | M26: 0 | N26: 0 | O26: 3894513664 | P26: 950809 | Q26: 0 | R26: 2300512
A27: Average | B27: =AVERAGE(B24:B26) | C27: =AVERAGE(C24:C26) | D27: =AVERAGE(D24:D26) | E27: =AVERAGE(E24:E26) | F27: =AVERAGE(F24:F26) | G27: =AVERAGE(G24:G26) | H27: =AVERAGE(H24:H26) | I27: =AVERAGE(I24:I26) | ... R27: =AVERAGE(R24:R26)
A29: RAM | B29: 12288
A30: Experiment | B30: Iterations | C30: Setup-Time | D30: Downtime | E30: Total-Time | F30: Ram-Total | G30: Ram-Postcopy-Requests | H30: Ram-Dirty-Sync-Count | I30: Ram-Remaining | J30: Ram-Mbps | K30: Ram-Transferred | L30: Ram-Duplicate | M30: Ram-Dirty-Pages-Rate | N30: Ram-Skipped | O30: Ram-Normal-Bytes | P30: Ram-Normal | Q30: Total-Fake-Dirty-Pages | R30: Total-Transferred-Page-Count
A31: 1 | B31: 7 | C31: 8 | D31: 160 | E31: 36280 | F31: 12902539264 | G31: 0 | H31: 9 | I31: 0 | J31: 915.6631 | K31: 4151403987 | L31: 2444445 | M31: 0 | N31: 0 | O31: 4121354240 | P31: 1006190 | Q31: 0 | R31: 3450635
A32: 2 | B32: 8 | C32: 8 | D32: 171 | E32: 37353 | F32: 12902539264 | G32: 0 | H32: 10 | I32: 0 | J32: 916.41726 | K32: 4277737787 | L32: 2396149 | M32: 0 | N32: 0 | O32: 4247875584 | P32: 1037079 | Q32: 0 | R32: 3433228
A33: 3 | B33: 6 | C33: 6 | D33: 159 | E33: 37546 | F33: 12902539264 | G33: 0 | H33: 8 | I33: 0 | J33: 910.19248 | K33: 4270865758 | L33: 2344864 | M33: 0 | N33: 0 | O33: 4241477632 | P33: 1035517 | Q33: 0 | R33: 3380381
A34: Average | B34: =AVERAGE(B31:B33) | C34: =AVERAGE(C31:C33) | D34: =AVERAGE(D31:D33) | E34: =AVERAGE(E31:E33) | F34: =AVERAGE(F31:F33) | G34: =AVERAGE(G31:G33) | H34: =AVERAGE(H31:H33) | I34: =AVERAGE(I31:I33) | ... R34: =AVERAGE(R31:R33)
A36: RAM | B36: 16384
A37: Experiment | B37: Iterations | C37: Setup-Time | D37: Downtime | E37: Total-Time | F37: Ram-Total | G37: Ram-Postcopy-Requests | H37: Ram-Dirty-Sync-Count | I37: Ram-Remaining | J37: Ram-Mbps | K37: Ram-Transferred | L37: Ram-Duplicate | M37: Ram-Dirty-Pages-Rate | N37: Ram-Skipped | O37: Ram-Normal-Bytes | P37: Ram-Normal | Q37: Total-Fake-Dirty-Pages | R37: Total-Transferred-Page-Count
A38: 1 | B38: 7 | C38: 8 | D38: 146 | E38: 39997 | F38: 17197506560 | G38: 0 | H38: 9 | I38: 0 | J38: 908.35965 | K38: 4540336755 | L38: 3336925 | M38: 0 | N38: 0 | O38: 4501512192 | P38: 1099002 | Q38: 0 | R38: 4435927
A39: 2 | B39: 6 | C39: 9 | D39: 132 | E39: 39595 | F39: 17197506560 | G39: 0 | H39: 8 | I39: 0 | J39: 911.51749 | K39: 4510203982 | L39: 3310344 | M39: 0 | N39: 0 | O39: 4471676928 | P39: 1091718 | Q39: 0 | R39: 4402062
A40: 3 | B40: 8 | C40: 10 | D40: 174 | E40: 39604 | F40: 17197506560 | G40: 0 | H40: 10 | I40: 0 | J40: 906.4005 | K40: 4485790175 | L40: 3444505 | M40: 0 | N40: 0 | O40: 4446105600 | P40: 1085475 | Q40: 0 | R40: 4529980
A41: Average | B41: =AVERAGE(B38:B40) | C41: =AVERAGE(C38:C40) | D41: =AVERAGE(D38:D40) | E41: =AVERAGE(E38:E40) | F41: =AVERAGE(F38:F40) | G41: =AVERAGE(G38:G40) | H41: =AVERAGE(H38:H40) | I41: =AVERAGE(I38:I40) | ... R41: =AVERAGE(R38:R40)

Sheet XBZRLE
A1: RAM | B1: 1024
A2: Experiment | B2: Iterations | C2: Setup-Time | D2: Downtime | E2: Total-Time | F2: Ram-Total | G2: Ram-Postcopy-Requests | H2: Ram-Dirty-Sync-Count | I2: Ram-Remaining | J2: Ram-Mbps | K2: Ram-Transferred | L2: Ram-Duplicate | M2: Ram-Dirty-Pages-Rate | N2: Ram-Skipped | O2: Ram-Normal-Bytes | P2: Ram-Normal | Q2: Total-Fake-Dirty-Pages | R2: Total-Transferred-Page-Count
A3: 1 | B3: 3 | C3: 16 | D3: 105 | E3: 10627 | F3: 1091379200 | G3: 0 | H3: 5 | I3: 0 | J3: 906.36791 | K3: 1201971347 | L3: 11543 | M3: 0 | N3: 0 | O3: 1198698496 | P3: 292651 | Q3: 0 | R3: 307325
A4: 2 | B4: 3 | C4: 17 | D4: 23 | E4: 9986 | F4: 1091379200 | G4: 0 | H4: 5 | I4: 0 | J4: 940.56745 | K4: 1171852235 | L4: 11549 | M4: 0 | N4: 0 | O4: 1168777216 | P4: 285346 | Q4: 0 | R4: 299190
A5: 3 | B5: 3 | C5: 17 | D5: 21 | E5: 10470 | F5: 1091379200 | G5: 0 | H5: 5 | I5: 0 | J5: 906.84079 | K5: 1184688469 | L5: 11889 | M5: 0 | N5: 0 | O5: 1181577216 | P5: 288471 | Q5: 0 | R5: 303213
A6: Average | B6: =AVERAGE(B3:B5) | C6: =AVERAGE(C3:C5) | D6: =AVERAGE(D3:D5) | E6: =AVERAGE(E3:E5) | F6: =AVERAGE(F3:F5) | G6: =AVERAGE(G3:G5) | H6: =AVERAGE(H3:H5) | I6: =AVERAGE(I3:I5) | ... R6: =AVERAGE(R3:R5)
A8: RAM | B8: 2048
A9: Experiment | B9: Iterations | C9: Setup-Time | D9: Downtime | E9: Total-Time | F9: Ram-Total | G9: Ram-Postcopy-Requests | H9: Ram-Dirty-Sync-Count | I9: Ram-Remaining | J9: Ram-Mbps | K9: Ram-Transferred | L9: Ram-Duplicate | M9: Ram-Dirty-Pages-Rate | N9: Ram-Skipped | O9: Ram-Normal-Bytes | P9: Ram-Normal | Q9: Total-Fake-Dirty-Pages | R9: Total-Transferred-Page-Count
A10: 1 | B10: 3 | C10: 17 | D10: 78 | E10: 20914 | F10: 2165121024 | G10: 0 | H10: 5 | I10: 0 | J10: 938.24309 | K10: 2450595835 | L10: 12021 | M10: 0 | N10: 0 | O10: 2443849728 | P10: 596643 | Q10: 0 | R10: 614154
A11: 2 | B11: 3 | C11: 17 | D11: 58 | E11: 20739 | F11: 2165121024 | G11: 0 | H11: 5 | I11: 0 | J11: 938.98153 | K11: 2431984535 | L11: 11299 | M11: 0 | N11: 0 | O11: 2425315328 | P11: 592118 | Q11: 0 | R11: 609174
A12: 3 | B12: 4 | C12: 19 | D12: 81 | E12: 21422 | F12: 2165121024 | G12: 0 | H12: 6 | I12: 0 | J12: 935.27747 | K12: 2502005558 | L12: 11702 | M12: 0 | N12: 0 | O12: 2495602688 | P12: 609278 | Q12: 0 | R12: 628108
A13: Average | B13: =AVERAGE(B10:B12) | C13: =AVERAGE(C10:C12) | D13: =AVERAGE(D10:D12) | E13: =AVERAGE(E10:E12) | F13: =AVERAGE(F10:F12) | G13: =AVERAGE(G10:G12) | H13: =AVERAGE(H10:H12) | I13: =AVERAGE(I10:I12) | ... R13: =AVERAGE(R10:R12)
A15: RAM | B15: 4096
A16: Experiment | B16: Iterations | C16: Setup-Time | D16: Downtime | E16: Total-Time | F16: Ram-Total | G16: Ram-Postcopy-Requests | H16: Ram-Dirty-Sync-Count | I16: Ram-Remaining | J16: Ram-Mbps | K16: Ram-Transferred | L16: Ram-Duplicate | M16: Ram-Dirty-Pages-Rate | N16: Ram-Skipped | O16: Ram-Normal-Bytes | P16: Ram-Normal | Q16: Total-Fake-Dirty-Pages | R16: Total-Transferred-Page-Count
A17: 1 | B17: 4 | C17: 19 | D17: 41 | E17: 30561 | F17: 4312604672 | G17: 0 | H17: 6 | I17: 0 | J17: 931.77813 | K17: 3557083554 | L17: 304714 | M17: 0 | N17: 0 | O17: 3544838144 | P17: 865439 | Q17: 0 | R17: 1177457
A18: 2 | B18: 4 | C18: 20 | D18: 38 | E18: 29916 | F18: 4312604672 | G18: 0 | H18: 6 | I18: 0 | J18: 931.68971 | K18: 3481512039 | L18: 320593 | M18: 0 | N18: 0 | O18: 3468795904 | P18: 846874 | Q18: 0 | R18: 1175172
A19: 3 | B19: 4 | C19: 17 | D19: 23 | E19: 30460 | F19: 4312604672 | G19: 0 | H19: 6 | I19: 0 | J19: 932.56807 | K19: 3548558805 | L19: 286071 | M19: 0 | N19: 0 | O19: 3536285696 | P19: 863351 | Q19: 0 | R19: 1156449
A20: Average | B20: =AVERAGE(B17:B19) | C20: =AVERAGE(C17:C19) | D20: =AVERAGE(D17:D19) | E20: =AVERAGE(E17:E19) | F20: =AVERAGE(F17:F19) | G20: =AVERAGE(G17:G19) | H20: =AVERAGE(H17:H19) | I20: =AVERAGE(I17:I19) | ... R20: =AVERAGE(R17:R19)
A22: RAM | B22: 8192
A23: Experiment | B23: Iterations | C23: Setup-Time | D23: Downtime | E23: Total-Time | F23: Ram-Total | G23: Ram-Postcopy-Requests | H23: Ram-Dirty-Sync-Count | I23: Ram-Remaining | J23: Ram-Mbps | K23: Ram-Transferred | L23: Ram-Duplicate | M23: Ram-Dirty-Pages-Rate | N23: Ram-Skipped | O23: Ram-Normal-Bytes | P23: Ram-Normal | Q23: Total-Fake-Dirty-Pages | R23: Total-Transferred-Page-Count
A24: 1 | B24: 4 | C24: 23 | D24: 59 | E24: 32097 | F24: 8607571968 | G24: 0 | H24: 6 | I24: 0 | J24: 921.38635 | K24: 3693855808 | L24: 1339432 | M24: 0 | N24: 0 | O24: 3671814144 | P24: 896439 | Q24: 0 | R24: 2244530
A25: 2 | B25: 5 | C25: 24 | D25: 56 | E25: 32731 | F25: 8607571968 | G25: 0 | H25: 7 | I25: 0 | J25: 921.63862 | K25: 3767791864 | L25: 1357169 | M25: 0 | N25: 0 | O25: 3743260672 | P25: 913882 | Q25: 0 | R25: 2283103
A26: 3 | B26: 4 | C26: 23 | D26: 45 | E26: 32939 | F26: 8607571968 | G26: 0 | H26: 6 | I26: 0 | J26: 919.50117 | K26: 3783075165 | L26: 1334947 | M26: 0 | N26: 0 | O26: 3761385472 | P26: 918307 | Q26: 0 | R26: 2259692
A27: Average | B27: =AVERAGE(B24:B26) | C27: =AVERAGE(C24:C26) | D27: =AVERAGE(D24:D26) | E27: =AVERAGE(E24:E26) | F27: =AVERAGE(F24:F26) | G27: =AVERAGE(G24:G26) | H27: =AVERAGE(H24:H26) | I27: =AVERAGE(I24:I26) | ... R27: =AVERAGE(R24:R26)
A29: RAM | B29: 12288
A30: Experiment | B30: Iterations | C30: Setup-Time | D30: Downtime | E30: Total-Time | F30: Ram-Total | G30: Ram-Postcopy-Requests | H30: Ram-Dirty-Sync-Count | I30: Ram-Remaining | J30: Ram-Mbps | K30: Ram-Transferred | L30: Ram-Duplicate | M30: Ram-Dirty-Pages-Rate | N30: Ram-Skipped | O30: Ram-Normal-Bytes | P30: Ram-Normal | Q30: Total-Fake-Dirty-Pages | R30: Total-Transferred-Page-Count
A31: 1 | B31: 5 | C31: 25 | D31: 51 | E31: 36560 | F31: 12902539264 | G31: 0 | H31: 7 | I31: 0 | J31: 914.83884 | K31: 4177742170 | L31: 2381027 | M31: 0 | N31: 0 | O31: 4144599040 | P31: 1011865 | Q31: 0 | R31: 3405268
A32: 2 | B32: 4 | C32: 25 | D32: 80 | E32: 36812 | F32: 12902539264 | G32: 0 | H32: 6 | I32: 0 | J32: 916.18609 | K32: 4212754794 | L32: 2293389 | M32: 0 | N32: 0 | O32: 4181139456 | P32: 1020786 | Q32: 0 | R32: 3323237
A33: 3 | B33: 4 | C33: 20 | D33: 47 | E33: 37157 | F33: 12902539264 | G33: 0 | H33: 6 | I33: 0 | J33: 916.4691 | K33: 4254151702 | L33: 2260013 | M33: 0 | N33: 0 | O33: 4223766528 | P33: 1031193 | Q33: 0 | R33: 3298745
A34: Average | B34: =AVERAGE(B31:B33) | C34: =AVERAGE(C31:C33) | D34: =AVERAGE(D31:D33) | E34: =AVERAGE(E31:E33) | F34: =AVERAGE(F31:F33) | G34: =AVERAGE(G31:G33) | H34: =AVERAGE(H31:H33) | I34: =AVERAGE(I31:I33) | ... R34: =AVERAGE(R31:R33)
A36: RAM | B36: 16384
A37: Experiment | B37: Iterations | C37: Setup-Time | D37: Downtime | E37: Total-Time | F37: Ram-Total | G37: Ram-Postcopy-Requests | H37: Ram-Dirty-Sync-Count | I37: Ram-Remaining | J37: Ram-Mbps | K37: Ram-Transferred | L37: Ram-Duplicate | M37: Ram-Dirty-Pages-Rate | N37: Ram-Skipped | O37: Ram-Normal-Bytes | P37: Ram-Normal | Q37: Total-Fake-Dirty-Pages | R37: Total-Transferred-Page-Count
A38: 1 | B38: 5 | C38: 24 | D38: 44 | E38: 39607 | F38: 17197506560 | G38: 0 | H38: 7 | I38: 0 | J38: 911.44877 | K38: 4509522162 | L38: 3309656 | M38: 0 | N38: 0 | O38: 4467712000 | P38: 1090750 | Q38: 0 | R38: 4410799
A39: 2 | B39: 5 | C39: 24 | D39: 46 | E39: 39033 | F39: 17197506560 | G39: 0 | H39: 7 | I39: 0 | J39: 912.66587 | K39: 4450060416 | L39: 3382399 | M39: 0 | N39: 0 | O39: 4407066624 | P39: 1075944 | Q39: 0 | R39: 4470534
A40: 3 | B40: 4 | C40: 25 | D40: 45 | E40: 38364 | F40: 17197506560 | G40: 0 | H40: 6 | I40: 0 | J40: 903.56802 | K40: 4330024403 | L40: 3311300 | M40: 0 | N40: 0 | O40: 4289921024 | P40: 1047344 | Q40: 0 | R40: 4365569
A41: Average | B41: =AVERAGE(B38:B40) | C41: =AVERAGE(C38:C40) | D41: =AVERAGE(D38:D40) | E41: =AVERAGE(E38:E40) | F41: =AVERAGE(F38:F40) | G41: =AVERAGE(G38:G40) | H41: =AVERAGE(H38:H40) | I41: =AVERAGE(I38:I40) | ... R41: =AVERAGE(R38:R40)

Sheet Compress
A1: RAM | B1: 1024
A2: Experiment | B2: Iterations | C2: Setup-Time | D2: Downtime | E2: Total-Time | F2: Ram-Total | G2: Ram-Postcopy-Requests | H2: Ram-Dirty-Sync-Count | I2: Ram-Remaining | J2: Ram-Mbps | K2: Ram-Transferred | L2: Ram-Duplicate | M2: Ram-Dirty-Pages-Rate | N2: Ram-Skipped | O2: Ram-Normal-Bytes | P2: Ram-Normal | Q2: Total-Fake-Dirty-Pages | R2: Total-Transferred-Page-Count
A3: 1 | B3: 2 | C3: 2 | D3: 523 | E3: 7014 | F3: 1091379200 | G3: 0 | H3: 4 | I3: 0 | J3: 803.81281 | K3: 704329569 | L3: 11862 | M3: 0 | N3: 0 | O3: 28672 | P3: 7 | Q3: 0 | R3: 291555
A4: 2 | B4: 2 | C4: 3 | D4: 957 | E4: 7453 | F4: 1091379200 | G4: 0 | H4: 4 | I4: 0 | J4: 770.58545 | K4: 717395338 | L4: 11691 | M4: 0 | N4: 0 | O4: 28672 | P4: 7 | Q4: 0 | R4: 294983
A5: 3 | B5: 2 | C5: 3 | D5: 352 | E5: 7645 | F5: 1091379200 | G5: 0 | H5: 4 | I5: 0 | J5: 747.8796 | K5: 714199632 | L5: 9800 | M5: 0 | N5: 0 | O5: 28672 | P5: 7 | Q5: 0 | R5: 293155
A6: Average | B6: =AVERAGE(B3:B5) | C6: =AVERAGE(C3:C5) | D6: =AVERAGE(D3:D5) | E6: =AVERAGE(E3:E5) | F6: =AVERAGE(F3:F5) | G6: =AVERAGE(G3:G5) | H6: =AVERAGE(H3:H5) | I6: =AVERAGE(I3:I5) | ... R6: =AVERAGE(R3:R5)
A8: RAM | B8: 2048
A9: Experiment | B9: Iterations | C9: Setup-Time | D9: Downtime | E9: Total-Time | F9: Ram-Total | G9: Ram-Postcopy-Requests | H9: Ram-Dirty-Sync-Count | I9: Ram-Remaining | J9: Ram-Mbps | K9: Ram-Transferred | L9: Ram-Duplicate | M9: Ram-Dirty-Pages-Rate | N9: Ram-Skipped | O9: Ram-Normal-Bytes | P9: Ram-Normal | Q9: Total-Fake-Dirty-Pages | R9: Total-Transferred-Page-Count
A10: 1 | B10: 3 | C10: 4 | D10: 118 | E10: 14222 | F10: 2165121024 | G10: 0 | H10: 5 | I10: 0 | J10: 875.07597 | K10: 1555016391 | L10: 11456 | M10: 0 | N10: 0 | O10: 28672 | P10: 7 | Q10: 0 | R10: 591126
A11: 2 | B11: 4 | C11: 3 | D11: 38 | E11: 14215 | F11: 2165121024 | G11: 0 | H11: 6 | I11: 0 | J11: 906.61233 | K11: 1610384389 | L11: 12095 | M11: 0 | N11: 0 | O11: 28672 | P11: 7 | Q11: 0 | R11: 611851
A12: 3 | B12: 3 | C12: 2 | D12: 75 | E12: 14250 | F12: 2165121024 | G12: 0 | H12: 5 | I12: 0 | J12: 880.90264 | K12: 1568675213 | L12: 12224 | M12: 0 | N12: 0 | O12: 28672 | P12: 7 | Q12: 0 | R12: 598340
A13: Average | B13: =AVERAGE(B10:B12) | C13: =AVERAGE(C10:C12) | D13: =AVERAGE(D10:D12) | E13: =AVERAGE(E10:E12) | F13: =AVERAGE(F10:F12) | G13: =AVERAGE(G10:G12) | H13: =AVERAGE(H10:H12) | I13: =AVERAGE(I10:I12) | ... R13: =AVERAGE(R10:R12)
A15: RAM | B15: 4096
A16: Experiment | B16: Iterations | C16: Setup-Time | D16: Downtime | E16: Total-Time | F16: Ram-Total | G16: Ram-Postcopy-Requests | H16: Ram-Dirty-Sync-Count | I16: Ram-Remaining | J16: Ram-Mbps | K16: Ram-Transferred | L16: Ram-Duplicate | M16: Ram-Dirty-Pages-Rate | N16: Ram-Skipped | O16: Ram-Normal-Bytes | P16: Ram-Normal | Q16: Total-Fake-Dirty-Pages | R16: Total-Transferred-Page-Count
A17: 1 | B17: 5 | C17: 5 | D17: 90 | E17: 22541 | F17: 4312604672 | G17: 0 | H17: 7 | I17: 0 | J17: 812.8864 | K17: 2289688543 | L17: 290451 | M17: 0 | N17: 0 | O17: 28672 | P17: 7 | Q17: 0 | R17: 1228061
A18: 2 | B18: 5 | C18: 5 | D18: 71 | E18: 22822 | F18: 4312604672 | G18: 0 | H18: 7 | I18: 0 | J18: 832.62872 | K18: 2374548747 | L18: 303501 | M18: 0 | N18: 0 | O18: 28672 | P18: 7 | Q18: 0 | R18: 1247584
A19: 3 | B19: 5 | C19: 5 | D19: 96 | E19: 22536 | F19: 4312604672 | G19: 0 | H19: 7 | I19: 0 | J19: 828.70029 | K19: 2333718344 | L19: 300407 | M19: 0 | N19: 0 | O19: 28672 | P19: 7 | Q19: 0 | R19: 1230083
A20: Average | B20: =AVERAGE(B17:B19) | C20: =AVERAGE(C17:C19) | D20: =AVERAGE(D17:D19) | E20: =AVERAGE(E17:E19) | F20: =AVERAGE(F17:F19) | G20: =AVERAGE(G17:G19) | H20: =AVERAGE(H17:H19) | I20: =AVERAGE(I17:I19) | ... R20: =AVERAGE(R17:R19)
A22: RAM | B22: 8192
A23: Experiment | B23: Iterations | C23: Setup-Time | D23: Downtime | E23: Total-Time | F23: Ram-Total | G23: Ram-Postcopy-Requests | H23: Ram-Dirty-Sync-Count | I23: Ram-Remaining | J23: Ram-Mbps | K23: Ram-Transferred | L23: Ram-Duplicate | M23: Ram-Dirty-Pages-Rate | N23: Ram-Skipped | O23: Ram-Normal-Bytes | P23: Ram-Normal | Q23: Total-Fake-Dirty-Pages | R23: Total-Transferred-Page-Count
A24: 1 | B24: 5 | C24: 6 | D24: 50 | E24: 26661 | F24: 8607571968 | G24: 0 | H24: 7 | I24: 0 | J24: 739.65756 | K24: 2464234095 | L24: 1318375 | M24: 0 | N24: 0 | O24: 28672 | P24: 7 | Q24: 0 | R24: 2308566
A25: 2 | B25: 5 | C25: 6 | D25: 92 | E25: 27942 | F25: 8607571968 | G25: 0 | H25: 7 | I25: 0 | J25: 756.90395 | K25: 2642896163 | L25: 1285692 | M25: 0 | N25: 0 | O25: 28672 | P25: 7 | Q25: 0 | R25: 2334439
A26: 3 | B26: 5 | C26: 9 | D26: 46 | E26: 28698 | F26: 8607571968 | G26: 0 | H26: 7 | I26: 0 | J26: 770.39498 | K26: 2762520274 | L26: 1245669 | M26: 0 | N26: 0 | O26: 28672 | P26: 7 | Q26: 0 | R26: 2335563
A27: Average | B27: =AVERAGE(B24:B26) | C27: =AVERAGE(C24:C26) | D27: =AVERAGE(D24:D26) | E27: =AVERAGE(E24:E26) | F27: =AVERAGE(F24:F26) | G27: =AVERAGE(G24:G26) | H27: =AVERAGE(H24:H26) | I27: =AVERAGE(I24:I26) | ... R27: =AVERAGE(R24:R26)
A29: RAM | B29: 12288
A30: Experiment | B30: Iterations | C30: Setup-Time | D30: Downtime | E30: Total-Time | F30: Ram-Total | G30: Ram-Postcopy-Requests | H30: Ram-Dirty-Sync-Count | I30: Ram-Remaining | J30: Ram-Mbps | K30: Ram-Transferred | L30: Ram-Duplicate | M30: Ram-Dirty-Pages-Rate | N30: Ram-Skipped | O30: Ram-Normal-Bytes | P30: Ram-Normal | Q30: Total-Fake-Dirty-Pages | R30: Total-Transferred-Page-Count
A31: 1 | B31: 5 | C31: 9 | D31: 84 | E31: 31267 | F31: 12902539264 | G31: 0 | H31: 7 | I31: 0 | J31: 669.9783 | K31: 2617560289 | L31: 2339021 | M31: 0 | N31: 0 | O31: 28672 | P31: 7 | Q31: 0 | R31: 3403701
A32: 2 | B32: 5 | C32: 9 | D32: 71 | E32: 31354 | F32: 12902539264 | G32: 0 | H32: 7 | I32: 0 | J32: 700.74093 | K32: 2745378121 | L32: 2287358 | M32: 0 | N32: 0 | O32: 28672 | P32: 7 | Q32: 0 | R32: 3390567
A33: 3 | B33: 5 | C33: 7 | D33: 32 | E33: 31020 | F33: 12902539264 | G33: 0 | H33: 7 | I33: 0 | J33: 697.56535 | K33: 2703986854 | L33: 2278706 | M33: 0 | N33: 0 | O33: 36864 | P33: 9 | Q33: 0 | R33: 3364220
A34: Average | B34: =AVERAGE(B31:B33) | C34: =AVERAGE(C31:C33) | D34: =AVERAGE(D31:D33) | E34: =AVERAGE(E31:E33) | F34: =AVERAGE(F31:F33) | G34: =AVERAGE(G31:G33) | H34: =AVERAGE(H31:H33) | I34: =AVERAGE(I31:I33) | ... R34: =AVERAGE(R31:R33)
A36: RAM | B36: 16384
A37: Experiment | B37: Iterations | C37: Setup-Time | D37: Downtime | E37: Total-Time | F37: Ram-Total | G37: Ram-Postcopy-Requests | H37: Ram-Dirty-Sync-Count | I37: Ram-Remaining | J37: Ram-Mbps | K37: Ram-Transferred | L37: Ram-Duplicate | M37: Ram-Dirty-Pages-Rate | N37: Ram-Skipped | O37: Ram-Normal-Bytes | P37: Ram-Normal | Q37: Total-Fake-Dirty-Pages | R37: Total-Transferred-Page-Count
A38: 1 | B38: 5 | C38: 10 | D38: 86 | E38: 33263 | F38: 17197506560 | G38: 0 | H38: 7 | I38: 0 | J38: 662.14621 | K38: 2752081057 | L38: 3328500 | M38: 0 | N38: 0 | O38: 28672 | P38: 7 | Q38: 0 | R38: 4444449
A39: 2 | B39: 5 | C39: 10 | D39: 84 | E39: 33749 | F39: 17197506560 | G39: 0 | H39: 7 | I39: 0 | J39: 642.76084 | K39: 2710551044 | L39: 3360503 | M39: 0 | N39: 0 | O39: 28672 | P39: 7 | Q39: 0 | R39: 4458435
A40: 3 | B40: 5 | C40: 10 | D40: 89 | E40: 33282 | F40: 17197506560 | G40: 0 | H40: 7 | I40: 0 | J40: 631.1182 | K40: 2624608147 | L40: 3371425 | M40: 0 | N40: 0 | O40: 28672 | P40: 7 | Q40: 0 | R40: 4438580
A41: Average | B41: =AVERAGE(B38:B40) | C41: =AVERAGE(C38:C40) | D41: =AVERAGE(D38:D40) | E41: =AVERAGE(E38:E40) | F41: =AVERAGE(F38:F40) | G41: =AVERAGE(G38:G40) | H41: =AVERAGE(H38:H40) | I41: =AVERAGE(I38:I40) | ... R41: =AVERAGE(R38:R40)

Sheet HBFDP_SHA1
A1: RAM | B1: 1024
A2: Experiment | B2: Iterations | C2: Setup-Time | D2: Downtime | E2: Total-Time | F2: Ram-Total | G2: Ram-Postcopy-Requests | H2: Ram-Dirty-Sync-Count | I2: Ram-Remaining | J2: Ram-Mbps | K2: Ram-Transferred | L2: Ram-Duplicate | M2: Ram-Dirty-Pages-Rate | N2: Ram-Skipped | O2: Ram-Normal-Bytes | P2: Ram-Normal | Q2: Total-Fake-Dirty-Pages | R2: Total-Transferred-Page-Count
A3: 1 | B3: 2 | C3: 1 | D3: 435 | E3: 10205 | F3: 1091379200 | G3: 0 | H3: 4 | I3: 0 | J3: 868.66588 | K3: 1107770969 | L3: 9875 | M3: 0 | N3: 0 | O3: 1105522688 | P3: 269903 | Q3: 20851 | R3: 279778
A4: 2 | B4: 3 | C4: 2 | D4: 370 | E4: 10312 | F4: 1091379200 | G4: 0 | H4: 5 | I4: 0 | J4: 891.49506 | K4: 1148701870 | L4: 10976 | M4: 0 | N4: 0 | O4: 1146363904 | P4: 279874 | Q4: 27268 | R4: 290850
A5: 3 | B5: 2 | C5: 1 | D5: 465 | E5: 10397 | F5: 1091379200 | G5: 0 | H5: 4 | I5: 0 | J5: 856.64972 | K5: 1113003947 | L5: 10829 | M5: 0 | N5: 0 | O5: 1110736896 | P5: 271176 | Q5: 20773 | R5: 282005
A6: Average | B6: =AVERAGE(B3:B5) | C6: =AVERAGE(C3:C5) | D6: =AVERAGE(D3:D5) | E6: =AVERAGE(E3:E5) | F6: =AVERAGE(F3:F5) | G6: =AVERAGE(G3:G5) | H6: =AVERAGE(H3:H5) | I6: =AVERAGE(I3:I5) | ... R6: =AVERAGE(R3:R5)
A8: RAM | B8: 2048
A9: Experiment | B9: Iterations | C9: Setup-Time | D9: Downtime | E9: Total-Time | F9: Ram-Total | G9: Ram-Postcopy-Requests | H9: Ram-Dirty-Sync-Count | I9: Ram-Remaining | J9: Ram-Mbps | K9: Ram-Transferred | L9: Ram-Duplicate | M9: Ram-Dirty-Pages-Rate | N9: Ram-Skipped | O9: Ram-Normal-Bytes | P9: Ram-Normal | Q9: Total-Fake-Dirty-Pages | R9: Total-Transferred-Page-Count
A10: 1 | B10: 3 | C10: 3 | D10: 203 | E10: 20047 | F10: 2165121024 | G10: 0 | H10: 5 | I10: 0 | J10: 921.97586 | K10: 2309798143 | L10: 11977 | M10: 0 | N10: 0 | O10: 2305187840 | P10: 562790 | Q10: 42511 | R10: 574767
A11: 2 | B11: 3 | C11: 1 | D11: 311 | E11: 20120 | F11: 2165121024 | G11: 0 | H11: 5 | I11: 0 | J11: 903.41284 | K11: 2271757987 | L11: 13325 | M11: 0 | N11: 0 | O11: 2267209728 | P11: 553518 | Q11: 54590 | R11: 566843
A12: 3 | B12: 3 | C12: 2 | D12: 142 | E12: 19831 | F12: 2165121024 | G12: 0 | H12: 5 | I12: 0 | J12: 928.79856 | K12: 2301930946 | L12: 11996 | M12: 0 | N12: 0 | O12: 2297335808 | P12: 560873 | Q12: 50604 | R12: 572869
A13: Average | B13: =AVERAGE(B10:B12) | C13: =AVERAGE(C10:C12) | D13: =AVERAGE(D10:D12) | E13: =AVERAGE(E10:E12) | F13: =AVERAGE(F10:F12) | G13: =AVERAGE(G10:G12) | H13: =AVERAGE(H10:H12) | I13: =AVERAGE(I10:I12) | ... R13: =AVERAGE(R10:R12)
A15: RAM | B15: 4096
A16: Experiment | B16: Iterations | C16: Setup-Time | D16: Downtime | E16: Total-Time | F16: Ram-Total | G16: Ram-Postcopy-Requests | H16: Ram-Dirty-Sync-Count | I16: Ram-Remaining | J16: Ram-Mbps | K16: Ram-Transferred | L16: Ram-Duplicate | M16: Ram-Dirty-Pages-Rate | N16: Ram-Skipped | O16: Ram-Normal-Bytes | P16: Ram-Normal | Q16: Total-Fake-Dirty-Pages | R16: Total-Transferred-Page-Count
A17: 1 | B17: 4 | C17: 3 | D17: 51 | E17: 34462 | F17: 4312604672 | G17: 0 | H17: 6 | I17: 0 | J17: 857.02131 | K17: 3691299744 | L17: 246906 | M17: 0 | N17: 0 | O17: 3681886208 | P17: 898898 | Q17: 42065 | R17: 1145804
A18: 2 | B18: 4 | C18: 4 | D18: 51 | E18: 33145 | F18: 4312604672 | G18: 0 | H18: 6 | I18: 0 | J18: 832.32706 | K18: 3447806490 | L18: 304036 | M18: 0 | N18: 0 | O18: 3438354432 | P18: 839442 | Q18: 66507 | R18: 1143478
A19: 3 | B19: 4 | C19: 3 | D19: 75 | E19: 33671 | F19: 4312604672 | G19: 0 | H19: 6 | I19: 0 | J19: 801.94386 | K19: 3374768313 | L19: 319619 | M19: 0 | N19: 0 | O19: 3365318656 | P19: 821611 | Q19: 174820 | R19: 1141230
A20: Average | B20: =AVERAGE(B17:B19) | C20: =AVERAGE(C17:C19) | D20: =AVERAGE(D17:D19) | E20: =AVERAGE(E17:E19) | F20: =AVERAGE(F17:F19) | G20: =AVERAGE(G17:G19) | H20: =AVERAGE(H17:H19) | I20: =AVERAGE(I17:I19) | ... R20: =AVERAGE(R17:R19)
A22: RAM | B22: 8192
A23: Experiment | B23: Iterations | C23: Setup-Time | D23: Downtime | E23: Total-Time | F23: Ram-Total | G23: Ram-Postcopy-Requests | H23: Ram-Dirty-Sync-Count | I23: Ram-Remaining | J23: Ram-Mbps | K23: Ram-Transferred | L23: Ram-Duplicate | M23: Ram-Dirty-Pages-Rate | N23: Ram-Skipped | O23: Ram-Normal-Bytes | P23: Ram-Normal | Q23: Total-Fake-Dirty-Pages | R23: Total-Transferred-Page-Count
A24: 1 | B24: 3 | C24: 5 | D24: 32 | E24: 43439 | F24: 8607571968 | G24: 0 | H24: 5 | I24: 0 | J24: 667.73379 | K24: 3625081300 | L24: 1255534 | M24: 0 | N24: 0 | O24: 3606736896 | P24: 880551 | Q24: 88317 | R24: 2136085
A25: 2 | B25: 4 | C25: 6 | D25: 51 | E25: 43226 | F25: 8607571968 | G25: 0 | H25: 6 | I25: 0 | J25: 656.45066 | K25: 3546262296 | L25: 1330586 | M25: 0 | N25: 0 | O25: 3527397376 | P25: 861181 | Q25: 56886 | R25: 2191767
A26: 3 | B26: 4 | C26: 5 | D26: 54 | E26: 43495 | F26: 8607571968 | G26: 0 | H26: 6 | I26: 0 | J26: 650.04262 | K26: 3533581802 | L26: 1339343 | M26: 0 | N26: 0 | O26: 3514662912 | P26: 858072 | Q26: 70915 | R26: 2197415
A27: Average | B27: =AVERAGE(B24:B26) | C27: =AVERAGE(C24:C26) | D27: =AVERAGE(D24:D26) | E27: =AVERAGE(E24:E26) | F27: =AVERAGE(F24:F26) | G27: =AVERAGE(G24:G26) | H27: =AVERAGE(H24:H26) | I27: =AVERAGE(I24:I26) | ... R27: =AVERAGE(R24:R26)
A29: RAM | B29: 12288
A30: Experiment | B30: Iterations | C30: Setup-Time | D30: Downtime | E30: Total-Time | F30: Ram-Total | G30: Ram-Postcopy-Requests | H30: Ram-Dirty-Sync-Count | I30: Ram-Remaining | J30: Ram-Mbps | K30: Ram-Transferred | L30: Ram-Duplicate | M30: Ram-Dirty-Pages-Rate | N30: Ram-Skipped | O30: Ram-Normal-Bytes | P30: Ram-Normal | Q30: Total-Fake-Dirty-Pages | R30: Total-Transferred-Page-Count
A31: 1 | B31: 4 | C31: 7 | D31: 50 | E31: 58121 | F31: 12902539264 | G31: 0 | H31: 6 | I31: 0 | J31: 601.50868 | K31: 4369297041 | L31: 2210907 | M31: 0 | N31: 0 | O31: 4340920320 | P31: 1059795 | Q31: 105074 | R31: 3270702
A32: 2 | B32: 4 | C32: 6 | D32: 35 | E32: 58277 | F32: 12902539264 | G32: 0 | H32: 6 | I32: 0 | J32: 593.81234 | K32: 4325042466 | L32: 2213972 | M32: 0 | N32: 0 | O32: 4296724480 | P32: 1049005 | Q32: 79234 | R32: 3262977
A33: 3 | B33: 4 | C33: 7 | D33: 55 | E33: 58478 | F33: 12902539264 | G33: 0 | H33: 6 | I33: 0 | J33: 576.22994 | K33: 4211380215 | L33: 2251601 | M33: 0 | N33: 0 | O33: 4182945792 | P33: 1021227 | Q33: 102908 | R33: 3272828
A34: Average | B34: =AVERAGE(B31:B33) | C34: =AVERAGE(C31:C33) | D34: =AVERAGE(D31:D33) | E34: =AVERAGE(E31:E33) | F34: =AVERAGE(F31:F33) | G34: =AVERAGE(G31:G33) | H34: =AVERAGE(H31:H33) | I34: =AVERAGE(I31:I33) | ... R34: =AVERAGE(R31:R33)
A36: RAM | B36: 16384
A37: Experiment | B37: Iterations | C37: Setup-Time | D37: Downtime | E37: Total-Time | F37: Ram-Total | G37: Ram-Postcopy-Requests | H37: Ram-Dirty-Sync-Count | I37: Ram-Remaining | J37: Ram-Mbps | K37: Ram-Transferred | L37: Ram-Duplicate | M37: Ram-Dirty-Pages-Rate | N37: Ram-Skipped | O37: Ram-Normal-Bytes | P37: Ram-Normal | Q37: Total-Fake-Dirty-Pages | R37: Total-Transferred-Page-Count
A38: 1 | B38: 4 | C38: 10 | D38: 56 | E38: 66340 | F38: 17197506560 | G38: 0 | H38: 6 | I38: 0 | J38: 496.6431 | K38: 4117579659 | L38: 3324165 | M38: 0 | N38: 0 | O38: 4079693824 | P38: 996019 | Q38: 133666 | R38: 4320184
A39: 2 | B39: 4 | C39: 10 | D39: 52 | E39: 66724 | F39: 17197506560 | G39: 0 | H39: 6 | I39: 0 | J39: 488.624 | K39: 4074545250 | L39: 3325092 | M39: 0 | N39: 0 | O39: 4036734976 | P39: 985531 | Q39: 174666 | R39: 4310623
A40: 3 | B40: 4 | C40: 9 | D40: 59 | E40: 66383 | F40: 17197506560 | G40: 0 | H40: 6 | I40: 0 | J40: 490.88618 | K40: 4072547538 | L40: 3327020 | M40: 0 | N40: 0 | O40: 4034723840 | P40: 985040 | Q40: 105133 | R40: 4312060
A41: Average | B41: =AVERAGE(B38:B40) | C41: =AVERAGE(C38:C40) | D41: =AVERAGE(D38:D40) | E41: =AVERAGE(E38:E40) | F41: =AVERAGE(F38:F40) | G41: =AVERAGE(G38:G40) | H41: =AVERAGE(H38:H40) | I41: =AVERAGE(I38:I40) | ... R41: =AVERAGE(R38:R40)

Sheet HBFDP_MD5
A1: RAM | B1: 1024
A2: Experiment | B2: Iterations | C2: Setup-Time | D2: Downtime | E2: Total-Time | F2: Ram-Total | G2: Ram-Postcopy-Requests | H2: Ram-Dirty-Sync-Count | I2: Ram-Remaining | J2: Ram-Mbps | K2: Ram-Transferred | L2: Ram-Duplicate | M2: Ram-Dirty-Pages-Rate | N2: Ram-Skipped | O2: Ram-Normal-Bytes | P2: Ram-Normal | Q2: Total-Fake-Dirty-Pages | R2: Total-Transferred-Page-Count
A3: 1 | B3: 2 | C3: 2 | D3: 62 | E3: 10449 | F3: 1091379200 | G3: 0 | H3: 4 | I3: 0 | J3: 843.17301 | K3: 1100866196 | L3: 11494 | M3: 0 | N3: 0 | O3: 1098616832 | P3: 268217 | Q3: 22461 | R3: 279711
A4: 2 | B4: 2 | C4: 1 | D4: 506 | E4: 10654 | F4: 1091379200 | G4: 0 | H4: 4 | I4: 0 | J4: 830.33363 | K4: 1105480658 | L4: 11212 | M4: 0 | N4: 0 | O4: 1103224832 | P4: 269342 | Q4: 19554 | R4: 280554
A5: 3 | B5: 2 | C5: 1 | D5: 548 | E5: 10524 | F5: 1091379200 | G5: 0 | H5: 4 | I5: 0 | J5: 838.42992 | K5: 1102637396 | L5: 11758 | M5: 0 | N5: 0 | O5: 1100382208 | P5: 268648 | Q5: 24287 | R5: 280406
A6: Average | B6: =AVERAGE(B3:B5) | C6: =AVERAGE(C3:C5) | D6: =AVERAGE(D3:D5) | E6: =AVERAGE(E3:E5) | F6: =AVERAGE(F3:F5) | G6: =AVERAGE(G3:G5) | H6: =AVERAGE(H3:H5) | I6: =AVERAGE(I3:I5) | ... R6: =AVERAGE(R3:R5)
A8: RAM | B8: 2048
A9: Experiment | B9: Iterations | C9: Setup-Time | D9: Downtime | E9: Total-Time | F9: Ram-Total | G9: Ram-Postcopy-Requests | H9: Ram-Dirty-Sync-Count | I9: Ram-Remaining | J9: Ram-Mbps | K9: Ram-Transferred | L9: Ram-Duplicate | M9: Ram-Dirty-Pages-Rate | N9: Ram-Skipped | O9: Ram-Normal-Bytes | P9: Ram-Normal | Q9: Total-Fake-Dirty-Pages | R9: Total-Transferred-Page-Count
A10: 1 | B10: 3 | C10: 2 | D10: 41 | E10: 21231 | F10: 2165121024 | G10: 0 | H10: 5 | I10: 0 | J10: 873.08273 | K10: 2316621774 | L10: 12739 | M10: 0 | N10: 0 | O10: 2311991296 | P10: 564451 | Q10: 49823 | R10: 577190
A11: 2 | B11: 2 | C11: 2 | D11: 510 | E11: 20689 | F11: 2165121024 | G11: 0 | H11: 4 | I11: 0 | J11: 844.93483 | K11: 2184683492 | L11: 12422 | M11: 0 | N11: 0 | O11: 2180313088 | P11: 532303 | Q11: 26764 | R11: 544725
A12: 3 | B12: 3 | C12: 2 | D12: 62 | E12: 20797 | F12: 2165121024 | G12: 0 | H12: 5 | I12: 0 | J12: 890.51278 | K12: 2314564273 | L12: 12587 | M12: 0 | N12: 0 | O12: 2309939200 | P12: 563950 | Q12: 57074 | R12: 576537
A13: Average | B13: =AVERAGE(B10:B12) | C13: =AVERAGE(C10:C12) | D13: =AVERAGE(D10:D12) | E13: =AVERAGE(E10:E12) | F13: =AVERAGE(F10:F12) | G13: =AVERAGE(G10:G12) | H13: =AVERAGE(H10:H12) | I13: =AVERAGE(I10:I12) | ... R13: =AVERAGE(R10:R12)
A15: RAM | B15: 4096
A16: Experiment | B16: Iterations | C16: Setup-Time | D16: Downtime | E16: Total-Time | F16: Ram-Total | G16: Ram-Postcopy-Requests | H16: Ram-Dirty-Sync-Count | I16: Ram-Remaining | J16: Ram-Mbps | K16: Ram-Transferred | L16: Ram-Duplicate | M16: Ram-Dirty-Pages-Rate | N16: Ram-Skipped | O16: Ram-Normal-Bytes | P16: Ram-Normal | Q16: Total-Fake-Dirty-Pages | R16: Total-Transferred-Page-Count
A17: 1 | B17: 4 | C17: 3 | D17: 53 | E17: 35074 | F17: 4312604672 | G17: 0 | H17: 6 | I17: 0 | J17: 849.17178 | K17: 3722450535 | L17: 249345 | M17: 0 | N17: 0 | O17: 3712954368 | P17: 906483 | Q17: 52362 | R17: 1155828
A18: 2 | B18: 5 | C18: 3 | D18: 33 | E18: 35527 | F18: 4312604672 | G18: 0 | H18: 7 | I18: 0 | J18: 816.7626 | K18: 3626621909 | L18: 265735 | M18: 0 | N18: 0 | O18: 3617165312 | P18: 883097 | Q18: 164577 | R18: 1148832
A19: 3 | B19: 4 | C19: 3 | D19: 66 | E19: 35291 | F19: 4312604672 | G19: 0 | H19: 6 | I19: 0 | J19: 826.18725 | K19: 3644099541 | L19: 256471 | M19: 0 | N19: 0 | O19: 3634692096 | P19: 887376 | Q19: 104547 | R19: 1143847
A20: Average | B20: =AVERAGE(B17:B19) | C20: =AVERAGE(C17:C19) | D20: =AVERAGE(D17:D19) | E20: =AVERAGE(E17:E19) | F20: =AVERAGE(F17:F19) | G20: =AVERAGE(G17:G19) | H20: =AVERAGE(H17:H19) | I20: =AVERAGE(I17:I19) | ... R20: =AVERAGE(R17:R19)
A22: RAM | B22: 8192
A23: Experiment | B23: Iterations | C23: Setup-Time | D23: Downtime | E23: Total-Time | F23: Ram-Total | G23: Ram-Postcopy-Requests | H23: Ram-Dirty-Sync-Count | I23: Ram-Remaining | J23: Ram-Mbps | K23: Ram-Transferred | L23: Ram-Duplicate | M23: Ram-Dirty-Pages-Rate | N23: Ram-Skipped | O23: Ram-Normal-Bytes | P23: Ram-Normal | Q23: Total-Fake-Dirty-Pages | R23: Total-Transferred-Page-Count
A24: 1 | B24: 4 | C24: 5 | D24: 56 | E24: 47675 | F24: 8607571968 | G24: 0 | H24: 6 | I24: 0 | J24: 659.47988 | K24: 3929463315 | L24: 1249677 | M24: 0 | N24: 0 | O24: 3910578176 | P24: 954731 | Q24: 65938 | R24: 2204408
A25: 2 | B25: 4 | C25: 6 | D25: 69 | E25: 47361 | F25: 8607571968 | G25: 0 | H25: 6 | I25: 0 | J25: 638.43271 | K25: 3778910235 | L25: 1292325 | M25: 0 | N25: 0 | O25: 3759935488 | P25: 917953 | Q25: 91733 | R25: 2210278
A26: 3 | B26: 4 | C26: 5 | D26: 38 | E26: 47662 | F26: 8607571968 | G26: 0 | H26: 6 | I26: 0 | J26: 672.24395 | K26: 4004428833 | L26: 1230275 | M26: 0 | N26: 0 | O26: 3985571840 | P26: 973040 | Q26: 38567 | R26: 2203315
A27: Average | B27: =AVERAGE(B24:B26) | C27: =AVERAGE(C24:C26) | D27: =AVERAGE(D24:D26) | E27: =AVERAGE(E24:E26) | F27: =AVERAGE(F24:F26) | G27: =AVERAGE(G24:G26) | H27: =AVERAGE(H24:H26) | I27: =AVERAGE(I24:I26) | ... R27: =AVERAGE(R24:R26)
A29: RAM | B29: 12288
A30: Experiment | B30: Iterations | C30: Setup-Time | D30: Downtime | E30: Total-Time | F30: Ram-Total | G30: Ram-Postcopy-Requests | H30: Ram-Dirty-Sync-Count | I30: Ram-Remaining | J30: Ram-Mbps | K30: Ram-Transferred | L30: Ram-Duplicate | M30: Ram-Dirty-Pages-Rate | N30: Ram-Skipped | O30: Ram-Normal-Bytes | P30: Ram-Normal | Q30: Total-Fake-Dirty-Pages | R30: Total-Transferred-Page-Count
A31: 1 | B31: 5 | C31: 7 | D31: 40 | E31: 60437 | F31: 12902539264 | G31: 0 | H31: 7 | I31: 0 | J31: 546.0829 | K31: 4124761307 | L31: 2280797 | M31: 0 | N31: 0 | O31: 4096233472 | P31: 1000057 | Q31: 116832 | R31: 3280854
A32: 2 | B32: 4 | C32: 7 | D32: 68 | E32: 60728 | F32: 12902539264 | G32: 0 | H32: 6 | I32: 0 | J32: 552.07427 | K32: 4190100282 | L32: 2254260 | M32: 0 | N32: 0 | O32: 4161683456 | P32: 1016036 | Q32: 103559 | R32: 3270296
A33: 3 | B33: 4 | C33: 7 | D33: 70 | E33: 59603 | F33: 12902539264 | G33: 0 | H33: 6 | I33: 0 | J33: 508.12674 | K33: 3785077764 | L33: 2342406 | M33: 0 | N33: 0 | O33: 3756658688 | P33: 917153 | Q33: 206975 | R33: 3259559
A34: Average | B34: =AVERAGE(B31:B33) | C34: =AVERAGE(C31:C33) | D34: =AVERAGE(D31:D33) | E34: =AVERAGE(E31:E33) | F34: =AVERAGE(F31:F33) | G34: =AVERAGE(G31:G33) | H34: =AVERAGE(H31:H33) | I34: =AVERAGE(I31:I33) | ... R34: =AVERAGE(R31:R33)
A36: RAM | B36: 16384
A37: Experiment | B37: Iterations | C37: Setup-Time | D37: Downtime | E37: Total-Time | F37: Ram-Total | G37: Ram-Postcopy-Requests | H37: Ram-Dirty-Sync-Count | I37: Ram-Remaining | J37: Ram-Mbps | K37: Ram-Transferred | L37: Ram-Duplicate | M37: Ram-Dirty-Pages-Rate | N37: Ram-Skipped | O37: Ram-Normal-Bytes | P37: Ram-Normal | Q37: Total-Fake-Dirty-Pages | R37: Total-Transferred-Page-Count
A38: 1 | B38: 4 | C38: 7 | D38: 83 | E38: 74855 | F38: 17197506560 | G38: 0 | H38: 6 | I38: 0 | J38: 484.68153 | K38: 4534467957 | L38: 3234319 | M38: 0 | N38: 0 | O38: 4496576512 | P38: 1097797 | Q38: 201304 | R38: 4332116
A39: 2 | B39: 4 | C39: 9 | D39: 70 | E39: 74090 | F39: 17197506560 | G39: 0 | H39: 6 | I39: 0 | J39: 466.35857 | K39: 4318326261 | L39: 3288079 | M39: 0 | N39: 0 | O39: 4280373248 | P39: 1045013 | Q39: 226066 | R39: 4333092
A40: 3 | B40: 5 | C40: 9 | D40: 42 | E40: 73735 | F40: 17197506560 | G40: 0 | H40: 7 | I40: 0 | J40: 492.83774 | K40: 4541656940 | L40: 3237830 | M40: 0 | N40: 0 | O40: 4503719936 | P40: 1099541 | Q40: 174535 | R40: 4337371
A41: Average | B41: =AVERAGE(B38:B40) | C41: =AVERAGE(C38:C40) | D41: =AVERAGE(D38:D40) | E41: =AVERAGE(E38:E40) | F41: =AVERAGE(F38:F40) | G41: =AVERAGE(G38:G40) | H41: =AVERAGE(H38:H40) | I41: =AVERAGE(I38:I40) | ... R41: =AVERAGE(R38:R40)

Sheet HBFDP_Murmur3
A1: RAM | B1: 1024
A2: Experiment | B2: Iterations | C2: Setup-Time | D2: Downtime | E2: Total-Time | F2: Ram-Total | G2: Ram-Postcopy-Requests | H2: Ram-Dirty-Sync-Count | I2: Ram-Remaining | J2: Ram-Mbps | K2: Ram-Transferred | L2: Ram-Duplicate | M2: Ram-Dirty-Pages-Rate | N2: Ram-Skipped | O2: Ram-Normal-Bytes | P2: Ram-Normal | Q2: Total-Fake-Dirty-Pages | R2: Total-Transferred-Page-Count
A3: 1 | B3: 2 | C3: 1 | D3: 123 | E3: 10161 | F3: 1091379200 | G3: 0 | H3: 4 | I3: 0 | J3: 868.43229 | K3: 1102696652 | L3: 10134 | M3: 0 | N3: 0 | O3: 1100455936 | P3: 268666 | Q3: 22306 | R3: 278800
A4: 2 | B4: 2 | C4: 1 | D4: 369 | E4: 10110 | F4: 1091379200 | G4: 0 | H4: 4 | I4: 0 | J4: 876.60678 | K4: 1107489890 | L4: 11476 | M4: 0 | N4: 0 | O4: 1105227776 | P4: 269831 | Q4: 22143 | R4: 281307
A5: 3 | B5: 2 | C5: 2 | D5: 336 | E5: 10171 | F5: 1091379200 | G5: 0 | H5: 4 | I5: 0 | J5: 865.6519 | K5: 1100139410 | L5: 10996 | M5: 0 | N5: 0 | O5: 1097895936 | P5: 268041 | Q5: 18750 | R5: 279037
A6: Average | B6: =AVERAGE(B3:B5) | C6: =AVERAGE(C3:C5) | D6: =AVERAGE(D3:D5) | E6: =AVERAGE(E3:E5) | F6: =AVERAGE(F3:F5) | G6: =AVERAGE(G3:G5) | H6: =AVERAGE(H3:H5) | I6: =AVERAGE(I3:I5) | ... R6: =AVERAGE(R3:R5)
A8: RAM | B8: 2048
A9: Experiment | B9: Iterations | C9: Setup-Time | D9: Downtime | E9: Total-Time | F9: Ram-Total | G9: Ram-Postcopy-Requests | H9: Ram-Dirty-Sync-Count | I9: Ram-Remaining | J9: Ram-Mbps | K9: Ram-Transferred | L9: Ram-Duplicate | M9: Ram-Dirty-Pages-Rate | N9: Ram-Skipped | O9: Ram-Normal-Bytes | P9: Ram-Normal | Q9: Total-Fake-Dirty-Pages | R9: Total-Transferred-Page-Count
A10: 1 | B10: 3 | C10: 2 | D10: 66 | E10: 20347 | F10: 2165121024 | G10: 0 | H10: 5 | I10: 0 | J10: 902.9807 | K10: 2296180405 | L10: 11903 | M10: 0 | N10: 0 | O10: 2291597312 | P10: 559472 | Q10: 70316 | R10: 571375
A11: 2 | B11: 3 | C11: 2 | D11: 63 | E11: 20366 | F11: 2165121024 | G11: 0 | H11: 5 | I11: 0 | J11: 914.6679 | K11: 2328074758 | L11: 13056 | M11: 0 | N11: 0 | O11: 2323419136 | P11: 567241 | Q11: 64003 | R11: 580297
A12: 3 | B12: 3 | C12: 2 | D12: 96 | E12: 20549 | F12: 2165121024 | G12: 0 | H12: 5 | I12: 0 | J12: 900.0149 | K12: 2311363387 | L12: 11701 | M12: 0 | N12: 0 | O12: 2306752512 | P12: 563172 | Q12: 53691 | R12: 574873
A13: Average | B13: =AVERAGE(B10:B12) | C13: =AVERAGE(C10:C12) | D13: =AVERAGE(D10:D12) | E13: =AVERAGE(E10:E12) | F13: =AVERAGE(F10:F12) | G13: =AVERAGE(G10:G12) | H13: =AVERAGE(H10:H12) | I13: =AVERAGE(I10:I12) | ... R13: =AVERAGE(R10:R12)
A15: RAM | B15: 4096
A16: Experiment | B16: Iterations | C16: Setup-Time | D16: Downtime | E16: Total-Time | F16: Ram-Total | G16: Ram-Postcopy-Requests | H16: Ram-Dirty-Sync-Count | I16: Ram-Remaining | J16: Ram-Mbps | K16: Ram-Transferred | L16: Ram-Duplicate | M16: Ram-Dirty-Pages-Rate | N16: Ram-Skipped | O16: Ram-Normal-Bytes | P16: Ram-Normal | Q16: Total-Fake-Dirty-Pages | R16: Total-Transferred-Page-Count
A17: 1 | B17: 4 | C17: 3 | D17: 49 | E17: 33845 | F17: 4312604672 | G17: 0 | H17: 6 | I17: 0 | J17: 838.0728 | K17: 3545045037 | L17: 283791 | M17: 0 | N17: 0 | O17: 3535585280 | P17: 863180 | Q17: 92399 | R17: 1146971
A18: 2 | B18: 4 | C18: 4 | D18: 55 | E18: 33405 | F18: 4312604672 | G18: 0 | H18: 6 | I18: 0 | J18: 807.02605 | K18: 3369222209 | L18: 315790 | M18: 0 | N18: 0 | O18: 3359817728 | P18: 820268 | Q18: 146473 | R18: 1136058
A19: 3 | B19: 4 | C19: 3 | D19: 45 | E19: 33523 | F19: 4312604672 | G19: 0 | H19: 6 | I19: 0 | J19: 844.24663 | K19: 3537180981 | L19: 278687 | M19: 0 | N19: 0 | O19: 3527782400 | P19: 861275 | Q19: 38075 | R19: 1139962
A20: Average | B20: =AVERAGE(B17:B19) | C20: =AVERAGE(C17:C19) | D20: =AVERAGE(D17:D19) | E20: =AVERAGE(E17:E19) | F20: =AVERAGE(F17:F19) | G20: =AVERAGE(G17:G19) | H20: =AVERAGE(H17:H19) | I20: =AVERAGE(I17:I19) | ... R20: =AVERAGE(R17:R19)
A22: RAM | B22: 8192
A23: Experiment | B23: Iterations | C23: Setup-Time | D23: Downtime | E23: Total-Time | F23: Ram-Total | G23: Ram-Postcopy-Requests | H23: Ram-Dirty-Sync-Count | I23: Ram-Remaining | J23: Ram-Mbps | K23: Ram-Transferred | L23: Ram-Duplicate | M23: Ram-Dirty-Pages-Rate | N23: Ram-Skipped | O23: Ram-Normal-Bytes | P23: Ram-Normal | Q23: Total-Fake-Dirty-Pages | R23: Total-Transferred-Page-Count
A24: 1 | B24: 4 | C24: 5 | D24: 44 | E24: 44809 | F24: 8607571968 | G24: 0 | H24: 6 | I24: 0 | J24: 654.81907 | K24: 3667101777 | L24: 1310211 | M24: 0 | N24: 0 | O24: 3648184320 | P24: 890670 | Q24: 87455 | R24: 2200881
A25: 2 | B25: 4 | C25: 5 | D25: 46 | E25: 43458 | F25: 8607571968 | G25: 0 | H25: 6 | I25: 0 | J25: 637.2703 | K25: 3461200866 | L25: 1350892 | M25: 0 | N25: 0 | O25: 3442319360 | P25: 840410 | Q25: 68315 | R25: 2191302
A26: 3 | B26: 4 | C26: 5 | D26: 37 | E26: 42969 | F26: 8607571968 | G26: 0 | H26: 6 | I26: 0 | J26: 647.46507 | K26: 3476998773 | L26: 1345143 | M26: 0 | N26: 0 | O26: 3458138112 | P26: 844272 | Q26: 70913 | R26: 2189415
A27: Average | B27: =AVERAGE(B24:B26) | C27: =AVERAGE(C24:C26) | D27: =AVERAGE(D24:D26) | E27: =AVERAGE(E24:E26) | F27: =AVERAGE(F24:F26) | G27: =AVERAGE(G24:G26) | H27: =AVERAGE(H24:H26) | I27: =AVERAGE(I24:I26) | ... R27: =AVERAGE(R24:R26)
A29: RAM | B29: 12288
A30: Experiment | B30: Iterations | C30: Setup-Time | D30: Downtime | E30: Total-Time | F30: Ram-Total | G30: Ram-Postcopy-Requests | H30: Ram-Dirty-Sync-Count | I30: Ram-Remaining | J30: Ram-Mbps | K30: Ram-Transferred | L30: Ram-Duplicate | M30: Ram-Dirty-Pages-Rate | N30: Ram-Skipped | O30: Ram-Normal-Bytes | P30: Ram-Normal | Q30: Total-Fake-Dirty-Pages | R30: Total-Transferred-Page-Count
A31: 1 | B31: 4 | C31: 8 | D31: 42 | E31: 55678 | F31: 12902539264 | G31: 0 | H31: 6 | I31: 0 | J31: 570.60058 | K31: 3970454355 | L31: 2300333 | M31: 0 | N31: 0 | O31: 3942051840 | P31: 962415 | Q31: 97309 | R31: 3262748
A32: 2 | B32: 4 | C32: 6 | D32: 56 | E32: 57772 | F32: 12902539264 | G32: 0 | H32: 6 | I32: 0 | J32: 594.7061 | K32: 4294011683 | L32: 2226688 | M32: 0 | N32: 0 | O32: 4265639936 | P32: 1041416 | Q32: 112690 | R32: 3268104
A33: 3 | B33: 4 | C33: 7 | D33: 68 | E33: 56939 | F33: 12902539264 | G33: 0 | H33: 6 | I33: 0 | J33: 558.36882 | K33: 3973419306 | L33: 2302820 | M33: 0 | N33: 0 | O33: 3944988672 | P33: 963132 | Q33: 184682 | R33: 3265952
A34: Average | B34: =AVERAGE(B31:B33) | C34: =AVERAGE(C31:C33) | D34: =AVERAGE(D31:D33) | E34: =AVERAGE(E31:E33) | F34: =AVERAGE(F31:F33) | G34: =AVERAGE(G31:G33) | H34: =AVERAGE(H31:H33) | I34: =AVERAGE(I31:I33) | ... R34: =AVERAGE(R31:R33)
A36: RAM | B36: 16384
A37: Experiment | B37: Iterations | C37: Setup-Time | D37: Downtime | E37: Total-Time | F37: Ram-Total | G37: Ram-Postcopy-Requests | H37: Ram-Dirty-Sync-Count | I37: Ram-Remaining | J37: Ram-Mbps | K37: Ram-Transferred | L37: Ram-Duplicate | M37: Ram-Dirty-Pages-Rate | N37: Ram-Skipped | O37: Ram-Normal-Bytes | P37: Ram-Normal | Q37: Total-Fake-Dirty-Pages | R37: Total-Transferred-Page-Count
A38: 1 | B38: 4 | C38: 9 | D38: 73 | E38: 66861 | F38: 17197506560 | G38: 0 | H38: 6 | I38: 0 | J38: 495.93875 | K38: 4144099761 | L38: 3320067 | M38: 0 | N38: 0 | O38: 4106199040 | P38: 1002490 | Q38: 141116 | R38: 4322557
A39: 2 | B39: 4 | C39: 9 | D39: 46 | E39: 66478 | F39: 17197506560 | G39: 0 | H39: 6 | I39: 0 | J39: 495.28964 | K39: 4114963467 | L39: 3317565 | M39: 0 | N39: 0 | O39: 4077142016 | P39: 995396 | Q39: 169452 | R39: 4312961
A40: 3 | B40: 5 | C40: 10 | D40: 40 | E40: 66551 | F40: 17197506560 | G40: 0 | H40: 7 | I40: 0 | J40: 482.72298 | K40: 4014896329 | L40: 3345910 | M40: 0 | N40: 0 | O40: 3977015296 | P40: 970951 | Q40: 154044 | R40: 4316861
A41: Average | B41: =AVERAGE(B38:B40) | C41: =AVERAGE(C38:C40) | D41: =AVERAGE(D38:D40) | E41: =AVERAGE(E38:E40) | F41: =AVERAGE(F38:F40) | G41: =AVERAGE(G38:G40) | H41: =AVERAGE(H38:H40) | I41: =AVERAGE(I38:I40) | ... R41: =AVERAGE(R38:R40)

Sheet Dtrack
A1: RAM | B1: 1024
A2: Experiment | B2: Iterations | C2: Setup-Time | D2: Downtime | E2: Total-Time | F2: Ram-Total | G2: Ram-Postcopy-Requests | H2: Ram-Dirty-Sync-Count | I2: Ram-Remaining | J2: Ram-Mbps | K2: Ram-Transferred | L2: Ram-Duplicate | M2: Ram-Dirty-Pages-Rate | N2: Ram-Skipped | O2: Ram-Normal-Bytes | P2: Ram-Normal | Q2: Total-Fake-Dirty-Pages | R2: Total-Transferred-Page-Count
A3: 1 | B3: 2 | C3: 1 | D3: 162 | E3: 9550 | F3: 1091379200 | G3: 0 | H3: 4 | I3: 0 | J3: 919.96642 | K3: 1097882559 | L3: 11034 | M3: 0 | N3: 0 | O3: 1095643136 | P3: 267491 | Q3: 0 | R3: 278525
A4: 2 | B4: 3 | C4: 2 | D4: 145 | E4: 9612 | F4: 1091379200 | G4: 0 | H4: 5 | I4: 0 | J4: 935.23635 | K4: 1123240283 | L4: 11846 | M4: 0 | N4: 0 | O4: 1120944128 | P4: 273668 | Q4: 0 | R4: 285514
A5: 3 | B5: 3 | C5: 2 | D5: 65 | E5: 9644 | F5: 1091379200 | G5: 0 | H5: 5 | I5: 0 | J5: 927.61211 | K5: 1117792106 | L5: 11149 | M5: 0 | N5: 0 | O5: 1115512832 | P5: 272342 | Q5: 0 | R5: 283491
A6: Average | B6: =AVERAGE(B3:B5) | C6: =AVERAGE(C3:C5) | D6: =AVERAGE(D3:D5) | E6: =AVERAGE(E3:E5) | F6: =AVERAGE(F3:F5) | G6: =AVERAGE(G3:G5) | H6: =AVERAGE(H3:H5) | I6: =AVERAGE(I3:I5) | ... R6: =AVERAGE(R3:R5)
A8: RAM | B8: 2048
A9: Experiment | B9: Iterations | C9: Setup-Time | D9: Downtime | E9: Total-Time | F9: Ram-Total | G9: Ram-Postcopy-Requests | H9: Ram-Dirty-Sync-Count | I9: Ram-Remaining | J9: Ram-Mbps | K9: Ram-Transferred | L9: Ram-Duplicate | M9: Ram-Dirty-Pages-Rate | N9: Ram-Skipped | O9: Ram-Normal-Bytes | P9: Ram-Normal | Q9: Total-Fake-Dirty-Pages | R9: Total-Transferred-Page-Count
A10: 1 | B10: 5 | C10: 2 | D10: 146 | E10: 19381 | F10: 2165121024 | G10: 0 | H10: 7 | I10: 0 | J10: 933.96903 | K10: 2262210794 | L10: 11808 | M10: 0 | N10: 0 | O10: 2257694720 | P10: 551195 | Q10: 0 | R10: 563003
A11: 2 | B11: 6 | C11: 3 | D11: 75 | E11: 19430 | F11: 2165121024 | G11: 0 | H11: 8 | I11: 0 | J11: 926.97947 | K11: 2250841298 | L11: 11197 | M11: 0 | N11: 0 | O11: 2246352896 | P11: 548426 | Q11: 0 | R11: 559623
A12: 3 | B12: 5 | C12: 3 | D12: 538 | E12: 20155 | F12: 2165121024 | G12: 0 | H12: 7 | I12: 0 | J12: 905.43446 | K12: 2280576975 | L12: 11898 | M12: 0 | N12: 0 | O12: 2276024320 | P12: 555670 | Q12: 0 | R12: 567568
A13: Average | B13: =AVERAGE(B10:B12) | C13: =AVERAGE(C10:C12) | D13: =AVERAGE(D10:D12) | E13: =AVERAGE(E10:E12) | F13: =AVERAGE(F10:F12) | G13: =AVERAGE(G10:G12) | H13: =AVERAGE(H10:H12) | I13: =AVERAGE(I10:I12) | ... R13: =AVERAGE(R10:R12)
A15: RAM | B15: 4096
A16: Experiment | B16: Iterations | C16: Setup-Time | D16: Downtime | E16: Total-Time | F16: Ram-Total | G16: Ram-Postcopy-Requests | H16: Ram-Dirty-Sync-Count | I16: Ram-Remaining | J16: Ram-Mbps | K16: Ram-Transferred | L16: Ram-Duplicate | M16: Ram-Dirty-Pages-Rate | N16: Ram-Skipped | O16: Ram-Normal-Bytes | P16: Ram-Normal | Q16: Total-Fake-Dirty-Pages | R16: Total-Transferred-Page-Count
A17: 1 | B17: 6 | C17: 4 | D17: 88 | E17: 26134 | F17: 4312604672 | G17: 0 | H17: 8 | I17: 0 | J17: 931.77921 | K17: 3043211398 | L17: 351204 | M17: 0 | N17: 0 | O17: 3034124288 | P17: 740753 | Q17: 0 | R17: 1091957
A18: 2 | B18: 5 | C18: 4 | D18: 166 | E18: 26959 | F18: 4312604672 | G18: 0 | H18: 7 | I18: 0 | J18: 932.74542 | K18: 3142556675 | L18: 324273 | M18: 0 | N18: 0 | O18: 3133517824 | P18: 765019 | Q18: 0 | R18: 1089292
A19: 3 | B19: 5 | C19: 3 | D19: 153 | E19: 27462 | F19: 4312604672 | G19: 0 | H19: 7 | I19: 0 | J19: 933.56756 | K19: 3204141513 | L19: 311988 | M19: 0 | N19: 0 | O19: 3195092992 | P19: 780052 | Q19: 0 | R19: 1092040
A20: Average | B20: =AVERAGE(B17:B19) | C20: =AVERAGE(C17:C19) | D20: =AVERAGE(D17:D19) | E20: =AVERAGE(E17:E19) | F20: =AVERAGE(F17:F19) | G20: =AVERAGE(G17:G19) | H20: =AVERAGE(H17:H19) | I20: =AVERAGE(I17:I19) | ... R20: =AVERAGE(R17:R19)
A22: RAM | B22: 8192
A23: Experiment | B23: Iterations | C23: Setup-Time | D23: Downtime | E23: Total-Time | F23: Ram-Total | G23: Ram-Postcopy-Requests | H23: Ram-Dirty-Sync-Count | I23: Ram-Remaining | J23: Ram-Mbps | K23: Ram-Transferred | L23: Ram-Duplicate | M23: Ram-Dirty-Pages-Rate | N23: Ram-Skipped | O23: Ram-Normal-Bytes | P23: Ram-Normal | Q23: Total-Fake-Dirty-Pages | R23: Total-Transferred-Page-Count
A24: 1 | B24: 6 | C24: 5 | D24: 91 | E24: 28521 | F24: 8607571968 | G24: 0 | H24: 8 | I24: 0 | J24: 919.43114 | K24: 3277099832 | L24: 1348187 | M24: 0 | N24: 0 | O24: 3258601472 | P24: 795557 | Q24: 0 | R24: 2143744
A25: 2 | B25: 6 | C25: 5 | D25: 90 | E25: 29060 | F25: 8607571968 | G25: 0 | H25: 8 | I25: 0 | J25: 878.21644 | K25: 3189359858 | L25: 1371381 | M25: 0 | N25: 0 | O25: 3170824192 | P25: 774127 | Q25: 0 | R25: 2145508
A26: 3 | B26: 6 | C26: 5 | D26: 89 | E26: 29552 | F26: 8607571968 | G26: 0 | H26: 8 | I26: 0 | J26: 918.93954 | K26: 3393775879 | L26: 1332605 | M26: 0 | N26: 0 | O26: 3375190016 | P26: 824021 | Q26: 0 | R26: 2156626
A27: Average | B27: =AVERAGE(B24:B26) | C27: =AVERAGE(C24:C26) | D27: =AVERAGE(D24:D26) | E27: =AVERAGE(E24:E26) | F27: =AVERAGE(F24:F26) | G27: =AVERAGE(G24:G26) | H27: =AVERAGE(H24:H26) | I27: =AVERAGE(I24:I26) | ... R27: =AVERAGE(R24:R26)
A29: RAM | B29: 12288
A30: Experiment | B30: Iterations | C30: Setup-Time | D30: Downtime | E30: Total-Time | F30: Ram-Total | G30: Ram-Postcopy-Requests | H30: Ram-Dirty-Sync-Count | I30: Ram-Remaining | J30: Ram-Mbps | K30: Ram-Transferred | L30: Ram-Duplicate | M30: Ram-Dirty-Pages-Rate | N30: Ram-Skipped | O30: Ram-Normal-Bytes | P30: Ram-Normal | Q30: Total-Fake-Dirty-Pages | R30: Total-Transferred-Page-Count
A31: 1 | B31: 6 | C31: 8 | D31: 101 | E31: 34742 | F31: 12902539264 | G31: 0 | H31: 8 | I31: 0 | J31: 908.88751 | K31: 3945949873 | L31: 2239279 | M31: 0 | N31: 0 | O31: 3918143488 | P31: 956578 | Q31: 0 | R31: 3195857
A32: 2 | B32: 10 | C32: 8 | D32: 155 | E32: 33293 | F32: 12902539264 | G32: 0 | H32: 12 | I32: 0 | J32: 902.56604 | K32: 3755026281 | L32: 2395071 | M32: 0 | N32: 0 | O32: 3726192640 | P32: 909715 | Q32: 0 | R32: 3304786
A33: 3 | B33: 11 | C33: 9 | D33: 168 | E33: 34268 | F33: 12902539264 | G33: 0 | H33: 13 | I33: 0 | J33: 897.54892 | K33: 3843428483 | L33: 2403505 | M33: 0 | N33: 0 | O33: 3814346752 | P33: 931237 | Q33: 0 | R33: 3334742
A34: Average | B34: =AVERAGE(B31:B33) | C34: =AVERAGE(C31:C33) | D34: =AVERAGE(D31:D33) | E34: =AVERAGE(E31:E33) | F34: =AVERAGE(F31:F33) | G34: =AVERAGE(G31:G33) | H34: =AVERAGE(H31:H33) | I34: =AVERAGE(I31:I33) | ... R34: =AVERAGE(R31:R33)
A36: RAM | B36: 16384
A37: Experiment | B37: Iterations | C37: Setup-Time | D37: Downtime | E37: Total-Time | F37: Ram-Total | G37: Ram-Postcopy-Requests | H37: Ram-Dirty-Sync-Count | I37: Ram-Remaining | J37: Ram-Mbps | K37: Ram-Transferred | L37: Ram-Duplicate | M37: Ram-Dirty-Pages-Rate | N37: Ram-Skipped | O37: Ram-Normal-Bytes | P37: Ram-Normal | Q37: Total-Fake-Dirty-Pages | R37: Total-Transferred-Page-Count
A38: 1 | B38: 9 | C38: 11 | D38: 177 | E38: 34056 | F38: 17197506560 | G38: 0 | H38: 11 | I38: 0 | J38: 894.29781 | K38: 3805583566 | L38: 3411052 | M38: 0 | N38: 0 | O38: 3767525376 | P38: 919806 | Q38: 0 | R38: 4330858
A39: 2 | B39: 9 | C39: 10 | D39: 153 | E39: 35541 | F39: 17197506560 | G39: 0 | H39: 11 | I39: 0 | J39: 879.37381 | K39: 3905416318 | L39: 3407732 | M39: 0 | N39: 0 | O39: 3867193344 | P39: 944139 | Q39: 0 | R39: 4351871
A40: 3 | B40: 6 | C40: 11 | D40: 104 | E40: 35714 | F40: 17197506560 | G40: 0 | H40: 8 | I40: 0 | J40: 764.1529 | K40: 3410106424 | L40: 3428918 | M40: 0 | N40: 0 | O40: 3372658688 | P40: 823403 | Q40: 0 | R40: 4252321
A41: Average | B41: =AVERAGE(B38:B40) | C41: =AVERAGE(C38:C40) | D41: =AVERAGE(D38:D40) | E41: =AVERAGE(E38:E40) | F41: =AVERAGE(F38:F40) | G41: =AVERAGE(G38:G40) | H41: =AVERAGE(H38:H40) | I41: =AVERAGE(I38:I40) | ... R41: =AVERAGE(R38:R40)

Sheet Compress_Dtrack
A1: RAM | B1: 1024
A2: Experiment | B2: Iterations | C2: Setup-Time | D2: Downtime | E2: Total-Time | F2: Ram-Total | G2: Ram-Postcopy-Requests | H2: Ram-Dirty-Sync-Count | I2: Ram-Remaining | J2: Ram-Mbps | K2: Ram-Transferred | L2: Ram-Duplicate | M2: Ram-Dirty-Pages-Rate | N2: Ram-Skipped | O2: Ram-Normal-Bytes | P2: Ram-Normal | Q2: Total-Fake-Dirty-Pages | R2: Total-Transferred-Page-Count
A3: 1 | B3: 2 | C3: 3 | D3: 82 | E3: 6329 | F3: 1091379200 | G3: 0 | H3: 4 | I3: 0 | J3: 837.2993 | K3: 661882066 | L3: 10434 | M3: 0 | N3: 0 | O3: 36864 | P3: 9 | Q3: 0 | R3: 278457
A4: 2 | B4: 3 | C4: 4 | D4: 63 | E4: 6348 | F4: 1091379200 | G4: 0 | H4: 5 | I4: 0 | J4: 832.29225 | K4: 659795372 | L4: 10592 | M4: 0 | N4: 0 | O4: 36864 | P4: 9 | Q4: 0 | R4: 275243
A5: 3 | B5: 2 | C5: 3 | D5: 83 | E5: 6444 | F5: 1091379200 | G5: 0 | H5: 4 | I5: 0 | J5: 852.48542 | K5: 686144965 | L5: 11751 | M5: 0 | N5: 0 | O5: 36864 | P5: 9 | Q5: 0 | R5: 278928
A6: Average | B6: =AVERAGE(B3:B5) | C6: =AVERAGE(C3:C5) | D6: =AVERAGE(D3:D5) | E6: =AVERAGE(E3:E5) | F6: =AVERAGE(F3:F5) | G6: =AVERAGE(G3:G5) | H6: =AVERAGE(H3:H5) | I6: =AVERAGE(I3:I5) | ... R6: =AVERAGE(R3:R5)
A8: RAM | B8: 2048
A9: Experiment | B9: Iterations | C9: Setup-Time | D9: Downtime | E9: Total-Time | F9: Ram-Total | G9: Ram-Postcopy-Requests | H9: Ram-Dirty-Sync-Count | I9: Ram-Remaining | J9: Ram-Mbps | K9: Ram-Transferred | L9: Ram-Duplicate | M9: Ram-Dirty-Pages-Rate | N9: Ram-Skipped | O9: Ram-Normal-Bytes | P9: Ram-Normal | Q9: Total-Fake-Dirty-Pages | R9: Total-Transferred-Page-Count
A10: 1 | B10: 4 | C10: 3 | D10: 45 | E10: 12332 | F10: 2165121024 | G10: 0 | H10: 6 | I10: 0 | J10: 902.6635 | K10: 1390904872 | L10: 11643 | M10: 0 | N10: 0 | O10: 36864 | P10: 9 | Q10: 0 | R10: 548701
A11: 2 | B11: 6 | C11: 3 | D11: 42 | E11: 12549 | F11: 2165121024 | G11: 0 | H11: 8 | I11: 0 | J11: 917.09832 | K11: 1438026983 | L11: 12084 | M11: 0 | N11: 0 | O11: 36864 | P11: 9 | Q11: 0 | R11: 567404
A12: 3 | B12: 4 | C12: 3 | D12: 46 | E12: 12604 | F12: 2165121024 | G12: 0 | H12: 6 | I12: 0 | J12: 916.33776 | K12: 1443134097 | L12: 11248 | M12: 0 | N12: 0 | O12: 36864 | P12: 9 | Q12: 0 | R12: 546307
A13: Average | B13: =AVERAGE(B10:B12) | C13: =AVERAGE(C10:C12) | D13: =AVERAGE(D10:D12) | E13: =AVERAGE(E10:E12) | F13: =AVERAGE(F10:F12) | G13: =AVERAGE(G10:G12) | H13: =AVERAGE(H10:H12) | I13: =AVERAGE(I10:I12) | ... R13: =AVERAGE(R10:R12)
A15: RAM | B15: 4096
