Workbook

Sheet Summary
A1: Optimization | B1: Vanilla
A2: Ram | B2: Total-Time | C2: Total-Fake-Dirty-Pages | D2: Total-Transferred-Page-Count
A3: 1024 | B3: ='Vanilla'!E6 | C3: ='Vanilla'!Q6 | D3: ='Vanilla'!R6
A4: 2048 | B4: ='Vanilla'!E13 | C4: ='Vanilla'!Q13 | D4: ='Vanilla'!R13
A5: 4096 | B5: ='Vanilla'!E20 | C5: ='Vanilla'!Q20 | D5: ='Vanilla'!R20
A6: 8192 | B6: ='Vanilla'!E27 | C6: ='Vanilla'!Q27 | D6: ='Vanilla'!R27
A7: 12288 | B7: ='Vanilla'!E34 | C7: ='Vanilla'!Q34 | D7: ='Vanilla'!R34
A8: 16384 | B8: ='Vanilla'!E41 | C8: ='Vanilla'!Q41 | D8: ='Vanilla'!R41
A10: Optimization | B10: XBZRLE
A11: Ram | B11: Total-Time | C11: Total-Fake-Dirty-Pages | D11: Total-Transferred-Page-Count
A12: 1024 | B12: ='XBZRLE'!E6 | C12: ='XBZRLE'!Q6 | D12: ='XBZRLE'!R6
A13: 2048 | B13: ='XBZRLE'!E13 | C13: ='XBZRLE'!Q13 | D13: ='XBZRLE'!R13
A14: 4096 | B14: ='XBZRLE'!E20 | C14: ='XBZRLE'!Q20 | D14: ='XBZRLE'!R20
A15: 8192 | B15: ='XBZRLE'!E27 | C15: ='XBZRLE'!Q27 | D15: ='XBZRLE'!R27
A16: 12288 | B16: ='XBZRLE'!E34 | C16: ='XBZRLE'!Q34 | D16: ='XBZRLE'!R34
A17: 16384 | B17: ='XBZRLE'!E41 | C17: ='XBZRLE'!Q41 | D17: ='XBZRLE'!R41
A19: Optimization | B19: Compress
A20: Ram | B20: Total-Time | C20: Total-Fake-Dirty-Pages | D20: Total-Transferred-Page-Count
A21: 1024 | B21: ='Compress'!E6 | C21: ='Compress'!Q6 | D21: ='Compress'!R6
A22: 2048 | B22: ='Compress'!E13 | C22: ='Compress'!Q13 | D22: ='Compress'!R13
A23: 4096 | B23: ='Compress'!E20 | C23: ='Compress'!Q20 | D23: ='Compress'!R20
A24: 8192 | B24: ='Compress'!E27 | C24: ='Compress'!Q27 | D24: ='Compress'!R27
A25: 12288 | B25: ='Compress'!E34 | C25: ='Compress'!Q34 | D25: ='Compress'!R34
A26: 16384 | B26: ='Compress'!E41 | C26: ='Compress'!Q41 | D26: ='Compress'!R41
A28: Optimization | B28: HBFDP_SHA1
A29: Ram | B29: Total-Time | C29: Total-Fake-Dirty-Pages | D29: Total-Transferred-Page-Count
A30: 1024 | B30: ='HBFDP_SHA1'!E6 | C30: ='HBFDP_SHA1'!Q6 | D30: ='HBFDP_SHA1'!R6
A31: 2048 | B31: ='HBFDP_SHA1'!E13 | C31: ='HBFDP_SHA1'!Q13 | D31: ='HBFDP_SHA1'!R13
A32: 4096 | B32: ='HBFDP_SHA1'!E20 | C32: ='HBFDP_SHA1'!Q20 | D32: ='HBFDP_SHA1'!R20
A33: 8192 | B33: ='HBFDP_SHA1'!E27 | C33: ='HBFDP_SHA1'!Q27 | D33: ='HBFDP_SHA1'!R27
A34: 12288 | B34: ='HBFDP_SHA1'!E34 | C34: ='HBFDP_SHA1'!Q34 | D34: ='HBFDP_SHA1'!R34
A35: 16384 | B35: ='HBFDP_SHA1'!E41 | C35: ='HBFDP_SHA1'!Q41 | D35: ='HBFDP_SHA1'!R41
A37: Optimization | B37: HBFDP_MD5
A38: Ram | B38: Total-Time | C38: Total-Fake-Dirty-Pages | D38: Total-Transferred-Page-Count
A39: 1024 | B39: ='HBFDP_MD5'!E6 | C39: ='HBFDP_MD5'!Q6 | D39: ='HBFDP_MD5'!R6
A40: 2048 | B40: ='HBFDP_MD5'!E13 | C40: ='HBFDP_MD5'!Q13 | D40: ='HBFDP_MD5'!R13
A41: 4096 | B41: ='HBFDP_MD5'!E20 | C41: ='HBFDP_MD5'!Q20 | D41: ='HBFDP_MD5'!R20
A42: 8192 | B42: ='HBFDP_MD5'!E27 | C42: ='HBFDP_MD5'!Q27 | D42: ='HBFDP_MD5'!R27
A43: 12288 | B43: ='HBFDP_MD5'!E34 | C43: ='HBFDP_MD5'!Q34 | D43: ='HBFDP_MD5'!R34
A44: 16384 | B44: ='HBFDP_MD5'!E41 | C44: ='HBFDP_MD5'!Q41 | D44: ='HBFDP_MD5'!R41
...

Sheet Vanilla
A1: RAM | B1: 1024
A2: Experiment | B2: Iterations | C2: Setup-Time | D2: Downtime | E2: Total-Time | F2: Ram-Total | G2: Ram-Postcopy-Requests | H2: Ram-Dirty-Sync-Count | I2: Ram-Remaining | J2: Ram-Mbps | K2: Ram-Transferred | L2: Ram-Duplicate | M2: Ram-Dirty-Pages-Rate | N2: Ram-Skipped | O2: Ram-Normal-Bytes | P2: Ram-Normal | Q2: Total-Fake-Dirty-Pages | R2: Total-Transferred-Page-Count
A3: 1 | B3: 3 | C3: 2 | D3: 96 | E3: 10703 | F3: 1091379200 | G3: 0 | H3: 5 | I3: 0 | J3: 906.92251 | K3: 1212909841 | L3: 11075 | M3: 0 | N3: 0 | O3: 1210445824 | P3: 295519 | Q3: 21281 | R3: 306594
A4: 2 | B4: 3 | C4: 2 | D4: 114 | E4: 10784 | F4: 1091379200 | G4: 0 | H4: 5 | I4: 0 | J4: 913.52367 | K4: 1230989140 | L4: 11206 | M4: 0 | N4: 0 | O4: 1228488704 | P4: 299924 | Q4: 24046 | R4: 311130
A5: 3 | B5: 3 | C5: 2 | D5: 109 | E5: 10775 | F5: 1091379200 | G5: 0 | H5: 5 | I5: 0 | J5: 910.5689 | K5: 1225982467 | L5: 11685 | M5: 0 | N5: 0 | O5: 1223487488 | P5: 298703 | Q5: 24839 | R5: 310388
A6: Average | B6: =AVERAGE(B3:B5) | C6: =AVERAGE(C3:C5) | D6: =AVERAGE(D3:D5) | E6: =AVERAGE(E3:E5) | F6: =AVERAGE(F3:F5) | G6: =AVERAGE(G3:G5) | H6: =AVERAGE(H3:H5) | I6: =AVERAGE(I3:I5) | ... R6: =AVERAGE(R3:R5)
A8: RAM | B8: 2048
A9: Experiment | B9: Iterations | C9: Setup-Time | D9: Downtime | E9: Total-Time | F9: Ram-Total | G9: Ram-Postcopy-Requests | H9: Ram-Dirty-Sync-Count | I9: Ram-Remaining | J9: Ram-Mbps | K9: Ram-Transferred | L9: Ram-Duplicate | M9: Ram-Dirty-Pages-Rate | N9: Ram-Skipped | O9: Ram-Normal-Bytes | P9: Ram-Normal | Q9: Total-Fake-Dirty-Pages | R9: Total-Transferred-Page-Count
A10: 1 | B10: 4 | C10: 3 | D10: 97 | E10: 22945 | F10: 2165121024 | G10: 0 | H10: 6 | I10: 0 | J10: 901.22973 | K10: 2584289142 | L10: 11872 | M10: 0 | N10: 0 | O10: 2579144704 | P10: 629674 | Q10: 55254 | R10: 641546
A11: 2 | B11: 4 | C11: 2 | D11: 102 | E11: 22915 | F11: 2165121024 | G11: 0 | H11: 6 | I11: 0 | J11: 908.13377 | K11: 2600796215 | L11: 13324 | M11: 0 | N11: 0 | O11: 2595606528 | P11: 633693 | Q11: 63535 | R11: 647017
A12: 3 | B12: 4 | C12: 2 | D12: 103 | E12: 22938 | F12: 2165121024 | G12: 0 | H12: 6 | I12: 0 | J12: 913.6644 | K12: 2619263412 | L12: 12326 | M12: 0 | N12: 0 | O12: 2614046720 | P12: 638195 | Q12: 60796 | R12: 650521
A13: Average | B13: =AVERAGE(B10:B12) | C13: =AVERAGE(C10:C12) | D13: =AVERAGE(D10:D12) | E13: =AVERAGE(E10:E12) | F13: =AVERAGE(F10:F12) | G13: =AVERAGE(G10:G12) | H13: =AVERAGE(H10:H12) | I13: =AVERAGE(I10:I12) | ... R13: =AVERAGE(R10:R12)
A15: RAM | B15: 4096
A16: Experiment | B16: Iterations | C16: Setup-Time | D16: Downtime | E16: Total-Time | F16: Ram-Total | G16: Ram-Postcopy-Requests | H16: Ram-Dirty-Sync-Count | I16: Ram-Remaining | J16: Ram-Mbps | K16: Ram-Transferred | L16: Ram-Duplicate | M16: Ram-Dirty-Pages-Rate | N16: Ram-Skipped | O16: Ram-Normal-Bytes | P16: Ram-Normal | Q16: Total-Fake-Dirty-Pages | R16: Total-Transferred-Page-Count
A17: 1 | B17: 6 | C17: 4 | D17: 153 | E17: 37778 | F17: 4312604672 | G17: 0 | H17: 8 | I17: 0 | J17: 847.68652 | K17: 4002351343 | L17: 348273 | M17: 0 | N17: 0 | O17: 3991420928 | P17: 974468 | Q17: 162908 | R17: 1322741
A18: 2 | B18: 7 | C18: 3 | D18: 167 | E18: 39569 | F18: 4312604672 | G18: 0 | H18: 9 | I18: 0 | J18: 870.57156 | K18: 4305416820 | L18: 293262 | M18: 0 | N18: 0 | O18: 4294389760 | P18: 1048435 | Q18: 180047 | R18: 1341697
A19: 3 | B19: 6 | C19: 4 | D19: 157 | E19: 36811 | F19: 4312604672 | G19: 0 | H19: 8 | I19: 0 | J19: 848.66062 | K19: 3904368955 | L19: 359285 | M19: 0 | N19: 0 | O19: 3893530624 | P19: 950569 | Q19: 152012 | R19: 1309854
A20: Average | B20: =AVERAGE(B17:B19) | C20: =AVERAGE(C17:C19) | D20: =AVERAGE(D17:D19) | E20: =AVERAGE(E17:E19) | F20: =AVERAGE(F17:F19) | G20: =AVERAGE(G17:G19) | H20: =AVERAGE(H17:H19) | I20: =AVERAGE(I17:I19) | ... R20: =AVERAGE(R17:R19)
A22: RAM | B22: 8192
A23: Experiment | B23: Iterations | C23: Setup-Time | D23: Downtime | E23: Total-Time | F23: Ram-Total | G23: Ram-Postcopy-Requests | H23: Ram-Dirty-Sync-Count | I23: Ram-Remaining | J23: Ram-Mbps | K23: Ram-Transferred | L23: Ram-Duplicate | M23: Ram-Dirty-Pages-Rate | N23: Ram-Skipped | O23: Ram-Normal-Bytes | P23: Ram-Normal | Q23: Total-Fake-Dirty-Pages | R23: Total-Transferred-Page-Count
A24: 1 | B24: 8 | C24: 6 | D24: 146 | E24: 48330 | F24: 8607571968 | G24: 0 | H24: 10 | I24: 0 | J24: 684.13801 | K24: 4132323140 | L24: 1367678 | M24: 0 | N24: 0 | O24: 4111982592 | P24: 1003902 | Q24: 154425 | R24: 2371580
A25: 2 | B25: 7 | C25: 6 | D25: 149 | E25: 48893 | F25: 8607571968 | G25: 0 | H25: 9 | I25: 0 | J25: 702.3367 | K25: 4291679283 | L25: 1299037 | M25: 0 | N25: 0 | O25: 4271644672 | P25: 1042882 | Q25: 127220 | R25: 2341919
A26: 3 | B26: 6 | C26: 5 | D26: 154 | E26: 47512 | F26: 8607571968 | G26: 0 | H26: 8 | I26: 0 | J26: 692.79506 | K26: 4113864376 | L26: 1300762 | M26: 0 | N26: 0 | O26: 4094160896 | P26: 999551 | Q26: 84191 | R26: 2300313
A27: Average | B27: =AVERAGE(B24:B26) | C27: =AVERAGE(C24:C26) | D27: =AVERAGE(D24:D26) | E27: =AVERAGE(E24:E26) | F27: =AVERAGE(F24:F26) | G27: =AVERAGE(G24:G26) | H27: =AVERAGE(H24:H26) | I27: =AVERAGE(I24:I26) | ... R27: =AVERAGE(R24:R26)
A29: RAM | B29: 12288
A30: Experiment | B30: Iterations | C30: Setup-Time | D30: Downtime | E30: Total-Time | F30: Ram-Total | G30: Ram-Postcopy-Requests | H30: Ram-Dirty-Sync-Count | I30: Ram-Remaining | J30: Ram-Mbps | K30: Ram-Transferred | L30: Ram-Duplicate | M30: Ram-Dirty-Pages-Rate | N30: Ram-Skipped | O30: Ram-Normal-Bytes | P30: Ram-Normal | Q30: Total-Fake-Dirty-Pages | R30: Total-Transferred-Page-Count
A31: 1 | B31: 7 | C31: 8 | D31: 180 | E31: 60677 | F31: 12902539264 | G31: 0 | H31: 9 | I31: 0 | J31: 615.54068 | K31: 4667817183 | L31: 2267825 | M31: 0 | N31: 0 | O31: 4638347264 | P31: 1132409 | Q31: 109460 | R31: 3400234
A32: 2 | B32: 5 | C32: 7 | D32: 187 | E32: 60969 | F32: 12902539264 | G32: 0 | H32: 7 | I32: 0 | J32: 623.65024 | K32: 4752158309 | L32: 2262335 | M32: 0 | N32: 0 | O32: 4722573312 | P32: 1152972 | Q32: 130802 | R32: 3415307
A33: 3 | B33: 7 | C33: 8 | D33: 179 | E33: 60479 | F33: 12902539264 | G33: 0 | H33: 9 | I33: 0 | J33: 614.34903 | K33: 4643575071 | L33: 2359505 | M33: 0 | N33: 0 | O33: 4613328896 | P33: 1126301 | Q33: 205306 | R33: 3485806
A34: Average | B34: =AVERAGE(B31:B33) | C34: =AVERAGE(C31:C33) | D34: =AVERAGE(D31:D33) | E34: =AVERAGE(E31:E33) | F34: =AVERAGE(F31:F33) | G34: =AVERAGE(G31:G33) | H34: =AVERAGE(H31:H33) | I34: =AVERAGE(I31:I33) | ... R34: =AVERAGE(R31:R33)
A36: RAM | B36: 16384
A37: Experiment | B37: Iterations | C37: Setup-Time | D37: Downtime | E37: Total-Time | F37: Ram-Total | G37: Ram-Postcopy-Requests | H37: Ram-Dirty-Sync-Count | I37: Ram-Remaining | J37: Ram-Mbps | K37: Ram-Transferred | L37: Ram-Duplicate | M37: Ram-Dirty-Pages-Rate | N37: Ram-Skipped | O37: Ram-Normal-Bytes | P37: Ram-Normal | Q37: Total-Fake-Dirty-Pages | R37: Total-Transferred-Page-Count
A38: 1 | B38: 7 | C38: 10 | D38: 159 | E38: 75749 | F38: 17197506560 | G38: 0 | H38: 9 | I38: 0 | J38: 554.33219 | K38: 5247858219 | L38: 3345597 | M38: 0 | N38: 0 | O38: 5207576576 | P38: 1271381 | Q38: 255755 | R38: 4616978
A39: 2 | B39: 6 | C39: 9 | D39: 197 | E39: 75387 | F39: 17197506560 | G39: 0 | H39: 8 | I39: 0 | J39: 540.23559 | K39: 5090022331 | L39: 3367925 | M39: 0 | N39: 0 | O39: 5049847808 | P39: 1232873 | Q39: 247915 | R39: 4600798
A40: 3 | B40: 7 | C40: 9 | D40: 185 | E40: 75859 | F40: 17197506560 | G40: 0 | H40: 9 | I40: 0 | J40: 562.9467 | K40: 5337225942 | L40: 3343664 | M40: 0 | N40: 0 | O40: 5296787456 | P40: 1293161 | Q40: 278823 | R40: 4636825
A41: Average | B41: =AVERAGE(B38:B40) | C41: =AVERAGE(C38:C40) | D41: =AVERAGE(D38:D40) | E41: =AVERAGE(E38:E40) | F41: =AVERAGE(F38:F40) | G41: =AVERAGE(G38:G40) | H41: =AVERAGE(H38:H40) | I41: =AVERAGE(I38:I40) | ... R41: =AVERAGE(R38:R40)

Sheet XBZRLE
A1: RAM | B1: 1024
A2: Experiment | B2: Iterations | C2: Setup-Time | D2: Downtime | E2: Total-Time | F2: Ram-Total | G2: Ram-Postcopy-Requests | H2: Ram-Dirty-Sync-Count | I2: Ram-Remaining | J2: Ram-Mbps | K2: Ram-Transferred | L2: Ram-Duplicate | M2: Ram-Dirty-Pages-Rate | N2: Ram-Skipped | O2: Ram-Normal-Bytes | P2: Ram-Normal | Q2: Total-Fake-Dirty-Pages | R2: Total-Transferred-Page-Count
A3: 1 | B3: 3 | C3: 17 | D3: 54 | E3: 10472 | F3: 1091379200 | G3: 0 | H3: 5 | I3: 0 | J3: 911.8726 | K3: 1191491124 | L3: 12093 | M3: 0 | N3: 0 | O3: 1188462592 | P3: 290152 | Q3: 23147 | R3: 305011
A4: 2 | B4: 3 | C4: 17 | D4: 122 | E4: 10495 | F4: 1091379200 | G4: 0 | H4: 5 | I4: 0 | J4: 896.1547 | K4: 1173526233 | L4: 10522 | M4: 0 | N4: 0 | O4: 1170296832 | P4: 285717 | Q4: 19885 | R4: 299684
A5: 3 | B5: 3 | C5: 18 | D5: 30 | E5: 10474 | F5: 1091379200 | G5: 0 | H5: 5 | I5: 0 | J5: 906.11595 | K5: 1184081163 | L5: 11894 | M5: 0 | N5: 0 | O5: 1180975104 | P5: 288324 | Q5: 20945 | R5: 303174
A6: Average | B6: =AVERAGE(B3:B5) | C6: =AVERAGE(C3:C5) | D6: =AVERAGE(D3:D5) | E6: =AVERAGE(E3:E5) | F6: =AVERAGE(F3:F5) | G6: =AVERAGE(G3:G5) | H6: =AVERAGE(H3:H5) | I6: =AVERAGE(I3:I5) | ... R6: =AVERAGE(R3:R5)
A8: RAM | B8: 2048
A9: Experiment | B9: Iterations | C9: Setup-Time | D9: Downtime | E9: Total-Time | F9: Ram-Total | G9: Ram-Postcopy-Requests | H9: Ram-Dirty-Sync-Count | I9: Ram-Remaining | J9: Ram-Mbps | K9: Ram-Transferred | L9: Ram-Duplicate | M9: Ram-Dirty-Pages-Rate | N9: Ram-Skipped | O9: Ram-Normal-Bytes | P9: Ram-Normal | Q9: Total-Fake-Dirty-Pages | R9: Total-Transferred-Page-Count
A10: 1 | B10: 4 | C10: 20 | D10: 24 | E10: 22186 | F10: 2165121024 | G10: 0 | H10: 6 | I10: 0 | J10: 918.7051 | K10: 2545289750 | L10: 12046 | M10: 0 | N10: 0 | O10: 2537828352 | P10: 619587 | Q10: 56721 | R10: 638794
A11: 2 | B11: 4 | C11: 18 | D11: 30 | E11: 22113 | F11: 2165121024 | G11: 0 | H11: 6 | I11: 0 | J11: 914.32593 | K11: 2525041531 | L11: 11194 | M11: 0 | N11: 0 | O11: 2518110208 | P11: 614773 | Q11: 59634 | R11: 633237
A12: 3 | B12: 3 | C12: 20 | D12: 71 | E12: 22226 | F12: 2165121024 | G12: 0 | H12: 5 | I12: 0 | J12: 911.57935 | K12: 2530103988 | L12: 12173 | M12: 0 | N12: 0 | O12: 2523471872 | P12: 616082 | Q12: 64563 | R12: 633950
A13: Average | B13: =AVERAGE(B10:B12) | C13: =AVERAGE(C10:C12) | D13: =AVERAGE(D10:D12) | E13: =AVERAGE(E10:E12) | F13: =AVERAGE(F10:F12) | G13: =AVERAGE(G10:G12) | H13: =AVERAGE(H10:H12) | I13: =AVERAGE(I10:I12) | ... R13: =AVERAGE(R10:R12)
A15: RAM | B15: 4096
A16: Experiment | B16: Iterations | C16: Setup-Time | D16: Downtime | E16: Total-Time | F16: Ram-Total | G16: Ram-Postcopy-Requests | H16: Ram-Dirty-Sync-Count | I16: Ram-Remaining | J16: Ram-Mbps | K16: Ram-Transferred | L16: Ram-Duplicate | M16: Ram-Dirty-Pages-Rate | N16: Ram-Skipped | O16: Ram-Normal-Bytes | P16: Ram-Normal | Q16: Total-Fake-Dirty-Pages | R16: Total-Transferred-Page-Count
A17: 1 | B17: 4 | C17: 21 | D17: 44 | E17: 34465 | F17: 4312604672 | G17: 0 | H17: 6 | I17: 0 | J17: 857.6187 | K17: 3692264906 | L17: 273836 | M17: 0 | N17: 0 | O17: 3679801344 | P17: 898389 | Q17: 44022 | R17: 1180207
A18: 2 | B18: 4 | C18: 21 | D18: 45 | E18: 34356 | F18: 4312604672 | G18: 0 | H18: 6 | I18: 0 | J18: 858.47475 | K18: 3684253912 | L18: 269927 | M18: 0 | N18: 0 | O18: 3672571904 | P18: 896624 | Q18: 39266 | R18: 1173850
A19: 3 | B19: 4 | C19: 22 | D19: 70 | E19: 35577 | F19: 4312604672 | G19: 0 | H19: 6 | I19: 0 | J19: 860.4123 | K19: 3823782511 | L19: 272267 | M19: 0 | N19: 0 | O19: 3811246080 | P19: 930480 | Q19: 70004 | R19: 1211814
A20: Average | B20: =AVERAGE(B17:B19) | C20: =AVERAGE(C17:C19) | D20: =AVERAGE(D17:D19) | E20: =AVERAGE(E17:E19) | F20: =AVERAGE(F17:F19) | G20: =AVERAGE(G17:G19) | H20: =AVERAGE(H17:H19) | I20: =AVERAGE(I17:I19) | ... R20: =AVERAGE(R17:R19)
A22: RAM | B22: 8192
A23: Experiment | B23: Iterations | C23: Setup-Time | D23: Downtime | E23: Total-Time | F23: Ram-Total | G23: Ram-Postcopy-Requests | H23: Ram-Dirty-Sync-Count | I23: Ram-Remaining | J23: Ram-Mbps | K23: Ram-Transferred | L23: Ram-Duplicate | M23: Ram-Dirty-Pages-Rate | N23: Ram-Skipped | O23: Ram-Normal-Bytes | P23: Ram-Normal | Q23: Total-Fake-Dirty-Pages | R23: Total-Transferred-Page-Count
A24: 1 | B24: 4 | C24: 23 | D24: 145 | E24: 47481 | F24: 8607571968 | G24: 0 | H24: 6 | I24: 0 | J24: 685.38624 | K24: 4065670084 | L24: 1340717 | M24: 0 | N24: 0 | O24: 4042960896 | P24: 987051 | Q24: 133700 | R24: 2338066
A25: 2 | B25: 5 | C25: 23 | D25: 122 | E25: 48430 | F25: 8607571968 | G25: 0 | H25: 7 | I25: 0 | J25: 698.93904 | K25: 4228980354 | L25: 1298514 | M25: 0 | N25: 0 | O25: 4205887488 | P25: 1026828 | Q25: 122419 | R25: 2337299
A26: 3 | B26: 4 | C26: 19 | D26: 65 | E26: 48027 | F26: 8607571968 | G26: 0 | H26: 6 | I26: 0 | J26: 708.71313 | K26: 4252775096 | L26: 1270325 | M26: 0 | N26: 0 | O26: 4230017024 | P26: 1032719 | Q26: 104786 | R26: 2313033
A27: Average | B27: =AVERAGE(B24:B26) | C27: =AVERAGE(C24:C26) | D27: =AVERAGE(D24:D26) | E27: =AVERAGE(E24:E26) | F27: =AVERAGE(F24:F26) | G27: =AVERAGE(G24:G26) | H27: =AVERAGE(H24:H26) | I27: =AVERAGE(I24:I26) | ... R27: =AVERAGE(R24:R26)
A29: RAM | B29: 12288
A30: Experiment | B30: Iterations | C30: Setup-Time | D30: Downtime | E30: Total-Time | F30: Ram-Total | G30: Ram-Postcopy-Requests | H30: Ram-Dirty-Sync-Count | I30: Ram-Remaining | J30: Ram-Mbps | K30: Ram-Transferred | L30: Ram-Duplicate | M30: Ram-Dirty-Pages-Rate | N30: Ram-Skipped | O30: Ram-Normal-Bytes | P30: Ram-Normal | Q30: Total-Fake-Dirty-Pages | R30: Total-Transferred-Page-Count
A31: 1 | B31: 3 | C31: 27 | D31: 74 | E31: 58544 | F31: 12902539264 | G31: 0 | H31: 5 | I31: 0 | J31: 583.1945 | K31: 4265636651 | L31: 2257860 | M31: 0 | N31: 0 | O31: 4234792960 | P31: 1033885 | Q31: 107105 | R31: 3295389
A32: 2 | B32: 5 | C32: 21 | D32: 38 | E32: 59946 | F32: 12902539264 | G32: 0 | H32: 7 | I32: 0 | J32: 612.08136 | K32: 4584659528 | L32: 2261100 | M32: 0 | N32: 0 | O32: 4552036352 | P32: 1111337 | Q32: 112484 | R32: 3384010
A33: 3 | B33: 4 | C33: 24 | D33: 117 | E33: 58498 | F33: 12902539264 | G33: 0 | H33: 6 | I33: 0 | J33: 606.64966 | K33: 4433941648 | L33: 2232379 | M33: 0 | N33: 0 | O33: 4402556928 | P33: 1074843 | Q33: 54040 | R33: 3316122
A34: Average | B34: =AVERAGE(B31:B33) | C34: =AVERAGE(C31:C33) | D34: =AVERAGE(D31:D33) | E34: =AVERAGE(E31:E33) | F34: =AVERAGE(F31:F33) | G34: =AVERAGE(G31:G33) | H34: =AVERAGE(H31:H33) | I34: =AVERAGE(I31:I33) | ... R34: =AVERAGE(R31:R33)
A36: RAM | B36: 16384
A37: Experiment | B37: Iterations | C37: Setup-Time | D37: Downtime | E37: Total-Time | F37: Ram-Total | G37: Ram-Postcopy-Requests | H37: Ram-Dirty-Sync-Count | I37: Ram-Remaining | J37: Ram-Mbps | K37: Ram-Transferred | L37: Ram-Duplicate | M37: Ram-Dirty-Pages-Rate | N37: Ram-Skipped | O37: Ram-Normal-Bytes | P37: Ram-Normal | Q37: Total-Fake-Dirty-Pages | R37: Total-Transferred-Page-Count
A38: 1 | B38: 6 | C38: 26 | D38: 45 | E38: 72596 | F38: 17197506560 | G38: 0 | H38: 8 | I38: 0 | J38: 541.21626 | K38: 4909295542 | L38: 3332611 | M38: 0 | N38: 0 | O38: 4864675840 | P38: 1187665 | Q38: 211280 | R38: 4535550
A39: 2 | B39: 5 | C39: 25 | D39: 39 | E39: 72367 | F39: 17197506560 | G39: 0 | H39: 7 | I39: 0 | J39: 564.30107 | K39: 5102621090 | L39: 3238701 | M39: 0 | N39: 0 | O39: 5060300800 | P39: 1235425 | Q39: 139654 | R39: 4485348
A40: 3 | B40: 5 | C40: 27 | D40: 38 | E40: 72606 | F40: 17197506560 | G40: 0 | H40: 7 | I40: 0 | J40: 533.07223 | K40: 4836018782 | L40: 3330748 | M40: 0 | N40: 0 | O40: 4792864768 | P40: 1170133 | Q40: 184003 | R40: 4512599
A41: Average | B41: =AVERAGE(B38:B40) | C41: =AVERAGE(C38:C40) | D41: =AVERAGE(D38:D40) | E41: =AVERAGE(E38:E40) | F41: =AVERAGE(F38:F40) | G41: =AVERAGE(G38:G40) | H41: =AVERAGE(H38:H40) | I41: =AVERAGE(I38:I40) | ... R41: =AVERAGE(R38:R40)

Sheet Compress
A1: RAM | B1: 1024
A2: Experiment | B2: Iterations | C2: Setup-Time | D2: Downtime | E2: Total-Time | F2: Ram-Total | G2: Ram-Postcopy-Requests | H2: Ram-Dirty-Sync-Count | I2: Ram-Remaining | J2: Ram-Mbps | K2: Ram-Transferred | L2: Ram-Duplicate | M2: Ram-Dirty-Pages-Rate | N2: Ram-Skipped | O2: Ram-Normal-Bytes | P2: Ram-Normal | Q2: Total-Fake-Dirty-Pages | R2: Total-Transferred-Page-Count
A3: 1 | B3: 2 | C3: 3 | D3: 64 | E3: 6674 | F3: 1091379200 | G3: 0 | H3: 4 | I3: 0 | J3: 826.8793 | K3: 689301617 | L3: 11101 | M3: 0 | N3: 0 | O3: 32768 | P3: 8 | Q3: 14073 | R3: 289400
A4: 2 | B4: 2 | C4: 2 | D4: 120 | E4: 6719 | F4: 1091379200 | G4: 0 | H4: 4 | I4: 0 | J4: 847.2962 | K4: 711198716 | L4: 12186 | M4: 0 | N4: 0 | O4: 32768 | P4: 8 | Q4: 17905 | R4: 294820
A5: 3 | B5: 2 | C5: 2 | D5: 94 | E5: 6674 | F5: 1091379200 | G5: 0 | H5: 4 | I5: 0 | J5: 854.61673 | K5: 712537997 | L5: 11823 | M5: 0 | N5: 0 | O5: 32768 | P5: 8 | Q5: 15380 | R5: 293624
A6: Average | B6: =AVERAGE(B3:B5) | C6: =AVERAGE(C3:C5) | D6: =AVERAGE(D3:D5) | E6: =AVERAGE(E3:E5) | F6: =AVERAGE(F3:F5) | G6: =AVERAGE(G3:G5) | H6: =AVERAGE(H3:H5) | I6: =AVERAGE(I3:I5) | ... R6: =AVERAGE(R3:R5)
A8: RAM | B8: 2048
A9: Experiment | B9: Iterations | C9: Setup-Time | D9: Downtime | E9: Total-Time | F9: Ram-Total | G9: Ram-Postcopy-Requests | H9: Ram-Dirty-Sync-Count | I9: Ram-Remaining | J9: Ram-Mbps | K9: Ram-Transferred | L9: Ram-Duplicate | M9: Ram-Dirty-Pages-Rate | N9: Ram-Skipped | O9: Ram-Normal-Bytes | P9: Ram-Normal | Q9: Total-Fake-Dirty-Pages | R9: Total-Transferred-Page-Count
A10: 1 | B10: 3 | C10: 5 | D10: 55 | E10: 14963 | F10: 2165121024 | G10: 0 | H10: 5 | I10: 0 | J10: 866.85546 | K10: 1620590619 | L10: 10236 | M10: 0 | N10: 0 | O10: 28672 | P10: 7 | Q10: 54883 | R10: 610321
A11: 2 | B11: 3 | C11: 3 | D11: 84 | E11: 13938 | F11: 2165121024 | G11: 0 | H11: 5 | I11: 0 | J11: 895.92676 | K11: 1560380049 | L11: 11706 | M11: 0 | N11: 0 | O11: 32768 | P11: 8 | Q11: 42974 | R11: 598245
A12: 3 | B12: 3 | C12: 4 | D12: 46 | E12: 13675 | F12: 2165121024 | G12: 0 | H12: 5 | I12: 0 | J12: 893.91201 | K12: 1527371510 | L12: 10935 | M12: 0 | N12: 0 | O12: 32768 | P12: 8 | Q12: 33877 | R12: 585690
A13: Average | B13: =AVERAGE(B10:B12) | C13: =AVERAGE(C10:C12) | D13: =AVERAGE(D10:D12) | E13: =AVERAGE(E10:E12) | F13: =AVERAGE(F10:F12) | G13: =AVERAGE(G10:G12) | H13: =AVERAGE(H10:H12) | I13: =AVERAGE(I10:I12) | ... R13: =AVERAGE(R10:R12)
A15: RAM | B15: 4096
A16: Experiment | B16: Iterations | C16: Setup-Time | D16: Downtime | E16: Total-Time | F16: Ram-Total | G16: Ram-Postcopy-Requests | H16: Ram-Dirty-Sync-Count | I16: Ram-Remaining | J16: Ram-Mbps | K16: Ram-Transferred | L16: Ram-Duplicate | M16: Ram-Dirty-Pages-Rate | N16: Ram-Skipped | O16: Ram-Normal-Bytes | P16: Ram-Normal | Q16: Total-Fake-Dirty-Pages | R16: Total-Transferred-Page-Count
A17: 1 | B17: 5 | C17: 4 | D17: 104 | E17: 25650 | F17: 4312604672 | G17: 0 | H17: 7 | I17: 0 | J17: 724.01689 | K17: 2320804696 | L17: 308598 | M17: 0 | N17: 0 | O17: 28672 | P17: 7 | Q17: 124084 | R17: 1250820
A18: 2 | B18: 5 | C18: 5 | D18: 130 | E18: 25509 | F18: 4312604672 | G18: 0 | H18: 7 | I18: 0 | J18: 696.16847 | K18: 2219172636 | L18: 343072 | M18: 0 | N18: 0 | O18: 28672 | P18: 7 | Q18: 116241 | R18: 1241031
A19: 3 | B19: 5 | C19: 5 | D19: 68 | E19: 25411 | F19: 4312604672 | G19: 0 | H19: 7 | I19: 0 | J19: 717.55638 | K19: 2278567241 | L19: 317457 | M19: 0 | N19: 0 | O19: 28672 | P19: 7 | Q19: 109867 | R19: 1232623
A20: Average | B20: =AVERAGE(B17:B19) | C20: =AVERAGE(C17:C19) | D20: =AVERAGE(D17:D19) | E20: =AVERAGE(E17:E19) | F20: =AVERAGE(F17:F19) | G20: =AVERAGE(G17:G19) | H20: =AVERAGE(H17:H19) | I20: =AVERAGE(I17:I19) | ... R20: =AVERAGE(R17:R19)
A22: RAM | B22: 8192
A23: Experiment | B23: Iterations | C23: Setup-Time | D23: Downtime | E23: Total-Time | F23: Ram-Total | G23: Ram-Postcopy-Requests | H23: Ram-Dirty-Sync-Count | I23: Ram-Remaining | J23: Ram-Mbps | K23: Ram-Transferred | L23: Ram-Duplicate | M23: Ram-Dirty-Pages-Rate | N23: Ram-Skipped | O23: Ram-Normal-Bytes | P23: Ram-Normal | Q23: Total-Fake-Dirty-Pages | R23: Total-Transferred-Page-Count
A24: 1 | B24: 5 | C24: 6 | D24: 84 | E24: 37620 | F24: 8607571968 | G24: 0 | H24: 7 | I24: 0 | J24: 533.39797 | K24: 2507691490 | L24: 1308013 | M24: 0 | N24: 0 | O24: 28672 | P24: 7 | Q24: 129506 | R24: 2312509
A25: 2 | B25: 5 | C25: 6 | D25: 85 | E25: 37491 | F25: 8607571968 | G25: 0 | H25: 7 | I25: 0 | J25: 514.59406 | K25: 2410982343 | L25: 1353208 | M25: 0 | N25: 0 | O25: 28672 | P25: 7 | Q25: 149041 | R25: 2325575
A26: 3 | B26: 5 | C26: 6 | D26: 73 | E26: 37943 | F26: 8607571968 | G26: 0 | H26: 7 | I26: 0 | J26: 537.79042 | K26: 2550056966 | L26: 1298610 | M26: 0 | N26: 0 | O26: 28672 | P26: 7 | Q26: 143774 | R26: 2323435
A27: Average | B27: =AVERAGE(B24:B26) | C27: =AVERAGE(C24:C26) | D27: =AVERAGE(D24:D26) | E27: =AVERAGE(E24:E26) | F27: =AVERAGE(F24:F26) | G27: =AVERAGE(G24:G26) | H27: =AVERAGE(H24:H26) | I27: =AVERAGE(I24:I26) | ... R27: =AVERAGE(R24:R26)
A29: RAM | B29: 12288
A30: Experiment | B30: Iterations | C30: Setup-Time | D30: Downtime | E30: Total-Time | F30: Ram-Total | G30: Ram-Postcopy-Requests | H30: Ram-Dirty-Sync-Count | I30: Ram-Remaining | J30: Ram-Mbps | K30: Ram-Transferred | L30: Ram-Duplicate | M30: Ram-Dirty-Pages-Rate | N30: Ram-Skipped | O30: Ram-Normal-Bytes | P30: Ram-Normal | Q30: Total-Fake-Dirty-Pages | R30: Total-Transferred-Page-Count
A31: 1 | B31: 5 | C31: 9 | D31: 52 | E31: 50620 | F31: 12902539264 | G31: 0 | H31: 7 | I31: 0 | J31: 437.6199 | K31: 2768335134 | L31: 2302527 | M31: 0 | N31: 0 | O31: 28672 | P31: 7 | Q31: 172947 | R31: 3408877
A32: 2 | B32: 5 | C32: 8 | D32: 63 | E32: 51084 | F32: 12902539264 | G32: 0 | H32: 7 | I32: 0 | J32: 441.02649 | K32: 2815521172 | L32: 2289383 | M32: 0 | N32: 0 | O32: 28672 | P32: 7 | Q32: 170478 | R32: 3411131
A33: 3 | B33: 5 | C33: 8 | D33: 61 | E33: 50772 | F33: 12902539264 | G33: 0 | H33: 7 | I33: 0 | J33: 426.24998 | K33: 2704556781 | L33: 2343933 | M33: 0 | N33: 0 | O33: 28672 | P33: 7 | Q33: 184913 | R33: 3432266
A34: Average | B34: =AVERAGE(B31:B33) | C34: =AVERAGE(C31:C33) | D34: =AVERAGE(D31:D33) | E34: =AVERAGE(E31:E33) | F34: =AVERAGE(F31:F33) | G34: =AVERAGE(G31:G33) | H34: =AVERAGE(H31:H33) | I34: =AVERAGE(I31:I33) | ... R34: =AVERAGE(R31:R33)
A36: RAM | B36: 16384
A37: Experiment | B37: Iterations | C37: Setup-Time | D37: Downtime | E37: Total-Time | F37: Ram-Total | G37: Ram-Postcopy-Requests | H37: Ram-Dirty-Sync-Count | I37: Ram-Remaining | J37: Ram-Mbps | K37: Ram-Transferred | L37: Ram-Duplicate | M37: Ram-Dirty-Pages-Rate | N37: Ram-Skipped | O37: Ram-Normal-Bytes | P37: Ram-Normal | Q37: Total-Fake-Dirty-Pages | R37: Total-Transferred-Page-Count
A38: 1 | B38: 5 | C38: 17 | D38: 123 | E38: 62791 | F38: 17197506560 | G38: 0 | H38: 7 | I38: 0 | J38: 361.04086 | K38: 2832784917 | L38: 3342837 | M38: 0 | N38: 0 | O38: 36864 | P38: 9 | Q38: 206315 | R38: 4500603
A39: 2 | B39: 6 | C39: 10 | D39: 96 | E39: 62862 | F39: 17197506560 | G39: 0 | H39: 8 | I39: 0 | J39: 381.9492 | K39: 3000571405 | L39: 3263975 | M39: 0 | N39: 0 | O39: 53248 | P39: 13 | Q39: 177579 | R39: 4476582
A40: 3 | B40: 5 | C40: 11 | D40: 85 | E40: 62871 | F40: 17197506560 | G40: 0 | H40: 7 | I40: 0 | J40: 378.72685 | K40: 2975633778 | L40: 3304594 | M40: 0 | N40: 0 | O40: 36864 | P40: 9 | Q40: 194237 | R40: 4497358
A41: Average | B41: =AVERAGE(B38:B40) | C41: =AVERAGE(C38:C40) | D41: =AVERAGE(D38:D40) | E41: =AVERAGE(E38:E40) | F41: =AVERAGE(F38:F40) | G41: =AVERAGE(G38:G40) | H41: =AVERAGE(H38:H40) | I41: =AVERAGE(I38:I40) | ... R41: =AVERAGE(R38:R40)

Sheet HBFDP_SHA1
A1: RAM | B1: 1024
A2: Experiment | B2: Iterations | C2: Setup-Time | D2: Downtime | E2: Total-Time | F2: Ram-Total | G2: Ram-Postcopy-Requests | H2: Ram-Dirty-Sync-Count | I2: Ram-Remaining | J2: Ram-Mbps | K2: Ram-Transferred | L2: Ram-Duplicate | M2: Ram-Dirty-Pages-Rate | N2: Ram-Skipped | O2: Ram-Normal-Bytes | P2: Ram-Normal | Q2: Total-Fake-Dirty-Pages | R2: Total-Transferred-Page-Count
A3: 1 | B3: 2 | C3: 1 | D3: 49 | E3: 9686 | F3: 1091379200 | G3: 0 | H3: 4 | I3: 0 | J3: 916.12097 | K3: 1108866593 | L3: 9403 | M3: 0 | N3: 0 | O3: 1106620416 | P3: 270171 | Q3: 16787 | R3: 279574
A4: 2 | B4: 2 | C4: 1 | D4: 41 | E4: 9546 | F4: 1091379200 | G4: 0 | H4: 4 | I4: 0 | J4: 919.37032 | K4: 1096711355 | L4: 10861 | M4: 0 | N4: 0 | O4: 1094475776 | P4: 267206 | Q4: 18649 | R4: 278067
A5: 3 | B5: 2 | C5: 2 | D5: 49 | E5: 9536 | F5: 1091379200 | G5: 0 | H5: 4 | I5: 0 | J5: 919.13685 | K5: 1095168980 | L5: 11854 | M5: 0 | N5: 0 | O5: 1092927488 | P5: 266828 | Q5: 23221 | R5: 278682
A6: Average | B6: =AVERAGE(B3:B5) | C6: =AVERAGE(C3:C5) | D6: =AVERAGE(D3:D5) | E6: =AVERAGE(E3:E5) | F6: =AVERAGE(F3:F5) | G6: =AVERAGE(G3:G5) | H6: =AVERAGE(H3:H5) | I6: =AVERAGE(I3:I5) | ... R6: =AVERAGE(R3:R5)
A8: RAM | B8: 2048
A9: Experiment | B9: Iterations | C9: Setup-Time | D9: Downtime | E9: Total-Time | F9: Ram-Total | G9: Ram-Postcopy-Requests | H9: Ram-Dirty-Sync-Count | I9: Ram-Remaining | J9: Ram-Mbps | K9: Ram-Transferred | L9: Ram-Duplicate | M9: Ram-Dirty-Pages-Rate | N9: Ram-Skipped | O9: Ram-Normal-Bytes | P9: Ram-Normal | Q9: Total-Fake-Dirty-Pages | R9: Total-Transferred-Page-Count
A10: 1 | B10: 3 | C10: 3 | D10: 41 | E10: 20249 | F10: 2165121024 | G10: 0 | H10: 5 | I10: 0 | J10: 908.02332 | K10: 2297767627 | L10: 12245 | M10: 0 | N10: 0 | O10: 2293178368 | P10: 559858 | Q10: 51351 | R10: 572103
A11: 2 | B11: 3 | C11: 1 | D11: 65 | E11: 20302 | F11: 2165121024 | G11: 0 | H11: 5 | I11: 0 | J11: 904.38743 | K11: 2294783776 | L11: 12218 | M11: 0 | N11: 0 | O11: 2290200576 | P11: 559131 | Q11: 46573 | R11: 571349
A12: 3 | B12: 3 | C12: 2 | D12: 70 | E12: 20147 | F12: 2165121024 | G12: 0 | H12: 5 | I12: 0 | J12: 918.26753 | K12: 2312100046 | L12: 12384 | M12: 0 | N12: 0 | O12: 2307481600 | P12: 563350 | Q12: 54947 | R12: 575734
A13: Average | B13: =AVERAGE(B10:B12) | C13: =AVERAGE(C10:C12) | D13: =AVERAGE(D10:D12) | E13: =AVERAGE(E10:E12) | F13: =AVERAGE(F10:F12) | G13: =AVERAGE(G10:G12) | H13: =AVERAGE(H10:H12) | I13: =AVERAGE(I10:I12) | ... R13: =AVERAGE(R10:R12)
A15: RAM | B15: 4096
A16: Experiment | B16: Iterations | C16: Setup-Time | D16: Downtime | E16: Total-Time | F16: Ram-Total | G16: Ram-Postcopy-Requests | H16: Ram-Dirty-Sync-Count | I16: Ram-Remaining | J16: Ram-Mbps | K16: Ram-Transferred | L16: Ram-Duplicate | M16: Ram-Dirty-Pages-Rate | N16: Ram-Skipped | O16: Ram-Normal-Bytes | P16: Ram-Normal | Q16: Total-Fake-Dirty-Pages | R16: Total-Transferred-Page-Count
A17: 1 | B17: 5 | C17: 3 | D17: 36 | E17: 34442 | F17: 4312604672 | G17: 0 | H17: 7 | I17: 0 | J17: 811.55193 | K17: 3493417184 | L17: 293874 | M17: 0 | N17: 0 | O17: 3483967488 | P17: 850578 | Q17: 153693 | R17: 1144452
A18: 2 | B18: 4 | C18: 4 | D18: 62 | E18: 34483 | F18: 4312604672 | G18: 0 | H18: 6 | I18: 0 | J18: 808.02744 | K18: 3482284869 | L18: 290887 | M18: 0 | N18: 0 | O18: 3472883712 | P18: 847872 | Q18: 159851 | R18: 1138759
A19: 3 | B19: 4 | C19: 3 | D19: 52 | E19: 34754 | F19: 4312604672 | G19: 0 | H19: 6 | I19: 0 | J19: 863.39238 | K19: 3750256152 | L19: 230762 | M19: 0 | N19: 0 | O19: 3740872704 | P19: 913299 | Q19: 54884 | R19: 1144061
A20: Average | B20: =AVERAGE(B17:B19) | C20: =AVERAGE(C17:C19) | D20: =AVERAGE(D17:D19) | E20: =AVERAGE(E17:E19) | F20: =AVERAGE(F17:F19) | G20: =AVERAGE(G17:G19) | H20: =AVERAGE(H17:H19) | I20: =AVERAGE(I17:I19) | ... R20: =AVERAGE(R17:R19)
A22: RAM | B22: 8192
A23: Experiment | B23: Iterations | C23: Setup-Time | D23: Downtime | E23: Total-Time | F23: Ram-Total | G23: Ram-Postcopy-Requests | H23: Ram-Dirty-Sync-Count | I23: Ram-Remaining | J23: Ram-Mbps | K23: Ram-Transferred | L23: Ram-Duplicate | M23: Ram-Dirty-Pages-Rate | N23: Ram-Skipped | O23: Ram-Normal-Bytes | P23: Ram-Normal | Q23: Total-Fake-Dirty-Pages | R23: Total-Transferred-Page-Count
A24: 1 | B24: 4 | C24: 6 | D24: 63 | E24: 45863 | F24: 8607571968 | G24: 0 | H24: 6 | I24: 0 | J24: 663.78414 | K24: 3804681276 | L24: 1275222 | M24: 0 | N24: 0 | O24: 3785809920 | P24: 924270 | Q24: 87721 | R24: 2199492
A25: 2 | B25: 4 | C25: 5 | D25: 47 | E25: 45288 | F25: 8607571968 | G25: 0 | H25: 6 | I25: 0 | J25: 676.31486 | K25: 3827983338 | L25: 1278364 | M25: 0 | N25: 0 | O25: 3809038336 | P25: 929941 | Q25: 97069 | R25: 2208305
A26: 3 | B26: 4 | C26: 6 | D26: 53 | E26: 45495 | F26: 8607571968 | G26: 0 | H26: 6 | I26: 0 | J26: 631.14387 | K26: 3588550506 | L26: 1326548 | M26: 0 | N26: 0 | O26: 3569639424 | P26: 871494 | Q26: 188294 | R26: 2198042
A27: Average | B27: =AVERAGE(B24:B26) | C27: =AVERAGE(C24:C26) | D27: =AVERAGE(D24:D26) | E27: =AVERAGE(E24:E26) | F27: =AVERAGE(F24:F26) | G27: =AVERAGE(G24:G26) | H27: =AVERAGE(H24:H26) | I27: =AVERAGE(I24:I26) | ... R27: =AVERAGE(R24:R26)
A29: RAM | B29: 12288
A30: Experiment | B30: Iterations | C30: Setup-Time | D30: Downtime | E30: Total-Time | F30: Ram-Total | G30: Ram-Postcopy-Requests | H30: Ram-Dirty-Sync-Count | I30: Ram-Remaining | J30: Ram-Mbps | K30: Ram-Transferred | L30: Ram-Duplicate | M30: Ram-Dirty-Pages-Rate | N30: Ram-Skipped | O30: Ram-Normal-Bytes | P30: Ram-Normal | Q30: Total-Fake-Dirty-Pages | R30: Total-Transferred-Page-Count
A31: 1 | B31: 4 | C31: 8 | D31: 43 | E31: 54369 | F31: 12902539264 | G31: 0 | H31: 6 | I31: 0 | J31: 546.18267 | K31: 3711167127 | L31: 2350881 | M31: 0 | N31: 0 | O31: 3682816000 | P31: 899125 | Q31: 104648 | R31: 3250006
A32: 2 | B32: 4 | C32: 7 | D32: 57 | E32: 55592 | F32: 12902539264 | G32: 0 | H32: 6 | I32: 0 | J32: 556.096 | K32: 3863612142 | L32: 2324192 | M32: 0 | N32: 0 | O32: 3835203584 | P32: 936329 | Q32: 92847 | R32: 3260521
A33: 3 | B33: 4 | C33: 7 | D33: 54 | E33: 55240 | F33: 12902539264 | G33: 0 | H33: 6 | I33: 0 | J33: 539.17057 | K33: 3722288625 | L33: 2358139 | M33: 0 | N33: 0 | O33: 3693850624 | P33: 901819 | Q33: 174456 | R33: 3259958
A34: Average | B34: =AVERAGE(B31:B33) | C34: =AVERAGE(C31:C33) | D34: =AVERAGE(D31:D33) | E34: =AVERAGE(E31:E33) | F34: =AVERAGE(F31:F33) | G34: =AVERAGE(G31:G33) | H34: =AVERAGE(H31:H33) | I34: =AVERAGE(I31:I33) | ... R34: =AVERAGE(R31:R33)
A36: RAM | B36: 16384
A37: Experiment | B37: Iterations | C37: Setup-Time | D37: Downtime | E37: Total-Time | F37: Ram-Total | G37: Ram-Postcopy-Requests | H37: Ram-Dirty-Sync-Count | I37: Ram-Remaining | J37: Ram-Mbps | K37: Ram-Transferred | L37: Ram-Duplicate | M37: Ram-Dirty-Pages-Rate | N37: Ram-Skipped | O37: Ram-Normal-Bytes | P37: Ram-Normal | Q37: Total-Fake-Dirty-Pages | R37: Total-Transferred-Page-Count
A38: 1 | B38: 5 | C38: 9 | D38: 47 | E38: 70050 | F38: 17197506560 | G38: 0 | H38: 7 | I38: 0 | J38: 491.67883 | K38: 4304497175 | L38: 3302825 | M38: 0 | N38: 0 | O38: 4266438656 | P38: 1041611 | Q38: 259505 | R38: 4344436
A39: 2 | B39: 5 | C39: 9 | D39: 46 | E39: 69335 | F39: 17197506560 | G39: 0 | H39: 7 | I39: 0 | J39: 471.46826 | K39: 4085413667 | L39: 3333869 | M39: 0 | N39: 0 | O39: 4047503360 | P39: 988160 | Q39: 228979 | R39: 4322029
A40: 3 | B40: 4 | C40: 8 | D40: 55 | E40: 69620 | F40: 17197506560 | G40: 0 | H40: 6 | I40: 0 | J40: 519.81974 | K40: 4522999023 | L40: 3234969 | M40: 0 | N40: 0 | O40: 4485124096 | P40: 1095001 | Q40: 238710 | R40: 4329970
A41: Average | B41: =AVERAGE(B38:B40) | C41: =AVERAGE(C38:C40) | D41: =AVERAGE(D38:D40) | E41: =AVERAGE(E38:E40) | F41: =AVERAGE(F38:F40) | G41: =AVERAGE(G38:G40) | H41: =AVERAGE(H38:H40) | I41: =AVERAGE(I38:I40) | ... R41: =AVERAGE(R38:R40)

Sheet HBFDP_MD5
A1: RAM | B1: 1024
A2: Experiment | B2: Iterations | C2: Setup-Time | D2: Downtime | E2: Total-Time | F2: Ram-Total | G2: Ram-Postcopy-Requests | H2: Ram-Dirty-Sync-Count | I2: Ram-Remaining | J2: Ram-Mbps | K2: Ram-Transferred | L2: Ram-Duplicate | M2: Ram-Dirty-Pages-Rate | N2: Ram-Skipped | O2: Ram-Normal-Bytes | P2: Ram-Normal | Q2: Total-Fake-Dirty-Pages | R2: Total-Transferred-Page-Count
A3: 1 | B3: 2 | C3: 2 | D3: 67 | E3: 9554 | F3: 1091379200 | G3: 0 | H3: 4 | I3: 0 | J3: 929.15413 | K3: 1109197676 | L3: 10622 | M3: 0 | N3: 0 | O3: 1106939904 | P3: 270249 | Q3: 23766 | R3: 280871
A4: 2 | B4: 2 | C4: 2 | D4: 56 | E4: 9652 | F4: 1091379200 | G4: 0 | H4: 4 | I4: 0 | J4: 911.30043 | K4: 1099043786 | L4: 10556 | M4: 0 | N4: 0 | O4: 1096806400 | P4: 267775 | Q4: 20672 | R4: 278331
A5: 3 | B5: 2 | C5: 1 | D5: 52 | E5: 9572 | F5: 1091379200 | G5: 0 | H5: 4 | I5: 0 | J5: 918.66385 | K5: 1098854102 | L5: 11368 | M5: 0 | N5: 0 | O5: 1096609792 | P5: 267727 | Q5: 17860 | R5: 279095
A6: Average | B6: =AVERAGE(B3:B5) | C6: =AVERAGE(C3:C5) | D6: =AVERAGE(D3:D5) | E6: =AVERAGE(E3:E5) | F6: =AVERAGE(F3:F5) | G6: =AVERAGE(G3:G5) | H6: =AVERAGE(H3:H5) | I6: =AVERAGE(I3:I5) | ... R6: =AVERAGE(R3:R5)
A8: RAM | B8: 2048
A9: Experiment | B9: Iterations | C9: Setup-Time | D9: Downtime | E9: Total-Time | F9: Ram-Total | G9: Ram-Postcopy-Requests | H9: Ram-Dirty-Sync-Count | I9: Ram-Remaining | J9: Ram-Mbps | K9: Ram-Transferred | L9: Ram-Duplicate | M9: Ram-Dirty-Pages-Rate | N9: Ram-Skipped | O9: Ram-Normal-Bytes | P9: Ram-Normal | Q9: Total-Fake-Dirty-Pages | R9: Total-Transferred-Page-Count
A10: 1 | B10: 3 | C10: 2 | D10: 31 | E10: 20253 | F10: 2165121024 | G10: 0 | H10: 5 | I10: 0 | J10: 903.11449 | K10: 2285909047 | L10: 12465 | M10: 0 | N10: 0 | O10: 2281340928 | P10: 556968 | Q10: 47016 | R10: 569433
A11: 2 | B11: 3 | C11: 2 | D11: 38 | E11: 20060 | F11: 2165121024 | G11: 0 | H11: 5 | I11: 0 | J11: 914.05725 | K11: 2291557663 | L11: 12177 | M11: 0 | N11: 0 | O11: 2286981120 | P11: 558345 | Q11: 47118 | R11: 570522
A12: 3 | B12: 3 | C12: 2 | D12: 47 | E12: 20240 | F12: 2165121024 | G12: 0 | H12: 5 | I12: 0 | J12: 906.44535 | K12: 2292867748 | L12: 12278 | M12: 0 | N12: 0 | O12: 2288287744 | P12: 558664 | Q12: 50743 | R12: 570942
A13: Average | B13: =AVERAGE(B10:B12) | C13: =AVERAGE(C10:C12) | D13: =AVERAGE(D10:D12) | E13: =AVERAGE(E10:E12) | F13: =AVERAGE(F10:F12) | G13: =AVERAGE(G10:G12) | H13: =AVERAGE(H10:H12) | I13: =AVERAGE(I10:I12) | ... R13: =AVERAGE(R10:R12)
A15: RAM | B15: 4096
A16: Experiment | B16: Iterations | C16: Setup-Time | D16: Downtime | E16: Total-Time | F16: Ram-Total | G16: Ram-Postcopy-Requests | H16: Ram-Dirty-Sync-Count | I16: Ram-Remaining | J16: Ram-Mbps | K16: Ram-Transferred | L16: Ram-Duplicate | M16: Ram-Dirty-Pages-Rate | N16: Ram-Skipped | O16: Ram-Normal-Bytes | P16: Ram-Normal | Q16: Total-Fake-Dirty-Pages | R16: Total-Transferred-Page-Count
A17: 1 | B17: 4 | C17: 3 | D17: 56 | E17: 32809 | F17: 4312604672 | G17: 0 | H17: 6 | I17: 0 | J17: 818.82922 | K17: 3357601524 | L17: 319646 | M17: 0 | N17: 0 | O17: 3348185088 | P17: 817428 | Q17: 47756 | R17: 1137074
A18: 2 | B18: 4 | C18: 4 | D18: 52 | E18: 33608 | F18: 4312604672 | G18: 0 | H18: 6 | I18: 0 | J18: 819.53102 | K18: 3442227651 | L18: 297941 | M18: 0 | N18: 0 | O18: 3432841216 | P18: 838096 | Q18: 78707 | R18: 1136037
A19: 3 | B19: 4 | C19: 4 | D19: 58 | E19: 32786 | F19: 4312604672 | G19: 0 | H19: 6 | I19: 0 | J19: 824.43692 | K19: 3378123990 | L19: 318096 | M19: 0 | N19: 0 | O19: 3368681472 | P19: 822432 | Q19: 37667 | R19: 1140528
A20: Average | B20: =AVERAGE(B17:B19) | C20: =AVERAGE(C17:C19) | D20: =AVERAGE(D17:D19) | E20: =AVERAGE(E17:E19) | F20: =AVERAGE(F17:F19) | G20: =AVERAGE(G17:G19) | H20: =AVERAGE(H17:H19) | I20: =AVERAGE(I17:I19) | ... R20: =AVERAGE(R17:R19)
A22: RAM | B22: 8192
A23: Experiment | B23: Iterations | C23: Setup-Time | D23: Downtime | E23: Total-Time | F23: Ram-Total | G23: Ram-Postcopy-Requests | H23: Ram-Dirty-Sync-Count | I23: Ram-Remaining | J23: Ram-Mbps | K23: Ram-Transferred | L23: Ram-Duplicate | M23: Ram-Dirty-Pages-Rate | N23: Ram-Skipped | O23: Ram-Normal-Bytes | P23: Ram-Normal | Q23: Total-Fake-Dirty-Pages | R23: Total-Transferred-Page-Count
A24: 1 | B24: 3 | C24: 4 | D24: 68 | E24: 42750 | F24: 8607571968 | G24: 0 | H24: 5 | I24: 0 | J24: 632.16295 | K24: 3377592280 | L24: 1315570 | M24: 0 | N24: 0 | O24: 3359191040 | P24: 820115 | Q24: 27625 | R24: 2135685
A25: Average | B25: =AVERAGE(B24:B26) | C25: =AVERAGE(C24:C26) | D25: =AVERAGE(D24:D26) | E25: =AVERAGE(E24:E26) | F25: =AVERAGE(F24:F26) | G25: =AVERAGE(G24:G26) | H25: =AVERAGE(H24:H26) | I25: =AVERAGE(I24:I26) | ... R25: =AVERAGE(R24:R26)
A27: RAM | B27: 12288
A28: Experiment | B28: Iterations | C28: Setup-Time | D28: Downtime | E28: Total-Time | F28: Ram-Total | G28: Ram-Postcopy-Requests | H28: Ram-Dirty-Sync-Count | I28: Ram-Remaining | J28: Ram-Mbps | K28: Ram-Transferred | L28: Ram-Duplicate | M28: Ram-Dirty-Pages-Rate | N28: Ram-Skipped | O28: Ram-Normal-Bytes | P28: Ram-Normal | Q28: Total-Fake-Dirty-Pages | R28: Total-Transferred-Page-Count
A29: Average | B29: =AVERAGE(B31:B33) | C29: =AVERAGE(C31:C33) | D29: =AVERAGE(D31:D33) | E29: =AVERAGE(E31:E33) | F29: =AVERAGE(F31:F33) | G29: =AVERAGE(G31:G33) | H29: =AVERAGE(H31:H33) | I29: =AVERAGE(I31:I33) | ... R29: =AVERAGE(R31:R33)
A31: RAM | B31: 16384
A32: Experiment | B32: Iterations | C32: Setup-Time | D32: Downtime | E32: Total-Time | F32: Ram-Total | G32: Ram-Postcopy-Requests | H32: Ram-Dirty-Sync-Count | I32: Ram-Remaining | J32: Ram-Mbps | K32: Ram-Transferred | L32: Ram-Duplicate | M32: Ram-Dirty-Pages-Rate | N32: Ram-Skipped | O32: Ram-Normal-Bytes | P32: Ram-Normal | Q32: Total-Fake-Dirty-Pages | R32: Total-Transferred-Page-Count
A33: 1 | B33: 3 | C33: 8 | D33: 54 | E33: 68312 | F33: 17197506560 | G33: 0 | H33: 5 | I33: 0 | J33: 462.15386 | K33: 3945657241 | L33: 3292051 | M33: 0 | N33: 0 | O33: 3908395008 | P33: 954198 | Q33: 92718 | R33: 4246249
A34: Average | B34: =AVERAGE(B38:B40) | C34: =AVERAGE(C38:C40) | D34: =AVERAGE(D38:D40) | E34: =AVERAGE(E38:E40) | F34: =AVERAGE(F38:F40) | G34: =AVERAGE(G38:G40) | H34: =AVERAGE(H38:H40) | I34: =AVERAGE(I38:I40) | ... R34: =AVERAGE(R38:R40)

Sheet HBFDP_Murmur3
A1: RAM | B1: 1024
A2: Experiment | B2: Iterations | C2: Setup-Time | D2: Downtime | E2: Total-Time | F2: Ram-Total | G2: Ram-Postcopy-Requests | H2: Ram-Dirty-Sync-Count | I2: Ram-Remaining | J2: Ram-Mbps | K2: Ram-Transferred | L2: Ram-Duplicate | M2: Ram-Dirty-Pages-Rate | N2: Ram-Skipped | O2: Ram-Normal-Bytes | P2: Ram-Normal | Q2: Total-Fake-Dirty-Pages | R2: Total-Transferred-Page-Count
A3: 1 | B3: 2 | C3: 2 | D3: 53 | E3: 9416 | F3: 1091379200 | G3: 0 | H3: 4 | I3: 0 | J3: 930.94278 | K3: 1095274559 | L3: 12641 | M3: 0 | N3: 0 | O3: 1093025792 | P3: 266852 | Q3: 19069 | R3: 279493
A4: 2 | B4: 2 | C4: 2 | D4: 42 | E4: 9491 | F4: 1091379200 | G4: 0 | H4: 4 | I4: 0 | J4: 919.16353 | K4: 1090030484 | L4: 12278 | M4: 0 | N4: 0 | O4: 1087795200 | P4: 265575 | Q4: 16914 | R4: 277853
A5: 3 | B5: 2 | C5: 2 | D5: 48 | E5: 9437 | F5: 1091379200 | G5: 0 | H5: 4 | I5: 0 | J5: 932.23459 | K5: 1099241813 | L5: 11127 | M5: 0 | N5: 0 | O5: 1096998912 | P5: 267822 | Q5: 18239 | R5: 278949
A6: Average | B6: =AVERAGE(B3:B5) | C6: =AVERAGE(C3:C5) | D6: =AVERAGE(D3:D5) | E6: =AVERAGE(E3:E5) | F6: =AVERAGE(F3:F5) | G6: =AVERAGE(G3:G5) | H6: =AVERAGE(H3:H5) | I6: =AVERAGE(I3:I5) | ... R6: =AVERAGE(R3:R5)
A8: RAM | B8: 2048
A9: Experiment | B9: Iterations | C9: Setup-Time | D9: Downtime | E9: Total-Time | F9: Ram-Total | G9: Ram-Postcopy-Requests | H9: Ram-Dirty-Sync-Count | I9: Ram-Remaining | J9: Ram-Mbps | K9: Ram-Transferred | L9: Ram-Duplicate | M9: Ram-Dirty-Pages-Rate | N9: Ram-Skipped | O9: Ram-Normal-Bytes | P9: Ram-Normal | Q9: Total-Fake-Dirty-Pages | R9: Total-Transferred-Page-Count
A10: 1 | B10: 3 | C10: 2 | D10: 53 | E10: 20202 | F10: 2165121024 | G10: 0 | H10: 5 | I10: 0 | J10: 913.52163 | K10: 2306429722 | L10: 12084 | M10: 0 | N10: 0 | O10: 2301825024 | P10: 561969 | Q10: 53482 | R10: 574053
A11: 2 | B11: 3 | C11: 2 | D11: 36 | E11: 20161 | F11: 2165121024 | G11: 0 | H11: 5 | I11: 0 | J11: 908.75161 | K11: 2289728089 | L11: 11811 | M11: 0 | N11: 0 | O11: 2285158400 | P11: 557900 | Q11: 47436 | R11: 569711
A12: 3 | B12: 3 | C12: 3 | D12: 52 | E12: 20259 | F12: 2165121024 | G12: 0 | H12: 5 | I12: 0 | J12: 901.25498 | K12: 2281765231 | L12: 13057 | M12: 0 | N12: 0 | O12: 2277199872 | P12: 555957 | Q12: 55950 | R12: 569014
A13: Average | B13: =AVERAGE(B10:B12) | C13: =AVERAGE(C10:C12) | D13: =AVERAGE(D10:D12) | E13: =AVERAGE(E10:E12) | F13: =AVERAGE(F10:F12) | G13: =AVERAGE(G10:G12) | H13: =AVERAGE(H10:H12) | I13: =AVERAGE(I10:I12) | ... R13: =AVERAGE(R10:R12)
A15: RAM | B15: 4096
A16: Experiment | B16: Iterations | C16: Setup-Time | D16: Downtime | E16: Total-Time | F16: Ram-Total | G16: Ram-Postcopy-Requests | H16: Ram-Dirty-Sync-Count | I16: Ram-Remaining | J16: Ram-Mbps | K16: Ram-Transferred | L16: Ram-Duplicate | M16: Ram-Dirty-Pages-Rate | N16: Ram-Skipped | O16: Ram-Normal-Bytes | P16: Ram-Normal | Q16: Total-Fake-Dirty-Pages | R16: Total-Transferred-Page-Count
A17: 1 | B17: 4 | C17: 4 | D17: 64 | E17: 33229 | F17: 4312604672 | G17: 0 | H17: 6 | I17: 0 | J17: 796.56905 | K17: 3308038409 | L17: 334790 | M17: 0 | N17: 0 | O17: 3298582528 | P17: 805318 | Q17: 165358 | R17: 1140108
A18: 2 | B18: 4 | C18: 5 | D18: 73 | E18: 33445 | F18: 4312604672 | G18: 0 | H18: 6 | I18: 0 | J18: 826.05551 | K18: 3452699628 | L18: 298238 | M18: 0 | N18: 0 | O18: 3443290112 | P18: 840647 | Q18: 106691 | R18: 1138885
A19: 3 | B19: 4 | C19: 4 | D19: 75 | E19: 33504 | F19: 4312604672 | G19: 0 | H19: 6 | I19: 0 | J19: 818.99194 | K19: 3429316332 | L19: 312062 | M19: 0 | N19: 0 | O19: 3419828224 | P19: 834919 | Q19: 100272 | R19: 1146981
A20: Average | B20: =AVERAGE(B17:B19) | C20: =AVERAGE(C17:C19) | D20: =AVERAGE(D17:D19) | E20: =AVERAGE(E17:E19) | F20: =AVERAGE(F17:F19) | G20: =AVERAGE(G17:G19) | H20: =AVERAGE(H17:H19) | I20: =AVERAGE(I17:I19) | ... R20: =AVERAGE(R17:R19)
A22: RAM | B22: 8192
A23: Experiment | B23: Iterations | C23: Setup-Time | D23: Downtime | E23: Total-Time | F23: Ram-Total | G23: Ram-Postcopy-Requests | H23: Ram-Dirty-Sync-Count | I23: Ram-Remaining | J23: Ram-Mbps | K23: Ram-Transferred | L23: Ram-Duplicate | M23: Ram-Dirty-Pages-Rate | N23: Ram-Skipped | O23: Ram-Normal-Bytes | P23: Ram-Normal | Q23: Total-Fake-Dirty-Pages | R23: Total-Transferred-Page-Count
A24: 1 | B24: 4 | C24: 5 | D24: 69 | E24: 44017 | F24: 8607571968 | G24: 0 | H24: 6 | I24: 0 | J24: 632.45541 | K24: 3479241024 | L24: 1349410 | M24: 0 | N24: 0 | O24: 3460337664 | P24: 844809 | Q24: 86534 | R24: 2194219
A25: 2 | B25: 4 | C25: 5 | D25: 43 | E25: 44278 | F25: 8607571968 | G25: 0 | H25: 6 | I25: 0 | J25: 654.07635 | K25: 3619527885 | L25: 1315647 | M25: 0 | N25: 0 | O25: 3600654336 | P25: 879066 | Q25: 130797 | R25: 2194713
A26: 3 | B26: 4 | C26: 5 | D26: 51 | E26: 44543 | F26: 8607571968 | G26: 0 | H26: 6 | I26: 0 | J26: 654.73967 | K26: 3644886996 | L26: 1309774 | M26: 0 | N26: 0 | O26: 3626016768 | P26: 885258 | Q26: 99067 | R26: 2195032
A27: Average | B27: =AVERAGE(B24:B26) | C27: =AVERAGE(C24:C26) | D27: =AVERAGE(D24:D26) | E27: =AVERAGE(E24:E26) | F27: =AVERAGE(F24:F26) | G27: =AVERAGE(G24:G26) | H27: =AVERAGE(H24:H26) | I27: =AVERAGE(I24:I26) | ... R27: =AVERAGE(R24:R26)
A29: RAM | B29: 12288
A30: Experiment | B30: Iterations | C30: Setup-Time | D30: Downtime | E30: Total-Time | F30: Ram-Total | G30: Ram-Postcopy-Requests | H30: Ram-Dirty-Sync-Count | I30: Ram-Remaining | J30: Ram-Mbps | K30: Ram-Transferred | L30: Ram-Duplicate | M30: Ram-Dirty-Pages-Rate | N30: Ram-Skipped | O30: Ram-Normal-Bytes | P30: Ram-Normal | Q30: Total-Fake-Dirty-Pages | R30: Total-Transferred-Page-Count
A31: 1 | B31: 4 | C31: 8 | D31: 61 | E31: 55320 | F31: 12902539264 | G31: 0 | H31: 6 | I31: 0 | J31: 551.50365 | K31: 3812883822 | L31: 2334360 | M31: 0 | N31: 0 | O31: 3784482816 | P31: 923946 | Q31: 78176 | R31: 3258306
A32: 2 | B32: 4 | C32: 7 | D32: 57 | E32: 55014 | F32: 12902539264 | G32: 0 | H32: 6 | I32: 0 | J32: 537.65937 | K32: 3696666192 | L32: 2355274 | M32: 0 | N32: 0 | O32: 3668303872 | P32: 895582 | Q32: 74954 | R32: 3250856
A33: 3 | B33: 3 | C33: 6 | D33: 65 | E33: 55920 | F33: 12902539264 | G33: 0 | H33: 5 | I33: 0 | J33: 591.80485 | K33: 4136059630 | L33: 2193704 | M33: 0 | N33: 0 | O33: 4108292096 | P33: 1003001 | Q33: 116860 | R33: 3196705
A34: Average | B34: =AVERAGE(B31:B33) | C34: =AVERAGE(C31:C33) | D34: =AVERAGE(D31:D33) | E34: =AVERAGE(E31:E33) | F34: =AVERAGE(F31:F33) | G34: =AVERAGE(G31:G33) | H34: =AVERAGE(H31:H33) | I34: =AVERAGE(I31:I33) | ... R34: =AVERAGE(R31:R33)
A36: RAM | B36: 16384
A37: Experiment | B37: Iterations | C37: Setup-Time | D37: Downtime | E37: Total-Time | F37: Ram-Total | G37: Ram-Postcopy-Requests | H37: Ram-Dirty-Sync-Count | I37: Ram-Remaining | J37: Ram-Mbps | K37: Ram-Transferred | L37: Ram-Duplicate | M37: Ram-Dirty-Pages-Rate | N37: Ram-Skipped | O37: Ram-Normal-Bytes | P37: Ram-Normal | Q37: Total-Fake-Dirty-Pages | R37: Total-Transferred-Page-Count
A38: 1 | B38: 4 | C38: 8 | D38: 74 | E38: 69739 | F38: 17197506560 | G38: 0 | H38: 6 | I38: 0 | J38: 537.81897 | K38: 4687619391 | L38: 3200393 | M38: 0 | N38: 0 | O38: 4649734144 | P38: 1135189 | Q38: 134279 | R38: 4335582
A39: 2 | B39: 4 | C39: 9 | D39: 50 | E39: 68861 | F39: 17197506560 | G39: 0 | H39: 6 | I39: 0 | J39: 489.91616 | K39: 4216251042 | L39: 3304892 | M39: 0 | N39: 0 | O39: 4178345984 | P39: 1020104 | Q39: 171766 | R39: 4324996
A40: 3 | B40: 5 | C40: 10 | D40: 47 | E40: 69355 | F40: 17197506560 | G40: 0 | H40: 7 | I40: 0 | J40: 519.80917 | K40: 4505558428 | L40: 3248801 | M40: 0 | N40: 0 | O40: 4467593216 | P40: 1090721 | Q40: 277250 | R40: 4339522
A41: Average | B41: =AVERAGE(B38:B40) | C41: =AVERAGE(C38:C40) | D41: =AVERAGE(D38:D40) | E41: =AVERAGE(E38:E40) | F41: =AVERAGE(F38:F40) | G41: =AVERAGE(G38:G40) | H41: =AVERAGE(H38:H40) | I41: =AVERAGE(I38:I40) | ... R41: =AVERAGE(R38:R40)

Sheet XBZRLE_HBFDP_SHA1
A1: RAM | B1: 1024
A2: Experiment | B2: Iterations | C2: Setup-Time | D2: Downtime | E2: Total-Time | F2: Ram-Total | G2: Ram-Postcopy-Requests | H2: Ram-Dirty-Sync-Count | I2: Ram-Remaining | J2: Ram-Mbps | K2: Ram-Transferred | L2: Ram-Duplicate | M2: Ram-Dirty-Pages-Rate | N2: Ram-Skipped | O2: Ram-Normal-Bytes | P2: Ram-Normal | Q2: Total-Fake-Dirty-Pages | R2: Total-Transferred-Page-Count
A3: 1 | B3: 2 | C3: 31 | D3: 349 | E3: 10482 | F3: 1091379200 | G3: 0 | H3: 4 | I3: 0 | J3: 871.02645 | K3: 1137674815 | L3: 11791 | M3: 0 | N3: 0 | O3: 1135153152 | P3: 277137 | Q3: 22194 | R3: 290074
A4: 2 | B4: 3 | C4: 31 | D4: 524 | E4: 10783 | F4: 1091379200 | G4: 0 | H4: 5 | I4: 0 | J4: 870.02783 | K4: 1169105023 | L4: 9610 | M4: 0 | N4: 0 | O4: 1166278656 | P4: 284736 | Q4: 26322 | R4: 296360
A5: 3 | B5: 3 | C5: 31 | D5: 323 | E5: 10427 | F5: 1091379200 | G5: 0 | H5: 5 | I5: 0 | J5: 875.45607 | K5: 1137442775 | L5: 11775 | M5: 0 | N5: 0 | O5: 1134698496 | P5: 277026 | Q5: 27540 | R5: 290703
A6: Average | B6: =AVERAGE(B3:B5) | C6: =AVERAGE(C3:C5) | D6: =AVERAGE(D3:D5) | E6: =AVERAGE(E3:E5) | F6: =AVERAGE(F3:F5) | G6: =AVERAGE(G3:G5) | H6: =AVERAGE(H3:H5) | I6: =AVERAGE(I3:I5) | ... R6: =AVERAGE(R3:R5)
A8: RAM | B8: 2048
A9: Experiment | B9: Iterations | C9: Setup-Time | D9: Downtime | E9: Total-Time | F9: Ram-Total | G9: Ram-Postcopy-Requests | H9: Ram-Dirty-Sync-Count | I9: Ram-Remaining | J9: Ram-Mbps | K9: Ram-Transferred | L9: Ram-Duplicate | M9: Ram-Dirty-Pages-Rate | N9: Ram-Skipped | O9: Ram-Normal-Bytes | P9: Ram-Normal | Q9: Total-Fake-Dirty-Pages | R9: Total-Transferred-Page-Count
A10: 1 | B10: 3 | C10: 31 | D10: 27 | E10: 20017 | F10: 2165121024 | G10: 0 | H10: 5 | I10: 0 | J10: 912.11871 | K10: 2278488179 | L10: 11934 | M10: 0 | N10: 0 | O10: 2273292288 | P10: 555003 | Q10: 50338 | R10: 569054
A11: 2 | B11: 3 | C11: 31 | D11: 38 | E11: 20057 | F11: 2165121024 | G11: 0 | H11: 5 | I11: 0 | J11: 905.07227 | K11: 2265409773 | L11: 11485 | M11: 0 | N11: 0 | O11: 2260029440 | P11: 551765 | Q11: 46961 | R11: 565695
A12: 3 | B12: 3 | C12: 35 | D12: 27 | E12: 20141 | F12: 2165121024 | G12: 0 | H12: 5 | I12: 0 | J12: 896.31562 | K12: 2252452841 | L12: 10610 | M12: 0 | N12: 0 | O12: 2247217152 | P12: 548637 | Q12: 45532 | R12: 561322
A13: Average | B13: =AVERAGE(B10:B12) | C13: =AVERAGE(C10:C12) | D13: =AVERAGE(D10:D12) | E13: =AVERAGE(E10:E12) | F13: =AVERAGE(F10:F12) | G13: =AVERAGE(G10:G12) | H13: =AVERAGE(H10:H12) | I13: =AVERAGE(I10:I12) | ... R13: =AVERAGE(R10:R12)
A15: RAM | B15: 4096
A16: Experiment | B16: Iterations | C16: Setup-Time | D16: Downtime | E16: Total-Time | F16: Ram-Total | G16: Ram-Postcopy-Requests | H16: Ram-Dirty-Sync-Count | I16: Ram-Remaining | J16: Ram-Mbps | K16: Ram-Transferred | L16: Ram-Duplicate | M16: Ram-Dirty-Pages-Rate | N16: Ram-Skipped | O16: Ram-Normal-Bytes | P16: Ram-Normal | Q16: Total-Fake-Dirty-Pages | R16: Total-Transferred-Page-Count
A17: 1 | B17: 3 | C17: 34 | D17: 61 | E17: 33552 | F17: 4312604672 | G17: 0 | H17: 5 | I17: 0 | J17: 855.17783 | K17: 3582768916 | L17: 257281 | M17: 0 | N17: 0 | O17: 3572391936 | P17: 872166 | Q17: 41707 | R17: 1134427
A18: 2 | B18: 4 | C18: 40 | D18: 48 | E18: 33206 | F18: 4312604672 | G18: 0 | H18: 6 | I18: 0 | J18: 791.87426 | K18: 3282700293 | L18: 328258 | M18: 0 | N18: 0 | O18: 3270598656 | P18: 798486 | Q18: 151490 | R18: 1134643
A19: 3 | B19: 4 | C19: 39 | D19: 52 | E19: 33570 | F19: 4312604672 | G19: 0 | H19: 6 | I19: 0 | J19: 805.17903 | K19: 3374594840 | L19: 312754 | M19: 0 | N19: 0 | O19: 3362402304 | P19: 820899 | Q19: 150924 | R19: 1142077
A20: Average | B20: =AVERAGE(B17:B19) | C20: =AVERAGE(C17:C19) | D20: =AVERAGE(D17:D19) | E20: =AVERAGE(E17:E19) | F20: =AVERAGE(F17:F19) | G20: =AVERAGE(G17:G19) | H20: =AVERAGE(H17:H19) | I20: =AVERAGE(I17:I19) | ... R20: =AVERAGE(R17:R19)
A22: RAM | B22: 8192
A23: Experiment | B23: Iterations | C23: Setup-Time | D23: Downtime | E23: Total-Time | F23: Ram-Total | G23: Ram-Postcopy-Requests | H23: Ram-Dirty-Sync-Count | I23: Ram-Remaining | J23: Ram-Mbps | K23: Ram-Transferred | L23: Ram-Duplicate | M23: Ram-Dirty-Pages-Rate | N23: Ram-Skipped | O23: Ram-Normal-Bytes | P23: Ram-Normal | Q23: Total-Fake-Dirty-Pages | R23: Total-Transferred-Page-Count
A24: 1 | B24: 4 | C24: 34 | D24: 41 | E24: 46733 | F24: 8607571968 | G24: 0 | H24: 6 | I24: 0 | J24: 682.1299 | K24: 3981635615 | L24: 1232224 | M24: 0 | N24: 0 | O24: 3959648256 | P24: 966711 | Q24: 77872 | R24: 2206868
A25: 2 | B25: 4 | C25: 36 | D25: 67 | E25: 46377 | F25: 8607571968 | G25: 0 | H25: 6 | I25: 0 | J25: 638.36934 | K25: 3697621813 | L25: 1295119 | M25: 0 | N25: 0 | O25: 3675451392 | P25: 897327 | Q25: 203159 | R25: 2201497
A26: 3 | B26: 4 | C26: 41 | D26: 45 | E26: 46485 | F26: 8607571968 | G26: 0 | H26: 6 | I26: 0 | J26: 676.36725 | K26: 3926437639 | L26: 1240925 | M26: 0 | N26: 0 | O26: 3904684032 | P26: 953292 | Q26: 95334 | R26: 2202128
A27: Average | B27: =AVERAGE(B24:B26) | C27: =AVERAGE(C24:C26) | D27: =AVERAGE(D24:D26) | E27: =AVERAGE(E24:E26) | F27: =AVERAGE(F24:F26) | G27: =AVERAGE(G24:G26) | H27: =AVERAGE(H24:H26) | I27: =AVERAGE(I24:I26) | ... R27: =AVERAGE(R24:R26)
A29: RAM | B29: 12288
A30: Experiment | B30: Iterations | C30: Setup-Time | D30: Downtime | E30: Total-Time | F30: Ram-Total | G30: Ram-Postcopy-Requests | H30: Ram-Dirty-Sync-Count | I30: Ram-Remaining | J30: Ram-Mbps | K30: Ram-Transferred | L30: Ram-Duplicate | M30: Ram-Dirty-Pages-Rate | N30: Ram-Skipped | O30: Ram-Normal-Bytes | P30: Ram-Normal | Q30: Total-Fake-Dirty-Pages | R30: Total-Transferred-Page-Count
A31: 1 | B31: 3 | C31: 40 | D31: 54 | E31: 55245 | F31: 12902539264 | G31: 0 | H31: 5 | I31: 0 | J31: 575.43744 | K31: 3970665584 | L31: 2229083 | M31: 0 | N31: 0 | O31: 3941601280 | P31: 962305 | Q31: 106877 | R31: 3195326
A32: 2 | B32: 5 | C32: 43 | D32: 51 | E32: 55266 | F32: 12902539264 | G32: 0 | H32: 7 | I32: 0 | J32: 557.35763 | K32: 3847157625 | L32: 2318749 | M32: 0 | N32: 0 | O32: 3815247872 | P32: 931457 | Q32: 108003 | R32: 3258995
A33: 3 | B33: 4 | C33: 36 | D33: 42 | E33: 55133 | F33: 12902539264 | G33: 0 | H33: 6 | I33: 0 | J33: 584.46615 | K33: 4025079013 | L33: 2214527 | M33: 0 | N33: 0 | O33: 3995459584 | P33: 975454 | Q33: 66827 | R33: 3193985
A34: Average | B34: =AVERAGE(B31:B33) | C34: =AVERAGE(C31:C33) | D34: =AVERAGE(D31:D33) | E34: =AVERAGE(E31:E33) | F34: =AVERAGE(F31:F33) | G34: =AVERAGE(G31:G33) | H34: =AVERAGE(H31:H33) | I34: =AVERAGE(I31:I33) | ... R34: =AVERAGE(R31:R33)
A36: RAM | B36: 16384
A37: Experiment | B37: Iterations | C37: Setup-Time | D37: Downtime | E37: Total-Time | F37: Ram-Total | G37: Ram-Postcopy-Requests | H37: Ram-Dirty-Sync-Count | I37: Ram-Remaining | J37: Ram-Mbps | K37: Ram-Transferred | L37: Ram-Duplicate | M37: Ram-Dirty-Pages-Rate | N37: Ram-Skipped | O37: Ram-Normal-Bytes | P37: Ram-Normal | Q37: Total-Fake-Dirty-Pages | R37: Total-Transferred-Page-Count
A38: 1 | B38: 4 | C38: 42 | D38: 42 | E38: 68674 | F38: 17197506560 | G38: 0 | H38: 6 | I38: 0 | J38: 528.69892 | K38: 4535495640 | L38: 3222925 | M38: 0 | N38: 0 | O38: 4495200256 | P38: 1097461 | Q38: 131768 | R38: 4328386
A39: 2 | B39: 4 | C39: 40 | D39: 48 | E39: 68985 | F39: 17197506560 | G39: 0 | H39: 6 | I39: 0 | J39: 494.8824 | K39: 4264745939 | L39: 3286059 | M39: 0 | N39: 0 | O39: 4224692224 | P39: 1031419 | Q39: 131355 | R39: 4325318
A40: 3 | B40: 4 | C40: 37 | D40: 38 | E40: 68344 | F40: 17197506560 | G40: 0 | H40: 6 | I40: 0 | J40: 525.83537 | K40: 4489567192 | L40: 3231742 | M40: 0 | N40: 0 | O40: 4449624064 | P40: 1086334 | Q40: 84150 | R40: 4325286
A41: Average | B41: =AVERAGE(B38:B40) | C41: =AVERAGE(C38:C40) | D41: =AVERAGE(D38:D40) | E41: =AVERAGE(E38:E40) | F41: =AVERAGE(F38:F40) | G41: =AVERAGE(G38:G40) | H41: =AVERAGE(H38:H40) | I41: =AVERAGE(I38:I40) | ... R41: =AVERAGE(R38:R40)

Sheet XBZRLE_HBFDP_MD5
A1: RAM | B1: 1024
A2: Experiment | B2: Iterations | C2: Setup-Time | D2: Downtime | E2: Total-Time | F2: Ram-Total | G2: Ram-Postcopy-Requests | H2: Ram-Dirty-Sync-Count | I2: Ram-Remaining | J2: Ram-Mbps | K2: Ram-Transferred | L2: Ram-Duplicate | M2: Ram-Dirty-Pages-Rate | N2: Ram-Skipped | O2: Ram-Normal-Bytes | P2: Ram-Normal | Q2: Total-Fake-Dirty-Pages | R2: Total-Transferred-Page-Count
A3: 1 | B3: 2 | C3: 31 | D3: 630 | E3: 10322 | F3: 1091379200 | G3: 0 | H3: 4 | I3: 0 | J3: 871.44233 | K3: 1120789269 | L3: 10105 | M3: 0 | N3: 0 | O3: 1118265344 | P3: 273014 | Q3: 21911 | R3: 284261
A4: 2 | B4: 2 | C4: 31 | D4: 548 | E4: 10401 | F4: 1091379200 | G4: 0 | H4: 4 | I4: 0 | J4: 856.22187 | K4: 1109665244 | L4: 11993 | M4: 0 | N4: 0 | O4: 1107378176 | P4: 270356 | Q4: 25399 | R4: 282626
A5: 3 | B5: 2 | C5: 31 | D5: 570 | E5: 10345 | F5: 1091379200 | G5: 0 | H5: 4 | I5: 0 | J5: 869.68712 | K5: 1121031756 | L5: 10473 | M5: 0 | N5: 0 | O5: 1118527488 | P5: 273078 | Q5: 22021 | R5: 284559
A6: Average | B6: =AVERAGE(B3:B5) | C6: =AVERAGE(C3:C5) | D6: =AVERAGE(D3:D5) | E6: =AVERAGE(E3:E5) | F6: =AVERAGE(F3:F5) | G6: =AVERAGE(G3:G5) | H6: =AVERAGE(H3:H5) | I6: =AVERAGE(I3:I5) | ... R6: =AVERAGE(R3:R5)
A8: RAM | B8: 2048
A9: Experiment | B9: Iterations | C9: Setup-Time | D9: Downtime | E9: Total-Time | F9: Ram-Total | G9: Ram-Postcopy-Requests | H9: Ram-Dirty-Sync-Count | I9: Ram-Remaining | J9: Ram-Mbps | K9: Ram-Transferred | L9: Ram-Duplicate | M9: Ram-Dirty-Pages-Rate | N9: Ram-Skipped | O9: Ram-Normal-Bytes | P9: Ram-Normal | Q9: Total-Fake-Dirty-Pages | R9: Total-Transferred-Page-Count
A10: 1 | B10: 3 | C10: 31 | D10: 23 | E10: 19523 | F10: 2165121024 | G10: 0 | H10: 5 | I10: 0 | J10: 929.15653 | K10: 2263677503 | L10: 10579 | M10: 0 | N10: 0 | O10: 2258583552 | P10: 551412 | Q10: 33220 | R10: 563970
A11: 2 | B11: 3 | C11: 32 | D11: 37 | E11: 19893 | F11: 2165121024 | G11: 0 | H11: 5 | I11: 0 | J11: 902.06929 | K11: 2239287388 | L11: 12277 | M11: 0 | N11: 0 | O11: 2234286080 | P11: 545480 | Q11: 24827 | R11: 559298
A12: 3 | B12: 2 | C12: 32 | D12: 65 | E12: 19232 | F12: 2165121024 | G12: 0 | H12: 4 | I12: 0 | J12: 920.43517 | K12: 2208832058 | L12: 12258 | M12: 0 | N12: 0 | O12: 2204094464 | P12: 538109 | Q12: 24622 | R12: 550986
A13: Average | B13: =AVERAGE(B10:B12) | C13: =AVERAGE(C10:C12) | D13: =AVERAGE(D10:D12) | E13: =AVERAGE(E10:E12) | F13: =AVERAGE(F10:F12) | G13: =AVERAGE(G10:G12) | H13: =AVERAGE(H10:H12) | I13: =AVERAGE(I10:I12) | ... R13: =AVERAGE(R10:R12)
A15: RAM | B15: 4096
A16: Experiment | B16: Iterations | C16: Setup-Time | D16: Downtime | E16: Total-Time | F16: Ram-Total | G16: Ram-Postcopy-Requests | H16: Ram-Dirty-Sync-Count | I16: Ram-Remaining | J16: Ram-Mbps | K16: Ram-Transferred | L16: Ram-Duplicate | M16: Ram-Dirty-Pages-Rate | N16: Ram-Skipped | O16: Ram-Normal-Bytes | P16: Ram-Normal | Q16: Total-Fake-Dirty-Pages | R16: Total-Transferred-Page-Count
A17: 1 | B17: 4 | C17: 40 | D17: 39 | E17: 32937 | F17: 4312604672 | G17: 0 | H17: 6 | I17: 0 | J17: 814.79105 | K17: 3350310226 | L17: 315998 | M17: 0 | N17: 0 | O17: 3338477568 | P17: 815058 | Q17: 54990 | R17: 1137845
A18: 2 | B18: 3 | C18: 40 | D18: 25 | E18: 31754 | F18: 4312604672 | G18: 0 | H18: 5 | I18: 0 | J18: 841.52084 | K18: 3335786618 | L18: 262393 | M18: 0 | N18: 0 | O18: 3325931520 | P18: 811995 | Q18: 31739 | R18: 1076533
A19: 3 | B19: 2 | C19: 33 | D19: 61 | E19: 32206 | F19: 4312604672 | G19: 0 | H19: 4 | I19: 0 | J19: 852.97357 | K19: 3430127469 | L19: 240144 | M19: 0 | N19: 0 | O19: 3420717056 | P19: 835136 | Q19: 21864 | R19: 1076160
A20: Average | B20: =AVERAGE(B17:B19) | C20: =AVERAGE(C17:C19) | D20: =AVERAGE(D17:D19) | E20: =AVERAGE(E17:E19) | F20: =AVERAGE(F17:F19) | G20: =AVERAGE(G17:G19) | H20: =AVERAGE(H17:H19) | I20: =AVERAGE(I17:I19) | ... R20: =AVERAGE(R17:R19)
A22: RAM | B22: 8192
